Workbook

Sheet Resumen Contrato
B8: Resumen Contratos Locales Comerciales
B9: Flexi Chile Spa
B12: Comuna | C12: Mall | D12: Bien Arrendado | E12: Metros Cuadrados | F12: Proveedor | G12: Fecha Suscripcion | H12: Fecha Inicio Contrato | I12: Inicio Atención Publico | J12: Periodo Duracion | K12: Hasta | L12: Tarifa | P12: Otras obligaciones derivadas del Contrato | T12: Clausulas Adiconales/comentarios
L13: Condiciones | M13: Valor Minimo | O13: Valor % | P13: Fondo de Promocion | Q13: Costo Administración | R13: Gastos Comunes | S13: Recargo Valor Minimo Mensual
B14: Las Condes | C14: Mall Plaza Dominicos | D14: locales comerciales Nº C-2057/C 2061 | E14: 109.01 | F14: Nuevos Desarrollos Spa | G14: 44180 | H14: 44151 | I14: 44181 | J14: 2 años | K14: 44911 | L14: será el mayor valor que resulte entre el Valor Mínimo Mensual Reajustable y el Valor Porcentual para el correspondiente mes, ambos más el Impuesto al Valor Agregado (I.V.A.) que corresponda al monto pagado | M14: 0,2 UF por m2 ( cada 24 meses se reajusta en un 10%), contrato no indica pago cuota numero 13. | N14: =0.2*E14 -> 21.802 | O14: 8,1% sobre la facturación neta mensual | P14: correspondiente al 10% de la renta de arrendamiento mensual, expresada en Unidades de Fomento, más el Impuesto al Valor Agregado. | Q14: correspondiente al 5% de la renta de arrendamiento mensual. | R14: 0,42 UF por m2 | S14: N/A | T14: Comenzo en diciembre de 2020 a cobrarse arriendo
B15: Ñuñoa | C15: Mall Plaza Egaña | D15: Nº A-2045/A-2049 | E15: 105.64 | F15: Nuevos Desarrollos Spa | G15: 44180 | H15: 44151 | I15: 44181 | J15: 2 años | K15: 44911 | L15: será el mayor valor que resulte entre el Valor Mínimo Mensual Reajustable y el Valor Porcentual para el correspondiente mes, ambos más el Impuesto al Valor Agregado (I.V.A.) que corresponda al monto pagado | M15: 1,2 UF por m2 ( cada 24 meses se reajusta en un 10%) contrato no indica pago cuota numero 13. | N15: =1.2*E15 -> 126.768 | O15: 8,1% sobre la facturación neta mensual | P15: correspondiente al 10% de la renta de arrendamiento mensual, expresada en Unidades de Fomento, más el Impuesto al Valor Agregado. | Q15: correspondiente al 5% de la renta de arrendamiento mensual. | R15: 0,44 UF por m2 | S15: N/A | T15: Comenzo en diciembre de 2020 a cobrarse arriendo
B16: La Florida | C16: Mall Plaza Vespucio | D16: Nº 077/078 | E16: 68 | F16: Plaza Vespucio Spa | G16: 44180 | H16: 44151 | I16: 44181 | J16: 2 años | K16: 44911 | L16: será el mayor valor que resulte entre el Valor Mínimo Mensual Reajustable y el Valor Porcentual para el correspondiente mes, ambos más el Impuesto al Valor Agregado (I.V.A.) que corresponda al monto pagado | M16: 1,5 UF por m2 ( cada 24 meses se reajusta en un 10%) contrato no indica pago cuota numero 13. | N16: =1.5*E16 -> 102 | O16: 8,1% sobre la facturación neta mensual | P16: correspondiente al 10% de la renta de arrendamiento mensual, expresada en Unidades de Fomento, más el Impuesto al Valor Agregado. | Q16: correspondiente al 5% de la renta de arrendamiento mensual. | R16: 0,44 UF por m2 | S16: N/A | T16: Comenzo en diciembre de 2020 a cobrarse arriendo
B17: Talcahuano | C17: Mall Plaza El Trebol | D17: A-237/A-239 | E17: 81.54 | F17: Plaza El Trebol Spa | G17: 44180 | H17: 44151 | I17: 44181 | J17: 2 años | K17: 44911 | L17: será el mayor valor que resulte entre el Valor Mínimo Mensual Reajustable y el Valor Porcentual para el correspondiente mes, ambos más el Impuesto al Valor Agregado (I.V.A.) que corresponda al monto pagado | M17: 1,4 UF por m2 ( cada 24 meses se reajusta en un 10%) contrato no indica pago cuota numero 13. | N17: =1.4*E17 -> 114.156 | O17: 8,1% sobre la facturación neta mensual | P17: correspondiente al 10% de la renta de arrendamiento mensual, expresada en Unidades de Fomento, más el Impuesto al Valor Agregado. | Q17: correspondiente al 5% de la renta de arrendamiento mensual. | R17: 0,44 UF por m2 | S17: N/A | T17: Comenzo en diciembre de 2020 a cobrarse arriendo
B18: Maipu | C18: Mall Arauco Maipu | D18: S.U.C N° 639 | E18: 60 | F18: Arauco Malls Chile S.A. | G18: 44167 | H18: 44166 | I18: 44166 | J18: 2 años 1 mes | K18: 44926 | L18: será el mayor valor que resulte entre el Valor Mínimo Mensual Reajustable y el Valor Porcentual para el correspondiente mes, ambos más el Impuesto al Valor Agregado (I.V.A.) que corresponda al monto pagado | M18: 1 UF por m2, contrato no indica pago cuota numero 13. | N18: =1*E18 -> 60 | O18: 8,1% sobre la facturación neta mensual | P18: correspondiente al 10% de la renta de arrendamiento mensual, expresada en Unidades de Fomento, más el Impuesto al Valor Agregado. | Q18: correspondiente al 5% de la renta de arrendamiento mensual. | R18: 0,52 UF por m2 | S18: N/A | T18: Comenzo en diciembre de 2020 a cobrarse arriendo
B19: Providencia | C19: Mall Costanera Center | D19: Local N° 2200 | E19: 96 | F19: Comercializadora Costanera Center Spa | G19: 44357 | H19: 44423 | I19: 44378 | J19: 5 años | K19: 46248 | L19: será el mayor valor que resulte entre el Valor Mínimo Mensual Reajustable y el Valor Porcentual para el correspondiente mes, ambos más el Impuesto al Valor Agregado (I.V.A.) que corresponda al monto pagado | M19: 2,6 UF por m2 (por el mes de diciembre de cada año se reajuste se paga un 75% del VMM adicional como una cuota de arriendo numero 13. Al termino del contrato se reajusta el VMM en un 10%) | N19: =2.6*E19 -> 249.6 | O19: 8,1% sobre la facturación neta mensual | P19: correspondiente al 10% de la renta de arrendamiento mensual, expresada en Unidades de Fomento, más el Impuesto al Valor Agregado. Adicionalmente debera pagar 248 UF como aporte inicial la cual se paga con la primera cuota de arrendamiento | Q19: correspondiente al 5% de la renta de arrendamiento mensual. | R19: 0,67 UF por m2 | S19: El VMM correspondiente a los 10 primero meses se recargara en un 21,63% , total de 540 UF pagandose junto con la 1era cuota de arrendamiento | T19: Se aplicaran los siguientes descuentos al VMM: a) desde 15-12-2021 al 14-12-2022 26,92%, b) desde 15-12-2022 al 14-12-2023 19,23%, c) desde 15-12-2023 al 14-12-2024 11,54%, d) desde 15-12-2024 al 14-12-2025 7,69% - Contrato comienza a cobrarse en octubre | U19: Valor Minimo con descuento a) desde 15-12-2021 al 14-12-2022 1,9, b) desde 15-12-2022 al 14-12-2023 2,1 c) desde 15-12-2023 al 14-12-2024 2,3 d) desde 15-12-2024 al 14-12-2025 2,4.
B20: La Florida | C20: Mall Florida Center | D20: Local N° 2068 | E20: 78.59 | F20: Cencosud Shopping S.A. | G20: 44357 | H20: 44454 | I20: 44409 | J20: 5 años | K20: 46279 | L20: será el mayor valor que resulte entre el Valor Mínimo Mensual Reajustable y el Valor Porcentual para el correspondiente mes, ambos más el Impuesto al Valor Agregado (I.V.A.) que corresponda al monto pagado | M20: 1,4 UF por m2 (por el mes de diciembre de cada año se reajuste se paga un 75% del VMM adicional como una cuota de arriendo numero 13. Al termino del contrato se reajusta el VMM en un 10%) | N20: =1.4*E20 -> 110.026 | O20: 8,1% sobre la facturación neta mensual | P20: correspondiente al 10% de la renta de arrendamiento mensual, expresada en Unidades de Fomento, más el Impuesto al Valor Agregado. Adicionalmente debera pagar 127 UF como aporte inicial la cual se paga con la primera cuota de arrendamiento | Q20: correspondiente al 5% de la renta de arrendamiento mensual. | R20: 0,46 UF por m2 | S20: El VMM correspondiente a los 10 primero meses se recargara en un 32,72% , total de 360 UF pagandose junto con la 1era cuota de arrendamiento | T20: Se aplicaran los siguientes descuentos al VMM: a) desde 15-12-2021 al 14-12-2022 42,85%, b) desde 15-12-2022 al 14-12-2023 35,71%, c) desde 15-12-2023 al 14-12-2024 28,57%, d) desde 15-12-2024 al 14-12-2025 14,28%. Contrato comienza a cobrarse en diciembre | U20: Valor Minimo con descuento a) desde 15-12-2021 al 14-12-2022 0,8, b) desde 15-12-2022 al 14-12-2023 0,9 c) desde 15-12-2023 al 14-12-2024 1,0 d) desde 15-12-2024 al 14-12-2025 1,2.

Sheet Contrato vs Factura (mensual)
B8: Resumen Facturacion Locales Comerciales
B9: Flexi Chile Spa
B12: Mall | C12: Mes | D12: Año | E12: Metros Cuadrados | F12: Valor UF | G12: Tarifa | M12: Otras obligaciones del Contrato | T12: Lo que se debio Facturar según Contrato | X12: Factura recibida | AE12: Diferencia | AG12: Detalle diferencias
G13: Valor Minimo | J13: Valor % | M13: Fondo de Promocion | O13: Costo Administracion | Q13: Gastos Comunes | X13: Arriendo | Y13: Fondo Promoción | Z13: Costo Administracion | AA13: Gastos Comunes | AB13: Otros | AC13: Total Neto | AG13: Factura N° | AH13: Arriendo | AI13: Fondo Promoción | AJ13: Costo Administracion | AK13: Gastos Comunes | AL13: Otros | AM13: Total
G14: UF x M2 | H14: Total UF | I14: Total Neto $ | J14: % | K14: Venta Local | L14: Total | M14: % | N14: Total | O14: % | P14: Total | Q14: UF x M2 | R14: Total UF | S14: Total $ | T14: Total Neto | U14: IVA | V14: Total | Y14: Total | AI14: Total
B15: Mall Plaza Los Dominicos | C15: Diciembre | D15: 2020 | E15: 109.01 | F15: 29070.33 | G15: 0.2 | H15: =G15*E15 -> 21.802 | I15: =H15*F15 -> 633791.33 | J15: 0.081 | K15: =6034404/1.19 -> 5070927.7 | L15: =J15*K15 -> 410745.15 | M15: 0.1 | N15: =IF(I15>L15,M15*I15,M15*L15) -> 63379.133 | O15: 0.05 | P15: =IF(I15>L15,O15*I15,O15*L15) -> 31689.567 | Q15: 0.42 | R15: =Q15*E15 -> 45.7842 | S15: =R15*F15 -> 1330961.8 | T15: =IF(I15>L15,I15,L15)+N15+P15+S15 -> 2059821.8 | U15: =T15*19% -> 391366.15 | V15: =T15+U15 -> 2451188 | X15: 0 | Y15: 0 | Z15: 0 | AA15: 0 | AB15: 0 | AC15: =SUM(X15:AB15) -> 0 | AE15: =AC15-T15 -> -2059821.8 | AG15: Sin Factura | AH15: =IF(I15>L15,I15,L15)-X15 -> 633791.33 | AI15: =N15-Y15 -> 63379.133 | AJ15: =P15-Z15 -> 31689.567 | AK15: =S15-AA15 -> 1330961.8 | AL15: =0-AB15 -> 0 | AM15: =SUM(AH15:AL15) -> 2059821.8
B16: Mall Plaza Los Dominicos | C16: Enero | D16: 2021 | E16: 109.01 | F16: 29123.74 | G16: 0.2 | H16: =G16*E16 -> 21.802 | I16: =H16*F16 -> 634955.78 | J16: 0.081 | K16: =10949320/1.19 -> 9201109.2 | L16: =J16*K16 -> 745289.85 | M16: 0.1 | N16: =IF(I16>L16,M16*I16,M16*L16) -> 74528.985 | O16: 0.05 | P16: =IF(I16>L16,O16*I16,O16*L16) -> 37264.492 | Q16: 0.42 | R16: =Q16*E16 -> 45.7842 | S16: =R16*F16 -> 1333407.1 | T16: =IF(I16>L16,I16,L16)+N16+P16+S16 -> 2190490.5 | U16: =T16*19% -> 416193.19 | V16: =T16+U16 -> 2606683.7 | X16: 0 | Y16: 0 | Z16: 0 | AA16: 0 | AB16: 0 | AC16: =SUM(X16:AB16) -> 0 | AE16: =AC16-T16 -> -2190490.5 | AG16: Sin Factura | AH16: =IF(I16>L16,I16,L16)-X16 -> 745289.85 | AI16: =N16-Y16 -> 74528.985 | AJ16: =P16-Z16 -> 37264.492 | AK16: =S16-AA16 -> 1333407.1 | AL16: =0-AB16 -> 0 | AM16: =SUM(AH16:AL16) -> 2190490.5
B17: Mall Plaza Los Dominicos | C17: Febrero | D17: 2021 | E17: 109.01 | F17: 29287.38 | G17: 0.2 | H17: =G17*E17 -> 21.802 | I17: =H17*F17 -> 638523.46 | J17: 0.081 | K17: =13021103/1.19 -> 10942103 | L17: =J17*K17 -> 886310.37 | M17: 0.1 | N17: =IF(I17>L17,M17*I17,M17*L17) -> 88631.037 | O17: 0.05 | P17: =IF(I17>L17,O17*I17,O17*L17) -> 44315.519 | Q17: 0.42 | R17: =Q17*E17 -> 45.7842 | S17: =R17*F17 -> 1340899.3 | T17: =IF(I17>L17,I17,L17)+N17+P17+S17 -> 2360156.2 | U17: =T17*19% -> 448429.68 | V17: =T17+U17 -> 2808585.9 | X17: 0 | Y17: 0 | Z17: 0 | AA17: 0 | AB17: 0 | AC17: =SUM(X17:AB17) -> 0 | AE17: =AC17-T17 -> -2360156.2 | AG17: Sin Factura | AH17: =IF(I17>L17,I17,L17)-X17 -> 886310.37 | AI17: =N17-Y17 -> 88631.037 | AJ17: =P17-Z17 -> 44315.519 | AK17: =S17-AA17 -> 1340899.3 | AL17: =0-AB17 -> 0 | AM17: =SUM(AH17:AL17) -> 2360156.2
B18: Mall Plaza Los Dominicos | C18: Marzo | D18: 2021 | E18: 109.01 | F18: 29394.77 | G18: 0.2 | H18: =G18*E18 -> 21.802 | I18: =H18*F18 -> 640864.78 | J18: 0.081 | K18: =5426443/1.19 -> 4560036.1 | L18: =J18*K18 -> 369362.93 | M18: 0.1 | N18: =IF(I18>L18,M18*I18,M18*L18) -> 64086.478 | O18: 0.05 | P18: =IF(I18>L18,O18*I18,O18*L18) -> 32043.239 | Q18: 0.42 | R18: =Q18*E18 -> 45.7842 | S18: =R18*F18 -> 1345816 | T18: =IF(I18>L18,I18,L18)+N18+P18+S18 -> 2082810.5 | U18: =T18*19% -> 395734 | V18: =T18+U18 -> 2478544.5 | X18: 0 | Y18: 0 | Z18: 0 | AA18: 0 | AB18: 0 | AC18: =SUM(X18:AB18) -> 0 | AE18: =AC18-T18 -> -2082810.5 | AG18: Sin Factura | AH18: =IF(I18>L18,I18,L18)-X18 -> 640864.78 | AI18: =N18-Y18 -> 64086.478 | AJ18: =P18-Z18 -> 32043.239 | AK18: =S18-AA18 -> 1345816 | AL18: =0-AB18 -> 0 | AM18: =SUM(AH18:AL18) -> 2082810.5
B19: Mall Plaza Los Dominicos | C19: Abril | D19: 2021 | E19: 109.01 | F19: 29494.13 | G19: 0.2 | H19: =G19*E19 -> 21.802 | I19: =H19*F19 -> 643031.02 | J19: 0.081 | K19: =1172639/1.19 -> 985410.92 | L19: =J19*K19 -> 79818.285 | M19: 0.1 | N19: =IF(I19>L19,M19*I19,M19*L19) -> 64303.102 | O19: 0.05 | P19: =IF(I19>L19,O19*I19,O19*L19) -> 32151.551 | Q19: 0.42 | R19: =Q19*E19 -> 45.7842 | S19: =R19*F19 -> 1350365.1 | T19: =IF(I19>L19,I19,L19)+N19+P19+S19 -> 2089850.8 | U19: =T19*19% -> 397071.66 | V19: =T19+U19 -> 2486922.5 | X19: 0 | Y19: 0 | Z19: 0 | AA19: 0 | AB19: 0 | AC19: =SUM(X19:AB19) -> 0 | AE19: =AC19-T19 -> -2089850.8 | AG19: Sin Factura | AH19: =IF(I19>L19,I19,L19)-X19 -> 643031.02 | AI19: =N19-Y19 -> 64303.102 | AJ19: =P19-Z19 -> 32151.551 | AK19: =S19-AA19 -> 1350365.1 | AL19: =0-AB19 -> 0 | AM19: =SUM(AH19:AL19) -> 2089850.8
B20: Mall Plaza Los Dominicos | C20: Mayo | D20: 2021 | E20: 109.01 | F20: 29613.26 | G20: 0.2 | H20: =G20*E20 -> 21.802 | I20: =H20*F20 -> 645628.29 | J20: 0.081 | K20: =10602865/1.19 -> 8909970.6 | L20: =J20*K20 -> 721707.62 | M20: 0.1 | N20: =IF(I20>L20,M20*I20,M20*L20) -> 72170.762 | O20: 0.05 | P20: =IF(I20>L20,O20*I20,O20*L20) -> 36085.381 | Q20: 0.42 | R20: =Q20*E20 -> 45.7842 | S20: =R20*F20 -> 1355819.4 | T20: =IF(I20>L20,I20,L20)+N20+P20+S20 -> 2185783.2 | U20: =T20*19% -> 415298.8 | V20: =T20+U20 -> 2601082 | X20: 0 | Y20: 0 | Z20: 0 | AA20: 0 | AB20: 0 | AC20: =SUM(X20:AB20) -> 0 | AE20: =AC20-T20 -> -2185783.2 | AG20: Sin Factura | AH20: =IF(I20>L20,I20,L20)-X20 -> 721707.62 | AI20: =N20-Y20 -> 72170.762 | AJ20: =P20-Z20 -> 36085.381 | AK20: =S20-AA20 -> 1355819.4 | AL20: =0-AB20 -> 0 | AM20: =SUM(AH20:AL20) -> 2185783.2
B21: Mall Plaza Los Dominicos | C21: Junio | D21: 2021 | E21: 109.01 | F21: 29709.83 | G21: 0.2 | H21: =G21*E21 -> 21.802 | I21: =H21*F21 -> 647733.71 | J21: 0.081 | K21: =4233173/1.19 -> 3557288.2 | L21: =J21*K21 -> 288140.35 | M21: 0.1 | N21: =IF(I21>L21,M21*I21,M21*L21) -> 64773.371 | O21: 0.05 | P21: =IF(I21>L21,O21*I21,O21*L21) -> 32386.686 | Q21: 0.42 | R21: =Q21*E21 -> 45.7842 | S21: =R21*F21 -> 1360240.8 | T21: =IF(I21>L21,I21,L21)+N21+P21+S21 -> 2105134.6 | U21: =T21*19% -> 399975.57 | V21: =T21+U21 -> 2505110.1 | X21: 11450586 | Y21: 0 | Z21: 0 | AA21: 0 | AB21: -403754 | AC21: =SUM(X21:AB21) -> 11046832 | AE21: =AC21-T21 -> 8941697.4 | AG21: F/143219 + NC/28133 | AH21: =IF(I21>L21,I21,L21)-X21 -> -10802852 | AI21: =N21-Y21 -> 64773.371 | AJ21: =P21-Z21 -> 32386.686 | AK21: =S21-AA21 -> 1360240.8 | AL21: =0-AB21 -> 403754 | AM21: =SUM(AH21:AL21) -> -8941697.4 | AO21: Factura no viene abierta por concepto
B22: Mall Plaza Los Dominicos | C22: Julio | D22: 2021 | E22: 109.01 | F22: 29757.64 | G22: 0.2 | H22: =G22*E22 -> 21.802 | I22: =H22*F22 -> 648776.07 | J22: 0.081 | K22: =11574755/1.19 -> 9726684.9 | L22: =J22*K22 -> 787861.47 | M22: 0.1 | N22: =IF(I22>L22,M22*I22,M22*L22) -> 78786.147 | O22: 0.05 | P22: =IF(I22>L22,O22*I22,O22*L22) -> 39393.074 | Q22: 0.42 | R22: =Q22*E22 -> 45.7842 | S22: =R22*F22 -> 1362429.7 | T22: =IF(I22>L22,I22,L22)+N22+P22+S22 -> 2268470.4 | U22: =T22*19% -> 431009.38 | V22: =T22+U22 -> 2699479.8 | X22: 2191169 | Y22: 0 | Z22: 0 | AA22: 0 | AB22: 0 | AC22: =SUM(X22:AB22) -> 2191169 | AE22: =AC22-T22 -> -77301.437 | AG22: F/144044 | AH22: =IF(I22>L22,I22,L22)-X22 -> -1403307.5 | AI22: =N22-Y22 -> 78786.147 | AJ22: =P22-Z22 -> 39393.074 | AK22: =S22-AA22 -> 1362429.7 | AL22: =0-AB22 -> 0 | AM22: =SUM(AH22:AL22) -> 77301.437 | AO22: Factura no viene abierta por concepto
B23: Mall Plaza Los Dominicos | C23: Agosto | D23: 2021 | E23: 109.01 | F23: 29935.08 | G23: 0.2 | H23: =G23*E23 -> 21.802 | I23: =H23*F23 -> 652644.61 | J23: 0.081 | K23: =16908395/1.19 -> 14208735 | L23: =J23*K23 -> 1150907.6 | M23: 0.1 | N23: =IF(I23>L23,M23*I23,M23*L23) -> 115090.76 | O23: 0.05 | P23: =IF(I23>L23,O23*I23,O23*L23) -> 57545.378 | Q23: 0.42 | R23: =Q23*E23 -> 45.7842 | S23: =R23*F23 -> 1370553.7 | T23: =IF(I23>L23,I23,L23)+N23+P23+S23 -> 2694097.4 | U23: =T23*19% -> 511878.5 | V23: =T23+U23 -> 3205975.9 | X23: =2331358 -> 2331358 | Y23: 0 | Z23: 0 | AA23: 0 | AB23: 0 | AC23: =SUM(X23:AB23) -> 2331358 | AE23: =AC23-T23 -> -362739.38 | AG23: F/146331 | AH23: =IF(I23>L23,I23,L23)-X23 -> -1180450.4 | AI23: =N23-Y23 -> 115090.76 | AJ23: =P23-Z23 -> 57545.378 | AK23: =S23-AA23 -> 1370553.7 | AL23: =0-AB23 -> 0 | AM23: =SUM(AH23:AL23) -> 362739.38 | AO23: Factura no viene abierta por concepto
B24: Mall Plaza Los Dominicos | C24: Septiembre | D24: 2021 | E24: 109.01 | F24: 30088.37 | G24: 0.2 | H24: =G24*E24 -> 21.802 | I24: =H24*F24 -> 655986.64 | J24: 0.081 | K24: =17855535/1.19 -> 15004651 | L24: =J24*K24 -> 1215376.8 | M24: 0.1 | N24: =IF(I24>L24,M24*I24,M24*L24) -> 121537.68 | O24: 0.05 | P24: =IF(I24>L24,O24*I24,O24*L24) -> 60768.838 | Q24: 0.42 | R24: =Q24*E24 -> 45.7842 | S24: =R24*F24 -> 1377571.9 | T24: =IF(I24>L24,I24,L24)+N24+P24+S24 -> 2775255.2 | U24: =T24*19% -> 527298.49 | V24: =T24+U24 -> 3302553.7 | X24: 2767628 | Y24: 0 | Z24: 0 | AA24: 0 | AB24: 0 | AC24: =SUM(X24:AB24) -> 2767628 | AE24: =AC24-T24 -> -7627.2147 | AG24: F/147859 | AH24: =IF(I24>L24,I24,L24)-X24 -> -1552251.2 | AI24: =N24-Y24 -> 121537.68 | AJ24: =P24-Z24 -> 60768.838 | AK24: =S24-AA24 -> 1377571.9 | AL24: =0-AB24 -> 0 | AM24: =SUM(AH24:AL24) -> 7627.2147 | AO24: Factura no viene abierta por concepto
B25: Mall Plaza Los Dominicos | C25: Octubre | D25: 2021 | E25: 109.01 | F25: 30380.53 | G25: 0.2 | H25: =G25*E25 -> 21.802 | I25: =H25*F25 -> 662356.32 | J25: 0.081 | K25: =24708686/1.19 -> 20763602 | L25: =J25*K25 -> 1681851.7 | M25: 0.1 | N25: =IF(I25>L25,M25*I25,M25*L25) -> 168185.17 | O25: 0.05 | P25: =IF(I25>L25,O25*I25,O25*L25) -> 84092.587 | Q25: 0.42 | R25: =Q25*E25 -> 45.7842 | S25: =R25*F25 -> 1390948.3 | T25: =IF(I25>L25,I25,L25)+N25+P25+S25 -> 3325077.8 | U25: =T25*19% -> 631764.77 | V25: =T25+U25 -> 3956842.5 | X25: 2911512 | Y25: 0 | Z25: 0 | AA25: 0 | AB25: 0 | AC25: =SUM(X25:AB25) -> 2911512 | AE25: =AC25-T25 -> -413565.76 | AG25: F/149428 | AH25: =IF(I25>L25,I25,L25)-X25 -> -1229660.3 | AI25: =N25-Y25 -> 168185.17 | AJ25: =P25-Z25 -> 84092.587 | AK25: =S25-AA25 -> 1390948.3 | AL25: =0-AB25 -> 0 | AM25: =SUM(AH25:AL25) -> 413565.76
B26: Mall Plaza Egaña | C26: Diciembre | D26: 2020 | E26: 105.64 | F26: 29070.33 | G26: 1.2 | H26: =G26*E26 -> 126.768 | I26: =H26*F26 -> 3685187.6 | J26: 0.081 | K26: =20888552/1.19 -> 17553405 | L26: =J26*K26 -> 1421825.8 | M26: 0.1 | N26: =IF(I26>L26,M26*I26,M26*L26) -> 368518.76 | O26: 0.05 | P26: =IF(I26>L26,O26*I26,O26*L26) -> 184259.38 | Q26: 0.44 | R26: =Q26*E26 -> 46.4816 | S26: =R26*F26 -> 1351235.5 | T26: =IF(I26>L26,I26,L26)+N26+P26+S26 -> 5589201.2 | U26: =T26*19% -> 1061948.2 | V26: =T26+U26 -> 6651149.4 | X26: 0 | Y26: 0 | Z26: 0 | AA26: 0 | AB26: 0 | AC26: =SUM(X26:AB26) -> 0 | AE26: =AC26-T26 -> -5589201.2 | AG26: Sin Factura | AH26: =IF(I26>L26,I26,L26)-X26 -> 3685187.6 | AI26: =N26-Y26 -> 368518.76 | AJ26: =P26-Z26 -> 184259.38 | AK26: =S26-AA26 -> 1351235.5 | AL26: =0-AB26 -> 0 | AM26: =SUM(AH26:AL26) -> 5589201.2 | AO26: No tengo factura
B27: Mall Plaza Egaña | C27: Enero | D27: 2021 | E27: 105.64 | F27: 29123.74 | G27: 1.2 | H27: =G27*E27 -> 126.768 | I27: =H27*F27 -> 3691958.3 | J27: 0.081 | K27: =21509390/1.19 -> 18075118 | L27: =J27*K27 -> 1464084.5 | M27: 0.1 | N27: =IF(I27>L27,M27*I27,M27*L27) -> 369195.83 | O27: 0.05 | P27: =IF(I27>L27,O27*I27,O27*L27) -> 184597.91 | Q27: 0.44 | R27: =Q27*E27 -> 46.4816 | S27: =R27*F27 -> 1353718 | T27: =IF(I27>L27,I27,L27)+N27+P27+S27 -> 5599470 | U27: =T27*19% -> 1063899.3 | V27: =T27+U27 -> 6663369.4 | X27: 0 | Y27: 0 | Z27: 0 | AA27: 0 | AB27: 0 | AC27: =SUM(X27:AB27) -> 0 | AE27: =AC27-T27 -> -5599470 | AG27: Sin Factura | AH27: =IF(I27>L27,I27,L27)-X27 -> 3691958.3 | AI27: =N27-Y27 -> 369195.83 | AJ27: =P27-Z27 -> 184597.91 | AK27: =S27-AA27 -> 1353718 | AL27: =0-AB27 -> 0 | AM27: =SUM(AH27:AL27) -> 5599470 | AO27: No tengo factura
B28: Mall Plaza Egaña | C28: Febrero | D28: 2021 | E28: 105.64 | F28: 29287.38 | G28: 1.2 | H28: =G28*E28 -> 126.768 | I28: =H28*F28 -> 3712702.6 | J28: 0.081 | K28: =26053991/1.19 -> 21894110 | L28: =J28*K28 -> 1773422.9 | M28: 0.1 | N28: =IF(I28>L28,M28*I28,M28*L28) -> 371270.26 | O28: 0.05 | P28: =IF(I28>L28,O28*I28,O28*L28) -> 185635.13 | Q28: 0.44 | R28: =Q28*E28 -> 46.4816 | S28: =R28*F28 -> 1361324.3 | T28: =IF(I28>L28,I28,L28)+N28+P28+S28 -> 5630932.3 | U28: =T28*19% -> 1069877.1 | V28: =T28+U28 -> 6700809.4 | X28: 0 | Y28: 0 | Z28: 0 | AA28: 0 | AB28: 0 | AC28: =SUM(X28:AB28) -> 0 | AE28: =AC28-T28 -> -5630932.3 | AG28: Sin Factura | AH28: =IF(I28>L28,I28,L28)-X28 -> 3712702.6 | AI28: =N28-Y28 -> 371270.26 | AJ28: =P28-Z28 -> 185635.13 | AK28: =S28-AA28 -> 1361324.3 | AL28: =0-AB28 -> 0 | AM28: =SUM(AH28:AL28) -> 5630932.3 | AO28: No tengo factura
B29: Mall Plaza Egaña | C29: Marzo | D29: 2021 | E29: 105.64 | F29: 29394.77 | G29: 1.2 | H29: =G29*E29 -> 126.768 | I29: =H29*F29 -> 3726316.2 | J29: 0.081 | K29: =13766428/1.19 -> 11568427 | L29: =J29*K29 -> 937042.58 | M29: 0.1 | N29: =IF(I29>L29,M29*I29,M29*L29) -> 372631.62 | O29: 0.05 | P29: =IF(I29>L29,O29*I29,O29*L29) -> 186315.81 | Q29: 0.44 | R29: =Q29*E29 -> 46.4816 | S29: =R29*F29 -> 1366315.9 | T29: =IF(I29>L29,I29,L29)+N29+P29+S29 -> 5651579.6 | U29: =T29*19% -> 1073800.1 | V29: =T29+U29 -> 6725379.7 | X29: 0 | Y29: 0 | Z29: 0 | AA29: 0 | AB29: 0 | AC29: =SUM(X29:AB29) -> 0 | AE29: =AC29-T29 -> -5651579.6 | AG29: Sin Factura | AH29: =IF(I29>L29,I29,L29)-X29 -> 3726316.2 | AI29: =N29-Y29 -> 372631.62 | AJ29: =P29-Z29 -> 186315.81 | AK29: =S29-AA29 -> 1366315.9 | AL29: =0-AB29 -> 0 | AM29: =SUM(AH29:AL29) -> 5651579.6 | AO29: No tengo factura
B30: Mall Plaza Egaña | C30: Abril | D30: 2021 | E30: 105.64 | F30: 29494.13 | G30: 1.2 | H30: =G30*E30 -> 126.768 | I30: =H30*F30 -> 3738911.9 | J30: 0.081 | K30: 0 | L30: =J30*K30 -> 0 | M30: 0.1 | N30: =IF(I30>L30,M30*I30,M30*L30) -> 373891.19 | O30: 0.05 | P30: =IF(I30>L30,O30*I30,O30*L30) -> 186945.59 | Q30: 0.44 | R30: =Q30*E30 -> 46.4816 | S30: =R30*F30 -> 1370934.4 | T30: =IF(I30>L30,I30,L30)+N30+P30+S30 -> 5670683 | U30: =T30*19% -> 1077429.8 | V30: =T30+U30 -> 6748112.8 | X30: =17023387+2940253+249261 -> 20212901 | Y30: 0 | Z30: 0 | AA30: 0 | AB30: =24926 -> 24926 | AC30: =SUM(X30:AB30) -> 20237827 | AE30: =AC30-T30 -> 14567144 | AG30: F/139434 + F/141817 | AH30: =IF(I30>L30,I30,L30)-X30 -> -16473989 | AI30: =N30-Y30 -> 373891.19 | AJ30: =P30-Z30 -> 186945.59 | AK30: =S30-AA30 -> 1370934.4 | AL30: =0-AB30 -> -24926 | AM30: =SUM(AH30:AL30) -> -14567144 | AO30: Factura no viene abierta por concepto
B31: Mall Plaza Egaña | C31: Mayo | D31: 2021 | E31: 105.64 | F31: 29613.26 | G31: 1.2 | H31: =G31*E31 -> 126.768 | I31: =H31*F31 -> 3754013.7 | J31: 0.081 | K31: =40712652/1.19 -> 34212313 | L31: =J31*K31 -> 2771197.3 | M31: 0.1 | N31: =IF(I31>L31,M31*I31,M31*L31) -> 375401.37 | O31: 0.05 | P31: =IF(I31>L31,O31*I31,O31*L31) -> 187700.69 | Q31: 0.44 | R31: =Q31*E31 -> 46.4816 | S31: =R31*F31 -> 1376471.7 | T31: =IF(I31>L31,I31,L31)+N31+P31+S31 -> 5693587.5 | U31: =T31*19% -> 1081781.6 | V31: =T31+U31 -> 6775369.1 | X31: =4984820+663215 -> 5648035 | Y31: 0 | Z31: 0 | AA31: 0 | AB31: 0 | AC31: =SUM(X31:AB31) -> 5648035 | AE31: =AC31-T31 -> -45552.511 | AG31: F/141561 | AH31: =IF(I31>L31,I31,L31)-X31 -> -1894021.3 | AI31: =N31-Y31 -> 375401.37 | AJ31: =P31-Z31 -> 187700.69 | AK31: =S31-AA31 -> 1376471.7 | AL31: =0-AB31 -> 0 | AM31: =SUM(AH31:AL31) -> 45552.511 | AO31: Factura no viene abierta por concepto
B32: Mall Plaza Egaña | C32: Junio | D32: 2021 | E32: 105.64 | F32: 29709.83 | G32: 1.2 | H32: =G32*E32 -> 126.768 | I32: =H32*F32 -> 3766255.7 | J32: 0.081 | K32: =19234136/1.19 -> 16163139 | L32: =J32*K32 -> 1309214.3 | M32: 0.1 | N32: =IF(I32>L32,M32*I32,M32*L32) -> 376625.57 | O32: 0.05 | P32: =IF(I32>L32,O32*I32,O32*L32) -> 188312.79 | Q32: 0.44 | R32: =Q32*E32 -> 46.4816 | S32: =R32*F32 -> 1380960.4 | T32: =IF(I32>L32,I32,L32)+N32+P32+S32 -> 5712154.5 | U32: =T32*19% -> 1085309.4 | V32: =T32+U32 -> 6797463.9 | X32: =4977402+663215 -> 5640617 | Y32: 0 | Z32: 0 | AA32: 0 | AB32: =-1971783-375822 -> -2347605 | AC32: =SUM(X32:AB32) -> 3293012 | AE32: =AC32-T32 -> -2419142.5 | AG32: F/142856 + NC/28072 | AH32: =IF(I32>L32,I32,L32)-X32 -> -1874361.3 | AI32: =N32-Y32 -> 376625.57 | AJ32: =P32-Z32 -> 188312.79 | AK32: =S32-AA32 -> 1380960.4 | AL32: =0-AB32 -> 2347605 | AM32: =SUM(AH32:AL32) -> 2419142.5 | AO32: Factura no viene abierta por concepto
B33: Mall Plaza Egaña | C33: Julio | D33: 2021 | E33: 105.64 | F33: 29757.64 | G33: 1.2 | H33: =G33*E33 -> 126.768 | I33: =H33*F33 -> 3772316.5 | J33: 0.081 | K33: =27086698/1.19 -> 22761931 | L33: =J33*K33 -> 1843716.4 | M33: 0.1 | N33: =IF(I33>L33,M33*I33,M33*L33) -> 377231.65 | O33: 0.05 | P33: =IF(I33>L33,O33*I33,O33*L33) -> 188615.83 | Q33: 0.44 | R33: =Q33*E33 -> 46.4816 | S33: =R33*F33 -> 1383182.7 | T33: =IF(I33>L33,I33,L33)+N33+P33+S33 -> 5721346.7 | U33: =T33*19% -> 1087055.9 | V33: =T33+U33 -> 6808402.6 | X33: =5161438+663215 -> 5824653 | Y33: 0 | Z33: 0 | AA33: 0 | AB33: 0 | AC33: =SUM(X33:AB33) -> 5824653 | AE33: =AC33-T33 -> 103306.3 | AG33: F/144528 | AH33: =IF(I33>L33,I33,L33)-X33 -> -2052336.5 | AI33: =N33-Y33 -> 377231.65 | AJ33: =P33-Z33 -> 188615.83 | AK33: =S33-AA33 -> 1383182.7 | AL33: =0-AB33 -> 0 | AM33: =SUM(AH33:AL33) -> -103306.3 | AO33: Factura no viene abierta por concepto
B34: Mall Plaza Egaña | C34: Agosto | D34: 2021 | E34: 105.64 | F34: 29935.08 | G34: 1.2 | H34: =G34*E34 -> 126.768 | I34: =H34*F34 -> 3794810.2 | J34: 0.081 | K34: =28992503/1.19 -> 24363448 | L34: =J34*K34 -> 1973439.3 | M34: 0.1 | N34: =IF(I34>L34,M34*I34,M34*L34) -> 379481.02 | O34: 0.05 | P34: =IF(I34>L34,O34*I34,O34*L34) -> 189740.51 | Q34: 0.44 | R34: =Q34*E34 -> 46.4816 | S34: =R34*F34 -> 1391430.4 | T34: =IF(I34>L34,I34,L34)+N34+P34+S34 -> 5755462.2 | U34: =T34*19% -> 1093537.8 | V34: =T34+U34 -> 6849000 | X34: =5039995+676940 -> 5716935 | Y34: 0 | Z34: 0 | AA34: 0 | AB34: 0 | AC34: =SUM(X34:AB34) -> 5716935 | AE34: =AC34-T34 -> -38527.169 | AG34: F/146330 | AH34: =IF(I34>L34,I34,L34)-X34 -> -1922124.8 | AI34: =N34-Y34 -> 379481.02 | AJ34: =P34-Z34 -> 189740.51 | AK34: =S34-AA34 -> 1391430.4 | AL34: =0-AB34 -> 0 | AM34: =SUM(AH34:AL34) -> 38527.169 | AO34: Factura no viene abierta por concepto
B35: Mall Plaza Egaña | C35: Septiembre | D35: 2021 | E35: 105.64 | F35: 30088.37 | G35: 1.2 | H35: =G35*E35 -> 126.768 | I35: =H35*F35 -> 3814242.5 | J35: 0.081 | K35: =31507730/1.19 -> 26477084 | L35: =J35*K35 -> 2144643.8 | M35: 0.1 | N35: =IF(I35>L35,M35*I35,M35*L35) -> 381424.25 | O35: 0.05 | P35: =IF(I35>L35,O35*I35,O35*L35) -> 190712.12 | Q35: 0.44 | R35: =Q35*E35 -> 46.4816 | S35: =R35*F35 -> 1398555.6 | T35: =IF(I35>L35,I35,L35)+N35+P35+S35 -> 5784934.4 | U35: =T35*19% -> 1099137.5 | V35: =T35+U35 -> 6884072 | X35: =5120671+676940 -> 5797611 | Y35: 0 | Z35: 0 | AA35: 0 | AB35: 4086 | AC35: =SUM(X35:AB35) -> 5801697 | AE35: =AC35-T35 -> 16762.56 | AG35: F/147858 + F/44411 | AH35: =IF(I35>L35,I35,L35)-X35 -> -1983368.5 | AI35: =N35-Y35 -> 381424.25 | AJ35: =P35-Z35 -> 190712.12 | AK35: =S35-AA35 -> 1398555.6 | AL35: =0-AB35 -> -4086 | AM35: =SUM(AH35:AL35) -> -16762.56 | AO35: Factura no viene abierta por concepto
B36: Mall Plaza Egaña | C36: Octubre | D36: 2021 | E36: 105.64 | F36: 30380.53 | G36: 1.2 | H36: =G36*E36 -> 126.768 | I36: =H36*F36 -> 3851279 | J36: 0.081 | K36: =41468422/1.19 -> 34847413 | L36: =J36*K36 -> 2822640.5 | M36: 0.1 | N36: =IF(I36>L36,M36*I36,M36*L36) -> 385127.9 | O36: 0.05 | P36: =IF(I36>L36,O36*I36,O36*L36) -> 192563.95 | Q36: 0.44 | R36: =Q36*E36 -> 46.4816 | S36: =R36*F36 -> 1412135.6 | T36: =IF(I36>L36,I36,L36)+N36+P36+S36 -> 5841106.5 | U36: =T36*19% -> 1109810.2 | V36: =T36+U36 -> 6950916.8 | X36: =5154424+676940 -> 5831364 | Y36: 0 | Z36: 0 | AA36: 0 | AB36: 0 | AC36: =SUM(X36:AB36) -> 5831364 | AE36: =AC36-T36 -> -9742.5243 | AG36: F/149427 | AH36: =IF(I36>L36,I36,L36)-X36 -> -1980085 | AI36: =N36-Y36 -> 385127.9 | AJ36: =P36-Z36 -> 192563.95 | AK36: =S36-AA36 -> 1412135.6 | AL36: =0-AB36 -> 0 | AM36: =SUM(AH36:AL36) -> 9742.5243 | AO36: Factura no viene abierta por concepto
B37: Mall Plaza Vespucio | C37: Diciembre | D37: 2020 | E37: 68 | F37: 29070.33 | G37: 1.5 | H37: =G37*E37 -> 102 | I37: =H37*F37 -> 2965173.7 | J37: 0.081 | K37: =14071565/1.19 -> 11824845 | L37: =J37*K37 -> 957812.41 | M37: 0.1 | N37: =IF(I37>L37,M37*I37,M37*L37) -> 296517.37 | O37: 0.05 | P37: =IF(I37>L37,O37*I37,O37*L37) -> 148258.68 | Q37: 0.44 | R37: =Q37*E37 -> 29.92 | S37: =R37*F37 -> 869784.27 | T37: =IF(I37>L37,I37,L37)+N37+P37+S37 -> 4279734 | U37: =T37*19% -> 813149.46 | V37: =T37+U37 -> 5092883.4 | X37: 0 | Y37: 0 | Z37: 0 | AA37: 0 | AB37: 0 | AC37: =SUM(X37:AB37) -> 0 | AE37: =AC37-T37 -> -4279734 | AG37: Sin Factura | AH37: =IF(I37>L37,I37,L37)-X37 -> 2965173.7 | AI37: =N37-Y37 -> 296517.37 | AJ37: =P37-Z37 -> 148258.68 | AK37: =S37-AA37 -> 869784.27 | AL37: =0-AB37 -> 0 | AM37: =SUM(AH37:AL37) -> 4279734 | AO37: No tengo factura
B38: Mall Plaza Vespucio | C38: Enero | D38: 2021 | E38: 68 | F38: 29123.74 | G38: 1.5 | H38: =G38*E38 -> 102 | I38: =H38*F38 -> 2970621.5 | J38: 0.081 | K38: =27746723/1.19 -> 23316574 | L38: =J38*K38 -> 1888642.5 | M38: 0.1 | N38: =IF(I38>L38,M38*I38,M38*L38) -> 297062.15 | O38: 0.05 | P38: =IF(I38>L38,O38*I38,O38*L38) -> 148531.07 | Q38: 0.44 | R38: =Q38*E38 -> 29.92 | S38: =R38*F38 -> 871382.3 | T38: =IF(I38>L38,I38,L38)+N38+P38+S38 -> 4287597 | U38: =T38*19% -> 814643.43 | V38: =T38+U38 -> 5102240.4 | X38: 0 | Y38: 0 | Z38: 0 | AA38: 0 | AB38: 0 | AC38: =SUM(X38:AB38) -> 0 | AE38: =AC38-T38 -> -4287597 | AG38: Sin Factura | AH38: =IF(I38>L38,I38,L38)-X38 -> 2970621.5 | AI38: =N38-Y38 -> 297062.15 | AJ38: =P38-Z38 -> 148531.07 | AK38: =S38-AA38 -> 871382.3 | AL38: =0-AB38 -> 0 | AM38: =SUM(AH38:AL38) -> 4287597 | AO38: No tengo factura
B39: Mall Plaza Vespucio | C39: Febrero | D39: 2021 | E39: 68 | F39: 29287.38 | G39: 1.5 | H39: =G39*E39 -> 102 | I39: =H39*F39 -> 2987312.8 | J39: 0.081 | K39: =29438751/1.19 -> 24738446 | L39: =J39*K39 -> 2003814.1 | M39: 0.1 | N39: =IF(I39>L39,M39*I39,M39*L39) -> 298731.28 | O39: 0.05 | P39: =IF(I39>L39,O39*I39,O39*L39) -> 149365.64 | Q39: 0.44 | R39: =Q39*E39 -> 29.92 | S39: =R39*F39 -> 876278.41 | T39: =IF(I39>L39,I39,L39)+N39+P39+S39 -> 4311688.1 | U39: =T39*19% -> 819220.74 | V39: =T39+U39 -> 5130908.8 | X39: 0 | Y39: 0 | Z39: 0 | AA39: 0 | AB39: 0 | AC39: =SUM(X39:AB39) -> 0 | AE39: =AC39-T39 -> -4311688.1 | AG39: Sin Factura | AH39: =IF(I39>L39,I39,L39)-X39 -> 2987312.8 | AI39: =N39-Y39 -> 298731.28 | AJ39: =P39-Z39 -> 149365.64 | AK39: =S39-AA39 -> 876278.41 | AL39: =0-AB39 -> 0 | AM39: =SUM(AH39:AL39) -> 4311688.1 | AO39: No tengo factura
B40: Mall Plaza Vespucio | C40: Marzo | D40: 2021 | E40: 68 | F40: 29394.77 | G40: 1.5 | H40: =G40*E40 -> 102 | I40: =H40*F40 -> 2998266.5 | J40: 0.081 | K40: =12859645/1.19 -> 10806424 | L40: =J40*K40 -> 875320.37 | M40: 0.1 | N40: =IF(I40>L40,M40*I40,M40*L40) -> 299826.65 | O40: 0.05 | P40: =IF(I40>L40,O40*I40,O40*L40) -> 149913.33 | Q40: 0.44 | R40: =Q40*E40 -> 29.92 | S40: =R40*F40 -> 879491.52 | T40: =IF(I40>L40,I40,L40)+N40+P40+S40 -> 4327498 | U40: =T40*19% -> 822224.63 | V40: =T40+U40 -> 5149722.7 | X40: =5654430+2399664 -> 8054094 | Y40: 0 | Z40: 0 | AA40: 0 | AB40: =-1405685-599916 -> -2005601 | AC40: =SUM(X40:AB40) -> 6048493 | AE40: =AC40-T40 -> 1720995 | AG40: F/71202 + NC/4031 | AH40: =IF(I40>L40,I40,L40)-X40 -> -5055827.5 | AI40: =N40-Y40 -> 299826.65 | AJ40: =P40-Z40 -> 149913.33 | AK40: =S40-AA40 -> 879491.52 | AL40: =0-AB40 -> 2005601 | AM40: =SUM(AH40:AL40) -> -1720995 | AO40: No tengo factura
B41: Mall Plaza Vespucio | C41: Abril | D41: 2021 | E41: 68 | F41: 29494.13 | G41: 1.5 | H41: =G41*E41 -> 102 | I41: =H41*F41 -> 3008401.3 | J41: 0.081 | K41: 0 | L41: =J41*K41 -> 0 | M41: 0.1 | N41: =IF(I41>L41,M41*I41,M41*L41) -> 300840.13 | O41: 0.05 | P41: =IF(I41>L41,O41*I41,O41*L41) -> 150420.06 | Q41: 0.44 | R41: =Q41*E41 -> 29.92 | S41: =R41*F41 -> 882464.37 | T41: =IF(I41>L41,I41,L41)+N41+P41+S41 -> 4342125.8 | U41: =T41*19% -> 825003.91 | V41: =T41+U41 -> 5167129.7 | X41: 3038786 | Y41: 0 | Z41: 0 | AA41: 0 | AB41: 0 | AC41: =SUM(X41:AB41) -> 3038786 | AE41: =AC41-T41 -> -1303339.8 | AG41: F/106575 | AH41: =IF(I41>L41,I41,L41)-X41 -> -30384.74 | AI41: =N41-Y41 -> 300840.13 | AJ41: =P41-Z41 -> 150420.06 | AK41: =S41-AA41 -> 882464.37 | AL41: =0-AB41 -> 0 | AM41: =SUM(AH41:AL41) -> 1303339.8 | AO41: Factura no viene abierta por concepto
B42: Mall Plaza Vespucio | C42: Mayo | D42: 2021 | E42: 68 | F42: 29613.26 | G42: 1.5 | H42: =G42*E42 -> 102 | I42: =H42*F42 -> 3020552.5 | J42: 0.081 | K42: 0 | L42: =J42*K42 -> 0 | M42: 0.1 | N42: =IF(I42>L42,M42*I42,M42*L42) -> 302055.25 | O42: 0.05 | P42: =IF(I42>L42,O42*I42,O42*L42) -> 151027.63 | Q42: 0.44 | R42: =Q42*E42 -> 29.92 | S42: =R42*F42 -> 886028.74 | T42: =IF(I42>L42,I42,L42)+N42+P42+S42 -> 4359664.1 | U42: =T42*19% -> 828336.19 | V42: =T42+U42 -> 5188000.3 | X42: 973640 | Y42: 0 | Z42: 0 | AA42: 0 | AB42: 0 | AC42: =SUM(X42:AB42) -> 973640 | AE42: =AC42-T42 -> -3386024.1 | AG42: F/107246 | AH42: =IF(I42>L42,I42,L42)-X42 -> 2046912.5 | AI42: =N42-Y42 -> 302055.25 | AJ42: =P42-Z42 -> 151027.63 | AK42: =S42-AA42 -> 886028.74 | AL42: =0-AB42 -> 0 | AM42: =SUM(AH42:AL42) -> 3386024.1 | AO42: Factura no viene abierta por concepto
B43: Mall Plaza Vespucio | C43: Junio | D43: 2021 | E43: 68 | F43: 29709.83 | G43: 1.5 | H43: =G43*E43 -> 102 | I43: =H43*F43 -> 3030402.7 | J43: 0.081 | K43: =4155815/1.19 -> 3492281.5 | L43: =J43*K43 -> 282874.8 | M43: 0.1 | N43: =IF(I43>L43,M43*I43,M43*L43) -> 303040.27 | O43: 0.05 | P43: =IF(I43>L43,O43*I43,O43*L43) -> 151520.13 | Q43: 0.44 | R43: =Q43*E43 -> 29.92 | S43: =R43*F43 -> 888918.11 | T43: =IF(I43>L43,I43,L43)+N43+P43+S43 -> 4373881.2 | U43: =T43*19% -> 831037.42 | V43: =T43+U43 -> 5204918.6 | X43: =819230+107178+599916 -> 1526324 | Y43: 0 | Z43: 0 | AA43: 0 | AB43: 0 | AC43: =SUM(X43:AB43) -> 1526324 | AE43: =AC43-T43 -> -2847557.2 | AG43: F/107611 + F/71561 | AH43: =IF(I43>L43,I43,L43)-X43 -> 1504078.7 | AI43: =N43-Y43 -> 303040.27 | AJ43: =P43-Z43 -> 151520.13 | AK43: =S43-AA43 -> 888918.11 | AL43: =0-AB43 -> 0 | AM43: =SUM(AH43:AL43) -> 2847557.2 | AO43: Factura no viene abierta por concepto
B44: Mall Plaza Vespucio | C44: Julio | D44: 2021 | E44: 68 | F44: 29757.64 | G44: 1.5 | H44: =G44*E44 -> 102 | I44: =H44*F44 -> 3035279.3 | J44: 0.081 | K44: =29053167/1.19 -> 24414426 | L44: =J44*K44 -> 1977568.5 | M44: 0.1 | N44: =IF(I44>L44,M44*I44,M44*L44) -> 303527.93 | O44: 0.05 | P44: =IF(I44>L44,O44*I44,O44*L44) -> 151763.96 | Q44: 0.44 | R44: =Q44*E44 -> 29.92 | S44: =R44*F44 -> 890348.59 | T44: =IF(I44>L44,I44,L44)+N44+P44+S44 -> 4380919.8 | U44: =T44*19% -> 832374.75 | V44: =T44+U44 -> 5213294.5 | X44: =842822+2435363+599916 -> 3878101 | Y44: 0 | Z44: 0 | AA44: 0 | AB44: 0 | AC44: =SUM(X44:AB44) -> 3878101 | AE44: =AC44-T44 -> -502818.76 | AG44: F/108086 + F/71442 | AH44: =IF(I44>L44,I44,L44)-X44 -> -842821.72 | AI44: =N44-Y44 -> 303527.93 | AJ44: =P44-Z44 -> 151763.96 | AK44: =S44-AA44 -> 890348.59 | AL44: =0-AB44 -> 0 | AM44: =SUM(AH44:AL44) -> 502818.76 | AO44: Factura no viene abierta por concepto
B45: Mall Plaza Vespucio | C45: Agosto | D45: 2021 | E45: 68 | F45: 29935.08 | G45: 1.5 | H45: =G45*E45 -> 102 | I45: =H45*F45 -> 3053378.2 | J45: 0.081 | K45: =31071060/1.19 -> 26110134 | L45: =J45*K45 -> 2114920.9 | M45: 0.1 | N45: =IF(I45>L45,M45*I45,M45*L45) -> 305337.82 | O45: 0.05 | P45: =IF(I45>L45,O45*I45,O45*L45) -> 152668.91 | Q45: 0.44 | R45: =Q45*E45 -> 29.92 | S45: =R45*F45 -> 895657.59 | T45: =IF(I45>L45,I45,L45)+N45+P45+S45 -> 4407042.5 | U45: =T45*19% -> 837338.07 | V45: =T45+U45 -> 5244380.5 | X45: =845573+2427897+625481 -> 3898951 | Y45: 0 | Z45: 0 | AA45: 0 | AB45: 0 | AC45: =SUM(X45:AB45) -> 3898951 | AE45: =AC45-T45 -> -508091.48 | AG45: F/108653 + F/71741 | AH45: =IF(I45>L45,I45,L45)-X45 -> -845572.84 | AI45: =N45-Y45 -> 305337.82 | AJ45: =P45-Z45 -> 152668.91 | AK45: =S45-AA45 -> 895657.59 | AL45: =0-AB45 -> 0 | AM45: =SUM(AH45:AL45) -> 508091.48 | AO45: Factura no viene abierta por concepto
B46: Mall Plaza Vespucio | C46: Septiembre | D46: 2021 | E46: 68 | F46: 30088.37 | G46: 1.5 | H46: =G46*E46 -> 102 | I46: =H46*F46 -> 3069013.7 | J46: 0.081 | K46: =32590070/1.19 -> 27386613 | L46: =J46*K46 -> 2218315.7 | M46: 0.1 | N46: =IF(I46>L46,M46*I46,M46*L46) -> 306901.37 | O46: 0.05 | P46: =IF(I46>L46,O46*I46,O46*L46) -> 153450.69 | Q46: 0.44 | R46: =Q46*E46 -> 29.92 | S46: =R46*F46 -> 900244.03 | T46: =IF(I46>L46,I46,L46)+N46+P46+S46 -> 4429609.8 | U46: =T46*19% -> 841625.87 | V46: =T46+U46 -> 5271235.7 | X46: =1000876+2443533+625481 -> 4069890 | Y46: 0 | Z46: 0 | AA46: 0 | AB46: 0 | AC46: =SUM(X46:AB46) -> 4069890 | AE46: =AC46-T46 -> -359719.83 | AG46: F/109080 + F/71940 | AH46: =IF(I46>L46,I46,L46)-X46 -> -1000876.3 | AI46: =N46-Y46 -> 306901.37 | AJ46: =P46-Z46 -> 153450.69 | AK46: =S46-AA46 -> 900244.03 | AL46: =0-AB46 -> 0 | AM46: =SUM(AH46:AL46) -> 359719.83 | AO46: Factura no viene abierta por concepto
B47: Mall Plaza Vespucio | C47: Octubre | D47: 2021 | E47: 68 | F47: 30380.53 | G47: 1.5 | H47: =G47*E47 -> 102 | I47: =H47*F47 -> 3098814.1 | J47: 0.081 | K47: =40808431/1.19 -> 34292799 | L47: =J47*K47 -> 2777716.7 | M47: 0.1 | N47: =IF(I47>L47,M47*I47,M47*L47) -> 309881.41 | O47: 0.05 | P47: =IF(I47>L47,O47*I47,O47*L47) -> 154940.7 | Q47: 0.44 | R47: =Q47*E47 -> 29.92 | S47: =R47*F47 -> 908985.46 | T47: =IF(I47>L47,I47,L47)+N47+P47+S47 -> 4472621.6 | U47: =T47*19% -> 849798.11 | V47: =T47+U47 -> 5322419.7 | X47: =975760+2473333+65481 -> 3514574 | Y47: 0 | Z47: 0 | AA47: 0 | AB47: 0 | AC47: =SUM(X47:AB47) -> 3514574 | AE47: =AC47-T47 -> -958047.63 | AG47: F/109518 + F/72152 | AH47: =IF(I47>L47,I47,L47)-X47 -> -415759.94 | AI47: =N47-Y47 -> 309881.41 | AJ47: =P47-Z47 -> 154940.7 | AK47: =S47-AA47 -> 908985.46 | AL47: =0-AB47 -> 0 | AM47: =SUM(AH47:AL47) -> 958047.63 | AO47: Factura no viene abierta por concepto
B48: Mall Plaza El Trebol | C48: Diciembre | D48: 2020 | E48: 81.54 | F48: 29070.33 | G48: 1.4 | H48: =G48*E48 -> 114.156 | I48: =H48*F48 -> 3318552.6 | J48: 0.081 | K48: =0/1.19 -> 0 | L48: =J48*K48 -> 0 | M48: 0.1 | N48: =IF(I48>L48,M48*I48,M48*L48) -> 331855.26 | O48: 0.05 | P48: =IF(I48>L48,O48*I48,O48*L48) -> 165927.63 | Q48: 0.44 | R48: =Q48*E48 -> 35.8776 | S48: =R48*F48 -> 1042973.7 | T48: =IF(I48>L48,I48,L48)+N48+P48+S48 -> 4859309.2 | U48: =T48*19% -> 923268.74 | V48: =T48+U48 -> 5782577.9 | X48: 0 | Y48: 0 | Z48: 0 | AA48: 0 | AB48: 0 | AC48: =SUM(X48:AB48) -> 0 | AE48: =AC48-T48 -> -4859309.2 | AG48: Sin Factura | AH48: =IF(I48>L48,I48,L48)-X48 -> 3318552.6 | AI48: =N48-Y48 -> 331855.26 | AJ48: =P48-Z48 -> 165927.63 | AK48: =S48-AA48 -> 1042973.7 | AL48: =0-AB48 -> 0 | AM48: =SUM(AH48:AL48) -> 4859309.2 | AO48: No tengo factura
B49: Mall Plaza El Trebol | C49: Enero | D49: 2021 | E49: 81.54 | F49: 29123.74 | G49: 1.4 | H49: =G49*E49 -> 114.156 | I49: =H49*F49 -> 3324649.7 | J49: 0.081 | K49: =1643968/1.19 -> 1381485.7 | L49: =J49*K49 -> 111900.34 | M49: 0.1 | N49: =IF(I49>L49,M49*I49,M49*L49) -> 332464.97 | O49: 0.05 | P49: =IF(I49>L49,O49*I49,O49*L49) -> 166232.48 | Q49: 0.44 | R49: =Q49*E49 -> 35.8776 | S49: =R49*F49 -> 1044889.9 | T49: =IF(I49>L49,I49,L49)+N49+P49+S49 -> 4868237 | U49: =T49*19% -> 924965.03 | V49: =T49+U49 -> 5793202 | X49: =1144900+366400 -> 1511300 | Y49: 0 | Z49: 0 | AA49: 0 | AB49: 0 | AC49: =SUM(X49:AB49) -> 1511300 | AE49: =AC49-T49 -> -3356937 | AG49: F/95725 | AH49: =IF(I49>L49,I49,L49)-X49 -> 1813349.7 | AI49: =N49-Y49 -> 332464.97 | AJ49: =P49-Z49 -> 166232.48 | AK49: =S49-AA49 -> 1044889.9 | AL49: =0-AB49 -> 0 | AM49: =SUM(AH49:AL49) -> 3356937 | AO49: Descto Flexi - Factura no viene abierta por concepto
...

Sheet Cobros Adicionales
B2: Cobros Adicionales
B4: Maipu
B5: 1.Facturacion consumo Electricidad
B7: F/63046 | C7: 44245 | D7: Energia electrica | F7: 278189 | G7: =F7*19% -> 52855.91 | H7: =F7+G7 -> 331044.91
B8: F/63559 | C8: 44273 | D8: Energia electrica | F8: 273912 | G8: =F8*19% -> 52043.28 | H8: =F8+G8 -> 325955.28
B9: F/64092 | C9: 44305 | D9: Energia electrica | F9: 270237 | G9: =F9*19% -> 51345.03 | H9: =F9+G9 -> 321582.03
B10: F/64803 | C10: 44333 | D10: Energia electrica | F10: 213294 | G10: =F10*19% -> 40525.86 | H10: =F10+G10 -> 253819.86
B11: F/65513 | C11: 44364 | D11: Energia electrica | F11: 216445 | G11: =F11*19% -> 41124.55 | H11: =F11+G11 -> 257569.55
B12: F/66180 | C12: 44394 | D12: Energia electrica | F12: 232499 | G12: =F12*19% -> 44174.81 | H12: =F12+G12 -> 276673.81
B13: F/66793 | C13: 44426 | D13: Energia electrica | F13: 235276 | G13: =F13*19% -> 44702.44 | H13: =F13+G13 -> 279978.44
B14: F/67364 | C14: 44455 | D14: Energia electrica | F14: 273912 | G14: =F14*19% -> 52043.28 | H14: =F14+G14 -> 325955.28
B15: F/67936 | C15: 44487 | D15: Energia electrica | F15: 281640 | G15: =F15*19% -> 53511.6 | H15: =F15+G15 -> 335151.6
B17: Costanera Center
B18: 1.Recargo al valor minimo
B20: F/46254 | C20: 44505 | D20: Recargo VM | F20: 16437082 | G20: =F20*19% -> 3123045.6 | H20: =F20+G20 -> 19560128

Sheet Mayores Contables
B2: Estado de Resultado por Centro de Costo
B3: =+'[1]Estado de Resultados'!B3 -> Para el período comprendido entre el 01-01-2021 hasta el 31-10-2021
B6: A Octubre de 2021
B7: N° CUENTA | C7: NOMBRE CUENTA | D7: DOMINICOS | E7: EGAÑA | F7: MAIPU | G7: VESPUCIO | H7: TREBOL | I7: COSTANERA CENTER | J7: FLORIDA CENTER | K7: TOTAL
B9: 3105301 | C9: ARRIENDOS | D9: 20626077 | E9: 46670248 | F9: 24757252 | G9: 26201225 | H9: 34399228 | I9: 12811237 | J9: 0 | K9: =SUM(D9:J9) -> 165465267
B11: A diciembre de 2020
B12: N° CUENTA | C12: NOMBRE CUENTA | D12: DOMINICOS | E12: EGAÑA | F12: MAIPU | G12: VESPUCIO | H12: TREBOL | I12: COSTANERA CENTER | J12: FLORIDA CENTER | K12: TOTAL
B14: 3105301 | C14: ARRIENDOS | D14: 316896 | E14: 1842594 | F14: 872110 | G14: 1482587 | H14: 1659276 | I14: 0 | J14: 0 | K14: =SUM(D14:J14) -> 6173463
B16: Total Contabilizado | D16: =D9+D14 -> 20942973 | E16: =E9+E14 -> 48512842 | F16: =F9+F14 -> 25629362 | G16: =G9+G14 -> 27683812 | H16: =H9+H14 -> 36058504 | I16: =I9+I14 -> 12811237 | J16: =J9+J14 -> 0 | K16: =K9+K14 -> 171638730
B18: Total Facturas recibidas | D18: =SUM('Contrato vs Factura (mensual)'!AC15:AC25) -> 21248499 | E18: =SUM('Contrato vs Factura (mensual)'!AC26:AC36) -> 52353523 | F18: =SUM('Contrato vs Factura (mensual)'!AC59:AC69) -> 18136837 | G18: =SUM('Contrato vs Factura (mensual)'!AC37:AC47) -> 26948759 | H18: =SUM('Contrato vs Factura (mensual)'!AC48:AC58) -> 34399228 | I18: =SUM('Contrato vs Factura (mensual)'!AC70:AC72) -> 4641305 | J18: =SUM('Contrato vs Factura (mensual)'!AC73:AC75) -> 501797 | K18: =SUM(D18:J18) -> 158229948
B20: Diferencia Facturas V/S Contabilidad | D20: =D16-D18 -> -305526 | E20: =E16-E18 -> -3840681 | F20: =F16-F18 -> 7492525 | G20: =G16-G18 -> 735053 | H20: =H16-H18 -> 1659276 | I20: =I16-I18 -> 8169932 | J20: =J16-J18 -> -501797 | K20: =SUM(D20:J20) -> 13408782
B23: Gastos según contrato (valor neto) | D23: =SUM('Contrato vs Factura (mensual)'!T15:T25) -> 26136948 | E23: =SUM('Contrato vs Factura (mensual)'!T26:T36) -> 62650458 | F23: =SUM('Contrato vs Factura (mensual)'!T59:T69) -> 32650677 | G23: =SUM('Contrato vs Factura (mensual)'!T37:T47) -> 47972382 | H23: =SUM('Contrato vs Factura (mensual)'!T48:T58) -> 54468954 | I23: =SUM('Contrato vs Factura (mensual)'!T70:T72) -> 12187404 | J23: =SUM('Contrato vs Factura (mensual)'!T73:T75) -> 3268230.4 | K23: =SUM(D23:J23) -> 2.3933505e+08
B25: Diferencia Contabilidad V/S Contrato | D25: =D16-D23 -> -5193975.4 | E25: =E16-E23 -> -14137616 | F25: =F16-F23 -> -7021315 | G25: =G16-G23 -> -20288570 | H25: =H16-H23 -> -18410450 | I25: =I16-I23 -> 623833.03 | J25: =J16-J23 -> -3268230.4 | K25: =SUM(D25:J25) -> -67696324
B28: Nota:
B30: 1. Diferencia Facturas V/S Contabilidad, se debe revisar y ajustar en esta linea no deberia haber diferencia, ojo que puede estar ocacionada por mal registro de este archivo o error en connttabilización, o en su defecto provisión faactura no recibida.
B32: 2. Diferencia Contabilidad V/S Contrato, debe reflejar los descuentos obtenidos.
