Workbook
Name Balance2005: #REF!
Name Balance2005: #REF!
Name Balance2005: #REF!
Name Balance2005: #REF!
Name cod: #REF!
Name cod: #REF!
Name cod: #REF!
Name cod: #REF!
Name cod: #REF!
Name cod: #REF!
Name cod: #REF!
Name cod: #REF!
Name cod: #REF!
Name cod: #REF!
Name cod: #REF!
Name COSTOS: #REF!
Name COSTOS: #REF!
Name COSTOS: #REF!
Name COSTOS: #REF!
Name datos: #REF!
Name PJ: #REF!
Name PJ: #REF!
Name PJ: #REF!
Name PJ: #REF!
Name sumas: #REF!
Name sumas: #REF!
Name sumas: #REF!
Name sumas: #REF!
Name sumas: #REF!
Name sumas: #REF!
Name sumas: #REF!
Name sumas: #REF!
Name sumas: #REF!
Name sumas: #REF!
Name sumas: #REF!
Name uf: #REF!
Name uf: #REF!
Name uf: #REF!
Name uf: #REF!
Name uf: #REF!
Name uf: #REF!
Name uf: #REF!
Name uf: #REF!
Name uf: #REF!
Name uf: #REF!
Name uf: #REF!

Sheet Carátula
A7: Flexi Chile SpA
A8: Estados Financieros
A9: Al 31 de enero de 2026
E13: Contenidos:
E14: - Balance Clasificado
E15: - Estado de Resultados
E16: - Cuadro Patrimonial
E17: - Análisis y detalle de cuentas Activos y Pasivos
E18: - Agrupación principales cuentas de Resultados
E19: - Balance General

Sheet Balance Clasificado
B1: =+Carátula!A7 -> Flexi Chile SpA
B2: Balance Clasificado
B3: =+Carátula!A9 -> Al 31 de enero de 2026
B6: Tipo Cambio de Cierre $ 895,60 | C6: 865.1 | D6: 46053 | F6: =+D6 -> 46053
B7: ACTIVOS | F7: US$
B9: Activos circulante
B10: Caja y Bancos | D10: =SUMIF('Balance 8 Columnas'!A:O,'Balance Clasificado'!B10,'Balance 8 Columnas'!N:N) -> 892013701 | F10: =SUMIF('Balance 8 Columnas'!A:O,'Balance Clasificado'!B10,'Balance 8 Columnas'!#REF!) -> #REF!
B11: Derechos de arrendamiento | D11: =SUMIF('Balance 8 Columnas'!A:O,'Balance Clasificado'!B11,'Balance 8 Columnas'!N:N) -> 88703455 | F11: =SUMIF('Balance 8 Columnas'!A:O,'Balance Clasificado'!B11,'Balance 8 Columnas'!#REF!) -> #REF!
B12: Clientes | D12: =SUMIF('Balance 8 Columnas'!A:O,'Balance Clasificado'!B12,'Balance 8 Columnas'!N:N) -> 0 | F12: =SUMIF('Balance 8 Columnas'!A:O,'Balance Clasificado'!B12,'Balance 8 Columnas'!#REF!) -> #REF!
B13: Pagos anticipados | D13: =SUMIF('Balance 8 Columnas'!A:O,'Balance Clasificado'!B13,'Balance 8 Columnas'!N:N) -> 32614989 | F13: =SUMIF('Balance 8 Columnas'!A:O,'Balance Clasificado'!B13,'Balance 8 Columnas'!#REF!) -> #REF!
B14: Deudores Diversos | D14: =SUMIF('Balance 8 Columnas'!A:O,'Balance Clasificado'!B14,'Balance 8 Columnas'!N:N) -> 343622261 | F14: =SUMIF('Balance 8 Columnas'!A:O,'Balance Clasificado'!B14,'Balance 8 Columnas'!#REF!) -> #REF!
B15: Inventarios | D15: =SUMIF('Balance 8 Columnas'!A:O,'Balance Clasificado'!B15,'Balance 8 Columnas'!N:N) -> 1824159549 | F15: =SUMIF('Balance 8 Columnas'!A:O,'Balance Clasificado'!B15,'Balance 8 Columnas'!#REF!) -> #REF!
B16: Impuestos a favor | D16: =SUMIF('Balance 8 Columnas'!A:O,'Balance Clasificado'!B16,'Balance 8 Columnas'!N:N) -> 357340940 | F16: =SUMIF('Balance 8 Columnas'!A:O,'Balance Clasificado'!B16,'Balance 8 Columnas'!#REF!) -> #REF!
B17: Activos circulantes totales | D17: =SUM(D10:D16) -> 3538454895 | F17: =SUM(F10:F16) -> #REF!
B19: Activo Fijo
B20: Equipo de tiendas | D20: =SUMIF('Balance 8 Columnas'!A:O,'Balance Clasificado'!B20,'Balance 8 Columnas'!N:N) -> 684577620 | F20: =SUMIF('Balance 8 Columnas'!A:O,'Balance Clasificado'!B20,'Balance 8 Columnas'!#REF!) -> #REF!
B21: Equipo de cómputo | D21: =SUMIF('Balance 8 Columnas'!A:O,'Balance Clasificado'!B21,'Balance 8 Columnas'!N:N) -> 109578639 | F21: =SUMIF('Balance 8 Columnas'!A:O,'Balance Clasificado'!B21,'Balance 8 Columnas'!#REF!) -> #REF!
B22: Depreciación acumulada | D22: =SUMIF('Balance 8 Columnas'!A:O,'Balance Clasificado'!B22,'Balance 8 Columnas'!N:N) -> -247517086 | F22: =SUMIF('Balance 8 Columnas'!A:O,'Balance Clasificado'!B22,'Balance 8 Columnas'!#REF!) -> #REF!
B23: Total de activo fijo | D23: =SUM(D20:D22) -> 546639173 | F23: =SUM(F20:F22) -> #REF!
B25: TOTAL ACTIVOS | D25: =D17+D23 -> 4085094068 | F25: =F17+F23 -> #REF!
B27: PATRIMONIO Y PASIVOS
B28: Pasivos circulante
B29: Proveedores | D29: =-SUMIF('Balance 8 Columnas'!A:O,'Balance Clasificado'!B29,'Balance 8 Columnas'!N:N) -> 18137459 | F29: =-SUMIF('Balance 8 Columnas'!A:O,'Balance Clasificado'!B29,'Balance 8 Columnas'!#REF!) -> #REF!
B30: Acreedores diversos | D30: =-SUMIF('Balance 8 Columnas'!A:O,'Balance Clasificado'!B30,'Balance 8 Columnas'!N:N) -> 4298052 | F30: =-SUMIF('Balance 8 Columnas'!A:O,'Balance Clasificado'!B30,'Balance 8 Columnas'!#REF!) -> #REF!
B31: Impuestos nómina | D31: =-SUMIF('Balance 8 Columnas'!A:O,'Balance Clasificado'!B31,'Balance 8 Columnas'!N:N) -> 9957035 | F31: =-SUMIF('Balance 8 Columnas'!A:O,'Balance Clasificado'!B31,'Balance 8 Columnas'!#REF!) -> #REF!
B32: Cuentas por pagar a empresas realcionadas | D32: =-SUMIF('Balance 8 Columnas'!A:O,'Balance Clasificado'!B32,'Balance 8 Columnas'!N:N) -> 1381573301 | F32: =-SUMIF('Balance 8 Columnas'!A:O,'Balance Clasificado'!B32,'Balance 8 Columnas'!#REF!) -> #REF!
B33: Otros pasivos | D33: =-SUMIF('Balance 8 Columnas'!A:O,'Balance Clasificado'!B33,'Balance 8 Columnas'!N:N) -> 93838855 | F33: =-SUMIF('Balance 8 Columnas'!A:O,'Balance Clasificado'!B33,'Balance 8 Columnas'!#REF!) -> #REF!
B34: IVA por pagar del mes | D34: =-SUMIF('Balance 8 Columnas'!A:O,'Balance Clasificado'!B34,'Balance 8 Columnas'!N:N) -> 958952 | F34: =-SUMIF('Balance 8 Columnas'!A:O,'Balance Clasificado'!B34,'Balance 8 Columnas'!#REF!) -> #REF!
B36: Pasivos circulantes totales | D36: =SUM(D29:D35) -> 1508763654 | F36: =SUM(F29:F35) -> #REF!
B39: Patrimonio
B40: Capital social | D40: =-SUMIF('Balance 8 Columnas'!A:O,'Balance Clasificado'!B40,'Balance 8 Columnas'!N:N) -> 5770668867 | F40: =-SUMIF('Balance 8 Columnas'!A:O,'Balance Clasificado'!B40,'Balance 8 Columnas'!#REF!) -> #REF!
B41: Resultados acumulados | D41: =-SUMIF('Balance 8 Columnas'!A:O,'Balance Clasificado'!B41,'Balance 8 Columnas'!N:N) -> -3142106839 | F41: =-SUMIF('Balance 8 Columnas'!A:O,'Balance Clasificado'!B41,'Balance 8 Columnas'!#REF!)+'Estado de Resultados'!E29 -> #REF!
B42: perdida del periodo | D42: =+'Estado de Resultados'!C29 -> -52231614
B44: Patrimonio total | D44: =SUM(D40:D43) -> 2576330414 | F44: =SUM(F40:F43) -> #REF!
B46: TOTAL DE PATRIMONIO Y PASIVOS | D46: =+D44+D36 -> 4085094068 | F46: =+F44+F36 -> #REF!
D48: =+D46-D25 -> 0 | F48: =+F46-F25 -> #REF!

Sheet Clasificado
B1: FLEXI CHILE SPA
B2: SVS Estado de Situación Financiera Clasificado Final
E3: 44196
B4: Estado de Situación Financiera
B5: Activos | E5: $
B6: Activos corrientes
B7: Efectivo y Equivalentes al Efectivo | E7: =SUMIF('Balance 8 Columnas'!$A$10:$A$113,B7,'Balance 8 Columnas'!$N$10:$N$113) -> 0 | G7: Ver
B8: Activos financieros corrientes | E8: =SUMIF('Balance 8 Columnas'!$A$10:$A$113,B8,'Balance 8 Columnas'!$N$10:$N$113) -> 0 | G8: Ver
B9: Otros Activos No Financieros, Corriente | E9: =SUMIF('Balance 8 Columnas'!$A$10:$A$113,B9,'Balance 8 Columnas'!$N$10:$N$113) -> 0 | G9: Ver
B10: Deudores comerciales y otras cuentas por cobrar corrientes | E10: =SUMIF('Balance 8 Columnas'!$A$10:$A$113,B10,'Balance 8 Columnas'!$N$10:$N$113) -> 0 | G10: Ver
B11: Cuentas por Cobrar a Entidades Relacionadas, Corrientes | E11: =SUMIF('Balance 8 Columnas'!$A$10:$A$113,B11,'Balance 8 Columnas'!$N$10:$N$113) -> 0
B12: Inventarios corrientes | E12: =SUMIF('Balance 8 Columnas'!$A$10:$A$113,B12,'Balance 8 Columnas'!$N$10:$N$113) -> 0
B13: Activos biológicos corrientes | E13: =SUMIF('Balance 8 Columnas'!$A$10:$A$113,B13,'Balance 8 Columnas'!$N$10:$N$113) -> 0
B14: Activos por impuestos corrientes | E14: =SUMIF('Balance 8 Columnas'!$A$10:$A$113,B14,'Balance 8 Columnas'!$N$10:$N$113) -> 0 | G14: Ver
B15: Total de activos corrientes distintos de los activos o grupos de activos para su disposición clasificados como mantenidos para la venta o como mantenidos para distribuir a los propietarios | E15: =SUM(E7:E14) -> 0
B16: Activos no corrientes o grupos de activos para su disposición clasificados como mantenidos para la venta | E16: =SUMIF('Balance 8 Columnas'!$A$10:$A$113,B16,'Balance 8 Columnas'!$N$10:$N$113) -> 0
B17: Activos no corrientes o grupos de activos para su disposición clasificados como mantenidos para distribuir a los propietarios | E17: =SUMIF('Balance 8 Columnas'!$A$10:$A$113,B17,'Balance 8 Columnas'!$N$10:$N$113) -> 0
B18: Activos no corrientes o grupos de activos para su disposición clasificados como mantenidos para la venta o como mantenidos para distribuir a los propietarios | E18: 0
B19: Activos corrientes totales | E19: =SUM(E15:E17) -> 0
B20: Activos no corrientes
B21: Otros activos financieros no corrientes | E21: =SUMIF('Balance 8 Columnas'!$A$10:$A$113,B21,'Balance 8 Columnas'!$N$10:$N$113) -> 0
B22: Otros activos no financieros no corrientes | E22: =SUMIF('Balance 8 Columnas'!$A$10:$A$113,B22,'Balance 8 Columnas'!$N$10:$N$113) -> 0 | G22: Ver
B23: Derechos por cobrar no corrientes | E23: =SUMIF('Balance 8 Columnas'!$A$10:$A$113,B23,'Balance 8 Columnas'!$N$10:$N$113) -> 0
B24: Cuentas por Cobrar a Entidades Relacionadas, No Corriente | E24: =SUMIF('Balance 8 Columnas'!$A$10:$A$113,B24,'Balance 8 Columnas'!$N$10:$N$113) -> 0
B25: Inversiones contabilizadas utilizando el método de la participación | E25: =SUMIF('Balance 8 Columnas'!$A$10:$A$113,B25,'Balance 8 Columnas'!$N$10:$N$113) -> 0
B26: Activos intangibles distintos de la plusvalía | E26: =SUMIF('Balance 8 Columnas'!$A$10:$A$113,B26,'Balance 8 Columnas'!$N$10:$N$113) -> 0
B27: Plusvalía | E27: =SUMIF('Balance 8 Columnas'!$A$10:$A$113,B27,'Balance 8 Columnas'!$N$10:$N$113) -> 0
B28: Inventario no corrientes | E28: =SUMIF('Balance 8 Columnas'!$A$10:$A$113,B28,'Balance 8 Columnas'!$N$10:$N$113) -> 0
B29: Propiedades, Plantas y Equipos | E29: =SUMIF('Balance 8 Columnas'!$A$10:$A$113,B29,'Balance 8 Columnas'!$N$10:$N$113) -> 0 | G29: Ver
B30: Activos biológicos, no corrientes | E30: =SUMIF('Balance 8 Columnas'!$A$10:$A$113,B30,'Balance 8 Columnas'!$N$10:$N$113) -> 0
B31: Propiedad de inversión | E31: =SUMIF('Balance 8 Columnas'!$A$10:$A$113,B31,'Balance 8 Columnas'!$N$10:$N$113) -> 0
B32: Activos por impuestos diferidos | E32: =SUMIF('Balance 8 Columnas'!$A$10:$A$113,B32,'Balance 8 Columnas'!$N$10:$N$113) -> 0
B33: Total de activos no corrientes | E33: =SUM(E21:E32) -> 0
B34: Total de activos | E34: =+E19+E33 -> 0
B36: SVS Estado de Situación Financiera Clasificado
E37: =E3 -> 44196
B38: Estado de Situación Financiera
B39: Patrimonio y pasivos
B40: Pasivos | E40: $
B41: Pasivos corrientes
...

Sheet Hoja1

Sheet Estado de Resultados
B1: =+Carátula!A7 -> Flexi Chile SpA
B2: Estado de Resultados
B3: Para el período comprendido entre el 01-01-2026 hasta el 31/01/2026
C6: =+'Balance Clasificado'!D6 -> 46053 | E6: =+C6 -> 46053
C7: $ | E7: US$
B8: Estado de resultados
B9: Ventas Netas | C9: =-SUMIF('Balance 8 Columnas'!A:O,'Estado de Resultados'!B9,'Balance 8 Columnas'!N:N) -> 246614292 | E9: =-SUMIF('Balance 8 Columnas'!A:O,'Estado de Resultados'!B9,'Balance 8 Columnas'!#REF!) -> #REF! | F9: =+E9/$E$9 -> #REF!
B10: Costo estándar de venta | C10: =-SUMIF('Balance 8 Columnas'!A:O,'Estado de Resultados'!B10,'Balance 8 Columnas'!J:J) -> -134839072 | E10: =-SUMIF('Balance 8 Columnas'!A:O,'Estado de Resultados'!B10,'Balance 8 Columnas'!#REF!) -> #REF! | F10: =+E10/$E$9 -> #REF!
B11: Ganancia bruta | C11: =+C9+C10 -> 111775220 | E11: =+E9+E10 -> #REF! | F11: =+E11/$E$9 -> #REF!
B12: Otros ingresos | C12: =-SUMIF('Balance 8 Columnas'!A:O,'Estado de Resultados'!B12,'Balance 8 Columnas'!N:N) -> 3751074 | E12: =-SUMIF('Balance 8 Columnas'!A:O,'Estado de Resultados'!B12,'Balance 8 Columnas'!#REF!) -> #REF!
B13: Resultado por siniestros | C13: =-SUMIF('Balance 8 Columnas'!A:O,'Estado de Resultados'!B13,'Balance 8 Columnas'!N:N) -> 0
B14: Publicidad | C14: =-SUMIF('Balance 8 Columnas'!A:O,'Estado de Resultados'!B14,'Balance 8 Columnas'!N:N) -> -2086868 | E14: =-SUMIF('Balance 8 Columnas'!A:O,'Estado de Resultados'!B14,'Balance 8 Columnas'!#REF!) -> #REF! | F14: =+E14/$E$9 -> #REF!
B15: Gastos de Administracion y Ventas | C15: =-SUMIF('Balance 8 Columnas'!A:O,'Estado de Resultados'!B15,'Balance 8 Columnas'!N:N) -> -109702350 | E15: =-SUMIF('Balance 8 Columnas'!A:O,'Estado de Resultados'!B15,'Balance 8 Columnas'!#REF!) -> #REF! | F15: =+E15/$E$9 -> #REF!
B16: Sueldos | C16: =-SUMIF('Balance 8 Columnas'!A:O,'Estado de Resultados'!B16,'Balance 8 Columnas'!N:N) -> -70008921 | E16: =-SUMIF('Balance 8 Columnas'!A:O,'Estado de Resultados'!B16,'Balance 8 Columnas'!#REF!) -> #REF! | F16: =+E16/$E$9 -> #REF!
B17: Depreciaciones | C17: =-SUMIF('Balance 8 Columnas'!A:O,'Estado de Resultados'!B17,'Balance 8 Columnas'!N:N) -> -8846337 | E17: =-SUMIF('Balance 8 Columnas'!A:O,'Estado de Resultados'!B17,'Balance 8 Columnas'!#REF!) -> #REF! | F17: =+E17/$E$9 -> #REF!
B18: Comisiones bancarias | C18: =-SUMIF('Balance 8 Columnas'!A:O,'Estado de Resultados'!B18,'Balance 8 Columnas'!N:N) -> -502259 | E18: =-SUMIF('Balance 8 Columnas'!A:O,'Estado de Resultados'!B18,'Balance 8 Columnas'!#REF!) -> #REF! | F18: =+E18/$E$9 -> #REF!
B19: Ingresos financieros | C19: =-SUMIF('Balance 8 Columnas'!A:O,'Estado de Resultados'!B19,'Balance 8 Columnas'!N:N) -> 0 | E19: =-SUMIF('Balance 8 Columnas'!A:O,'Estado de Resultados'!B19,'Balance 8 Columnas'!#REF!) -> #REF! | F19: =+E19/$E$9 -> #REF!
B20: Costo financiero | C20: =-SUMIF('Balance 8 Columnas'!A:O,'Estado de Resultados'!B20,'Balance 8 Columnas'!N:N) -> 23388827 | E20: =-SUMIF('Balance 8 Columnas'!A:O,'Estado de Resultados'!B20,'Balance 8 Columnas'!#REF!) -> #REF! | F20: =+E20/$E$9 -> #REF!
B21: Diferencia de cambio | F21: =+E21/$E$9 -> #REF!
B22: Ganancia (pérdida), antes de impuestos | C22: =SUM(C11:C21) -> -52231614 | E22: =SUM(E11:E21) -> #REF! | F22: =+E22/$E$9 -> #REF!
B23: Gasto por impuestos a las ganancias | C23: =SUMIF('Balance 8 Columnas'!A:O,'Estado de Resultados'!B23,'Balance 8 Columnas'!N:N) -> 0 | E23: 0
B25: Ganancia (pérdida) | C25: =SUM(C22:C23) -> -52231614 | E25: =SUM(E22:E23) -> #REF! | F25: =+E25/$E$9 -> #REF!
B26: Ganancia (pérdida), atribuible a
B27: Ganancia (pérdida), atribuible a los propietarios de la controladora | C27: =+C25 -> -52231614 | E27: =+E25 -> #REF! | F27: =+E27/$E$9 -> #REF!
B28: Ganancia (pérdida), atribuible a participaciones no controladoras | C28: 0 | E28: 0
B29: Ganancia (pérdida) | C29: =+C27+C28 -> -52231614 | E29: =+E27+E28 -> #REF! | F29: =+E29/$E$9 -> #REF!

Sheet Balance 8 Columnas
B2: =+Carátula!A7 -> Flexi Chile SpA
B3: Balance General IFRS
B4: =+Carátula!A9 -> Al 31 de enero de 2026
A7: Clasificacion | B7: Numero Cuenta | C7: Nombre Cuenta | D7: Valores Acumulados | F7: Saldos | H7: Inventario | J7: Resultados | N7: Saldos | O7: T/C Cierre
D8: Debitos | E8: Creditos | F8: Deudor | G8: Acreedor | H8: Activo | I8: Pasivo | J8: Perdidas | K8: Ganancias | O8: =+'Balance Clasificado'!C6 -> 865.1
A9: Caja y Bancos | B9: 1.1.01.101 | C9: EFECTIVO EN TRANSITO | D9: 216337650 | E9: 142232595 | F9: 74105055 | G9: 0 | H9: 74105055 | I9: 0 | J9: 0 | K9: 0 | M9: Monetaria | N9: =+D9-E9 -> 74105055 | O9: =N9/$O$8 -> 85660.681
A10: Caja y Bancos | B10: 1.1.01.203 | C10: FONDO FIJO PLAZA EGAÑA | D10: 99910 | E10: 58308 | F10: 41602 | G10: 0 | H10: 41602 | I10: 0 | J10: 0 | K10: 0 | M10: Monetaria | N10: =+D10-E10 -> 41602 | O10: =N10/$O$8 -> 48.089238
A11: Caja y Bancos | B11: 1.1.01.204 | C11: FONDO FIJO VESPUCIO | D11: 85990 | E11: 0 | F11: 85990 | G11: 0 | H11: 85990 | I11: 0 | J11: 0 | K11: 0 | M11: Monetaria | N11: =+D11-E11 -> 85990 | O11: =N11/$O$8 -> 99.398913
A12: Caja y Bancos | B12: 1.1.01.205 | C12: FONDO FIJO TREBOL | D12: 154990 | E12: 152308 | F12: 2682 | G12: 0 | H12: 2682 | I12: 0 | J12: 0 | K12: 0 | M12: Monetaria | N12: =+D12-E12 -> 2682 | O12: =N12/$O$8 -> 3.1002196
A13: Caja y Bancos | B13: 1.1.01.206 | C13: FONDO FIJO COSTANERA CENTER | D13: 100000 | E13: 108130 | F13: 0 | G13: 8130 | H13: 0 | I13: 8130 | J13: 0 | K13: 0 | M13: Monetaria | N13: =+D13-E13 -> -8130 | O13: =N13/$O$8 -> -9.3977575
A14: Caja y Bancos | B14: 1.1.01.207 | C14: FONDO FIJO FLORIDA CENTER | D14: 337628 | E14: 254628 | F14: 83000 | G14: 0 | H14: 83000 | I14: 0 | J14: 0 | K14: 0 | M14: Monetaria | N14: =+D14-E14 -> 83000 | O14: =N14/$O$8 -> 95.942666
A15: Caja y Bancos | B15: 1.1.01.208 | C15: FONDO FIJO SANTIAGO CENTRO | D15: 131290 | E15: 91720 | F15: 39570 | G15: 0 | H15: 39570 | I15: 0 | J15: 0 | K15: 0 | M15: Monetaria | N15: =+D15-E15 -> 39570 | O15: =N15/$O$8 -> 45.740377
A16: Caja y Bancos | B16: 1.1.01.209 | C16: FONDO FIJO CONCEPCION CENTRO | D16: 103980 | E16: 46490 | F16: 57490 | G16: 0 | H16: 57490 | I16: 0 | J16: 0 | K16: 0 | M16: Monetaria | N16: =+D16-E16 -> 57490 | O16: =N16/$O$8 -> 66.454745
A17: Caja y Bancos | B17: 1.1.01.210 | C17: FONDO FIJO TALCA | D17: 103994 | E17: 90688 | F17: 13306 | G17: 0 | H17: 13306 | I17: 0 | J17: 0 | K17: 0 | M17: Monetaria | N17: =+D17-E17 -> 13306 | O17: =N17/$O$8 -> 15.380881
A18: Caja y Bancos | B18: 1.1.01.211 | C18: FONSO FIJO PLAZA NORTE | D18: 128075 | E18: 80955 | F18: 47120 | G18: 0 | H18: 47120 | I18: 0 | J18: 0 | K18: 0 | M18: Monetaria | N18: =+D18-E18 -> 47120 | O18: =N18/$O$8 -> 54.467692
A19: Caja y Bancos | B19: 1.1.01.212 | C19: FONDO FIJO PLAZA OESTE | D19: 135671 | E19: 75671 | F19: 60000 | G19: 0 | H19: 60000 | I19: 0 | J19: 0 | K19: 0 | M19: Monetaria | N19: =+D19-E19 -> 60000 | O19: =N19/$O$8 -> 69.356144
A20: Caja y Bancos | B20: 1.1.01.301 | C20: BANCOS CTA CTE $ | D20: 822199777 | E20: 381616850 | F20: 440582927 | G20: 0 | H20: 440582927 | I20: 0 | J20: 0 | K20: 0 | M20: Monetaria | N20: =+D20-E20 -> 440582927 | O20: =N20/$O$8 -> 509285.55
... A116: Costo financiero | B116: 3.2.13.109 | C116: AJUSTE REDONDEO AUTO | D116: 34 | E116: 0 | F116: 34 | G116: 0 | H116: 0 | I116: 0 | J116: 34 | K116: 0 | M116: NO Monetario | N116: =+D116-E116 -> 34 | O116: =N116/$O$8 -> 0.039301815
B117: Total Acumulado | D117: =SUM(D9:D116) -> 13821361994 | E117: =SUM(E9:E116) -> 13821361994 | F117: =SUM(F9:F116) -> 7806222781 | G117: =SUM(G9:G116) -> 7806222781 | H117: =SUM(H9:H116) -> 7478455448 | I117: =SUM(I9:I116) -> 7530687062 | J117: =SUM(J9:J116) -> 327767333 | K117: =SUM(K9:K116) -> 275535719 | N117: =+D117-E117 -> 0 | O117: =SUM(O9:O116) -> 2.1525032e-10
B118: Resultado del ejercicio | H118: 0 | I118: =+H117-I117 -> -52231614 | J118: =+K117-J117 -> -52231614 | K118: 0 | N118: =SUM(N62:N116) -> 52231614 | O118: =SUM(O62:O116) -> 60376.389
B119: Sumas Iguales | D119: =D117 -> 13821361994 | E119: =E117 -> 13821361994 | F119: =F117 -> 7806222781 | G119: =G117 -> 7806222781 | H119: =SUM(H117:H118) -> 7478455448 | I119: =SUM(I117:I118) -> 7478455448 | J119: =SUM(J117:J118) -> 275535719 | K119: =SUM(K117:K118) -> 275535719
E120: =D119-E119 -> 0
E122: =E120/2 -> 0
E123: =E120*2 -> 0

Sheet EERR Mensual US$
A2: Flexi Chile SpA
A3: Estado de Resultado mensual
A4: =+'Estado de Resultados'!B3 -> Para el período comprendido entre el 01-01-2026 hasta el 31/01/2026
A5: Moneda US$
A8: Numero Cuenta | B8: Nombre Cuenta | C8: 44957 | D8: 44985 | E8: 45016 | F8: 45046 | G8: 45077 | H8: 45107 | I8: 45138 | J8: 45169 | K8: Resultado Periodo
J9: 855.86
C10: USD | D10: USD | E10: USD | F10: USD | G10: USD | H10: USD | I10: USD | J10: USD | K10: USD
A11: 3.1.01.101 | B11: VENTAS CON BOLETA | C11: 0 | D11: 1879.2 | E11: 0 | F11: 0 | G11: 0 | H11: 0 | I11: 283320.34 | J11: ='EERR Mensual $'!#REF!/'EERR Mensual US$'!$J$9 -> #REF! | K11: =SUM(C11:J11) -> #REF!
A12: 3.1.01.102 | B12: VENTAS CON FACTURA | C12: 0 | D12: 0 | E12: 0 | F12: 0 | G12: 0 | H12: 0 | I12: 154.26 | J12: ='EERR Mensual $'!#REF!/'EERR Mensual US$'!$J$9 -> #REF! | K12: =SUM(C12:J12) -> #REF!
A13: 3.1.01.103 | B13: VENTAS CON BOLETA (RPA) | C13: 236876.85 | D13: 181614.1 | E13: 197725.78 | F13: 278768.47 | G13: 325586.65 | H13: 267228.92 | I13: 0 | J13: ='EERR Mensual $'!#REF!/'EERR Mensual US$'!$J$9 -> #REF! | K13: =SUM(C13:J13) -> #REF!
A14: 3.1.01.104 | B14: VENTAS CON FACTURA (RPA) | C14: 37403.03 | D14: 128785.99 | E14: 95545.93 | F14: 70291.04 | G14: 32098.07 | H14: 1370.34 | I14: 0 | J14: ='EERR Mensual $'!#REF!/'EERR Mensual US$'!$J$9 -> #REF! | K14: =SUM(C14:J14) -> #REF!
A15: 3.1.02.101 | B15: COSTO DE VENTAS | C15: -172048.4 | D15: -193242.82 | E15: -174833.04 | F15: -179090.11 | G15: -175480.27 | H15: -132641.24 | I15: -147645.76 | J15: ='EERR Mensual $'!#REF!/'EERR Mensual US$'!$J$9 -> #REF! | K15: =SUM(C15:J15) -> #REF!
A16: 3.1.02.102 | B16: COSTOS OPERATIVOS - FLETES INTERNOS | C16: -5526.8 | D16: -3269.95 | E16: -2476.83 | F16: -4054.64 | G16: -4460.46 | H16: -3747.18 | I16: -2806.37 | J16: ='EERR Mensual $'!#REF!/'EERR Mensual US$'!$J$9 -> #REF! | K16: =SUM(C16:J16) -> #REF!
A17: 3.1.02.103 | B17: CANAL DIGITAL | C17: 0 | D17: -1815.63 | E17: 0 | F17: 0 | G17: -8.84 | H17: 0 | I17: 0 | J17: ='EERR Mensual $'!#REF!/'EERR Mensual US$'!$J$9 -> #REF! | K17: =SUM(C17:J17) -> #REF!
A18: 3.1.02.104 | B18: COMISIÓN - CANAL DIGITAL | C18: -7346.76 | D18: -6770.43 | E18: -6816.94 | F18: -5793.52 | G18: -5837.44 | H18: -5822.39 | I18: -2880.4 | J18: ='EERR Mensual $'!#REF!/'EERR Mensual US$'!$J$9 -> #REF! | K18: =SUM(C18:J18) -> #REF!
A19: 3.1.02.105 | B19: FLETES - CANAL DIGITAL | C19: -1346.95 | D19: -1543.2 | E19: -1141.34 | F19: -1804.89 | G19: -1496.94 | H19: -1560.26 | I19: -1890.16 | J19: ='EERR Mensual $'!#REF!/'EERR Mensual US$'!$J$9 -> #REF! | K19: =SUM(C19:J19) -> #REF!
A20: 3.1.02.108 | B20: SERVICIOS - CANAL DIGITAL | C20: -3921.59 | D20: -6599.82 | E20: -7103.61 | F20: -10158.6 | G20: -7259.92 | H20: -8043.44 | I20: -10487.54 | J20: ='EERR Mensual $'!#REF!/'EERR Mensual US$'!$J$9 -> #REF! | K20: =SUM(C20:J20) -> #REF!
A21: 3.1.02.113 | B21: COSTOS OPERATIVOS - INTERNACIO | C21: 15.11 | D21: -48.72 | E21: 203.13 | F21: 19.37 | G21: -23.38 | H21: 0 | I21: 0 | J21: ='EERR Mensual $'!#REF!/'EERR Mensual US$'!$J$9 -> #REF! | K21: =SUM(C21:J21) -> #REF!
A22: 3.1.05.101 | B22: REMUNERACIONES | C22: -28991.84 | D22: -51892.52 | E22: -29766.33 | F22: -28208.49 | G22: -28491.3 | H22: -29738.91 | I22: -28728.39 | J22: ='EERR Mensual $'!#REF!/'EERR Mensual US$'!$J$9 -> #REF! | K22: =SUM(C22:J22) -> #REF!
... A39: 3.1.05.129 | B39: RE SEMANA CORRIDA | C39: -679.12 | D39: -363.6 | E39: -334.49 | F39: -942.79 | G39: -2139.63 | H39: -984 | I39: -764.59 | J39: ='EERR Mensual $'!#REF!/'EERR Mensual US$'!$J$9 -> #REF! | K39: =SUM(C39:J39) -> #REF!
A40: 3.1.05.130 | B40: RE HORAS EXTRAS DOMINICAL | J40: ='EERR Mensual $'!#REF!/'EERR Mensual US$'!$J$9 -> #REF! | K40: =SUM(C40:J40) -> #REF!
A41: 3.1.05.132 | B41: RE SEGURO DE CESANTIA | C41: -557.26 | D41: -496.18 | E41: -546.09 | F41: -780.92 | G41: -825.81 | H41: -822.45 | I41: -730.57 | J41: ='EERR Mensual $'!#REF!/'EERR Mensual US$'!$J$9 -> #REF! | K41: =SUM(C41:J41) -> #REF!
A42: 3.1.05.133 | B42: RE MUTUAL DE SEGURIDAD | C42: -189.07 | D42: -166.98 | E42: -182.67 | F42: -249.76 | G42: -275.81 | H42: -285.51 | I42: -265.02 | J42: ='EERR Mensual $'!#REF!/'EERR Mensual US$'!$J$9 -> #REF! | K42: =SUM(C42:J42) -> #REF!
A43: 3.1.05.134 | B43: RE SEGURO INVALIDEZ (AFP) | C43: -332.03 | D43: -300.75 | E43: -324.07 | F43: -462.84 | G43: -489.93 | H43: -495.57 | I43: -535.75 | J43: ='EERR Mensual $'!#REF!/'EERR Mensual US$'!$J$9 -> #REF! | K43: =SUM(C43:J43) -> #REF!
A44: 3.1.05.406 | B44: GASTOS DE TELEFONIA MOVIL | C44: 0 | D44: 0 | E44: -50.57 | F44: -132.07 | G44: -347.37 | H44: 197.52 | I44: -326 | J44: ='EERR Mensual $'!#REF!/'EERR Mensual US$'!$J$9 -> #REF! | K44: =SUM(C44:J44) -> #REF!
A45: 3.1.05.818 | B45: LICENCIAS SOTWARE RENTAS | C45: -1029.54 | D45: -659.43 | E45: -1208.25 | F45: -1557.22 | G45: -1705.7 | H45: -1422.98 | I45: -2060.54 | J45: ='EERR Mensual $'!#REF!/'EERR Mensual US$'!$J$9 -> #REF! | K45: =SUM(C45:J45) -> #REF!
A46: 3.1.05.834 | B46: GASTO VENTA CANAL MAYORISTA | C46: 0 | D46: 0 | E46: 0 | F46: 0 | G46: -1029.65 | H46: -4041.18 | I46: 0 | J46: ='EERR Mensual $'!#REF!/'EERR Mensual US$'!$J$9 -> #REF! | K46: =SUM(C46:J46) -> #REF!
A47: 3.1.05.835 | B47: GASTOS CEDIS | C47: 0 | D47: -950.61 | E47: -618.51 | F47: 0 | G47: -960.98 | H47: 0 | I47: 0 | J47: ='EERR Mensual $'!#REF!/'EERR Mensual US$'!$J$9 -> #REF! | K47: =SUM(C47:J47) -> #REF!
A48: 3.1.06.108 | B48: ASIGNACION COLACION | C48: -1578.29 | D48: -1545.87 | E48: -1557.05 | F48: -1490.31 | G48: -1475.63 | H48: -1592.57 | I48: -1477.35 | J48: ='EERR Mensual $'!#REF!/'EERR Mensual US$'!$J$9 -> #REF! | K48: =SUM(C48:J48) -> #REF!
A49: 3.1.06.109 | B49: ASIGNACION MOVILIZACION | C49: -1578.29 | D49: -1545.87 | E49: -1557.05 | F49: -1490.31 | G49: -1475.63 | H49: -1592.57 | I49: -1477.35 | J49: ='EERR Mensual $'!#REF!/'EERR Mensual US$'!$J$9 -> #REF! | K49: =SUM(C49:J49) -> #REF!
A50: 3.1.06.112 | B50: GASTOS DE CAPACITACION | C50: 0 | D50: 0 | E50: 0 | F50: 0 | G50: 0 | H50: 0 | I50: -5865.62 | J50: ='EERR Mensual $'!#REF!/'EERR Mensual US$'!$J$9 -> #REF! | K50: =SUM(C50:J50) -> #REF!
A51: 3.1.06.116 | B51: UNIFORMES | C51: -530.76 | D51: -291.98 | E51: -1719.09 | F51: -2660.05 | G51: -2170.86 | H51: -185.13 | I51: -2440.08 | J51: ='EERR Mensual $'!#REF!/'EERR Mensual US$'!$J$9 -> #REF! | K51: =SUM(C51:J51) -> #REF!
A52: 3.1.06.130 | B52: RE ASIGNACION COLACION | C52: -744.89 | D52: -771.37 | E52: -841.12 | F52: -979.02 | G52: -1097.01 | H52: -1121.49 | I52: -1109.47 | J52: ='EERR Mensual $'!#REF!/'EERR Mensual US$'!$J$9 -> #REF! | K52: =SUM(C52:J52) -> #REF!
... A90: 3.2.13.109 | B90: AJUSTE REDONDEO AUTO | C90: 0 | D90: -0.01 | E90: 0 | F90: 0.03 | G90: 0.03 | H90: -0.21 | I90: -0.34 | J90: ='EERR Mensual $'!#REF!/'EERR Mensual US$'!$J$9 -> #REF! | K90: =SUM(C90:J90) -> #REF!
A91: Resultado del ejercicio mensual | C91: =SUM(C11:C90) -> -86218.13 | D91: =SUM(D11:D90) -> -71469.99 | E91: =SUM(E11:E90) -> -85958.11 | F91: =SUM(F11:F90) -> -15133.3 | G91: =SUM(G11:G90) -> -19700.89 | H91: =SUM(H11:H90) -> -77864.35 | I91: =SUM(I11:I90) -> -68349.73 | J91: =SUM(J11:J90) -> #REF! | K91: =SUM(K11:K90) -> #REF!
K92: =K91+'Balance 8 Columnas'!O118 -> #REF!

Sheet EERR Mensual $
Q1: Sum. Visual'!A1
A2: Flexi Chile SpA
A3: Estado de Resultado mensual
A4: =+'Estado de Resultados'!B3 -> Para el período comprendido entre el 01-01-2026 hasta el 31/01/2026
A5: Moneda $
A8: Numero Cuenta | B8: Nombre Cuenta | C8: 46053 | D8: 46081 | E8: 46112 | F8: 46142 | G8: 46173 | H8: 46203 | I8: 46234 | J8: 46265 | K8: 46295 | L8: 46326 | M8: 46356 | N8: 46387 | O8: Resultado Periodo
C10: $ | D10: $ | E10: $ | F10: $ | G10: $ | H10: $ | I10: $ | J10: $ | K10: $ | L10: $ | M10: $ | N10: $ | O10: $
A11: 3.1.01.103 | B11: VENTAS CON BOLETA (RPA) | C11: 246614292 | O11: =SUM(C11:N11) -> 246614292
A12: 3.1.01.300 | B12: OTROS INGRESOS | C12: 3751074 | O12: =SUM(C12:N12) -> 3751074
A13: 3.1.02.101 | B13: COSTO DE VENTAS | C13: -134839072 | O13: =SUM(C13:N13) -> -134839072 | P13: =C13-D13 -> -134839072
A14: 3.1.02.102 | B14: COSTOS OPERATIVOS - FLETES INTERNOS | C14: -1840455 | O14: =SUM(C14:N14) -> -1840455 | P14: =C14-D14 -> -1840455 | T14: HIDALGO DIC 2.521.008 ENE 2.819.732 FEB 3.040.000
A15: 3.1.02.104 | B15: COMISIÓN - CANAL DIGITAL | C15: -2699824 | O15: =SUM(C15:N15) -> -2699824 | P15: =C15-D15 -> -2699824
A16: 3.1.02.105 | B16: FLETES - CANAL DIGITAL | C16: -800047 | O16: =SUM(C16:N16) -> -800047 | P16: =C16-D16 -> -800047
A17: 3.1.02.108 | B17: SERVICIOS - CANAL DIGITAL | C17: -1976022 | O17: =SUM(C17:N17) -> -1976022 | P17: =C17-D17 -> -1976022
A18: 3.1.02.109 | B18: DESCUENTOS GIFTCARD | C18: -44990 | O18: =SUM(C18:N18) -> -44990 | P18: =C18-D18 -> -44990
A19: 3.1.02.110 | B19: DESCUENTOS CLUB FLEXI | C19: -46507 | O19: =SUM(C19:N19) -> -46507 | P19: =C19-D19 -> -46507
A20: 3.1.05.101 | B20: REMUNERACIONES | C20: -45117151 | O20: =SUM(C20:N20) -> -45117151 | P20: =C21-D20 -> -1730490
A21: 3.1.05.102 | B21: BONOS | C21: -1730490 | O21: =SUM(C21:N21) -> -1730490 | P21: =C22-D21 -> -1655083
A22: 3.1.05.103 | B22: SEGURO DE CESANTIA | C22: -1655083 | O22: =SUM(C22:N22) -> -1655083 | P22: =C23-D22 -> -10584152
A23: 3.1.05.104 | B23: GRATIFICACION | C23: -10584152 | O23: =SUM(C23:N23) -> -10584152 | P23: =C24-D23 -> -4000
A24: 3.1.05.107 | B24: FINIQUITOS | C24: -4000 | O24: =SUM(C24:N24) -> -4000 | P24: =C25-D24 -> -600154
A25: 3.1.05.110 | B25: MUTUAL DE SEGURIDAD | C25: -600154 | O25: =SUM(C25:N25) -> -600154 | P25: =C26-D25 -> -1012481
A26: 3.1.05.111 | B26: SEGURO INVALIDEZ (AFP) | C26: -1012481 | O26: =SUM(C26:N26) -> -1012481 | P26: =C29-D26 -> 0
A27: 3.1.05.112 | B27: CAPITALIZACION INDIVIDUAL AFP | C27: -64495 | O27: =SUM(C27:N27) -> -64495
A28: 3.1.05.113 | B28: EXPECTATIVA DE VIDA | C28: -591718 | O28: =SUM(C28:N28) -> -591718
A29: 3.1.05.114 | B29: HORAS EXTRAS | C29: 0 | O29: =SUM(C29:N29) -> 0 | P29: =C30-D29 -> -756324
A30: 3.1.05.117 | B30: DOMINGOS Y FESTIVOS | C30: -756324 | O30: =SUM(C30:N30) -> -756324 | P30: =C31-D30 -> -1447552
A31: 3.1.05.121 | B31: SEMANA CORRIDA | C31: -1447552 | O31: =SUM(C31:N31) -> -1447552 | P31: =C32-D31 -> -6445321
A32: 3.1.05.122 | B32: COMISION POR VENTA | C32: -6445321 | O32: =SUM(C32:N32) -> -6445321 | P32: =C33-D32 -> -2326500
A33: 3.1.06.108 | B33: ASIGNACION COLACION | C33: -2326500 | O33: =SUM(C33:N33) -> -2326500 | P33: =C34-D33 -> -2326500
A34: 3.1.06.109 | B34: ASIGNACION MOVILIZACION | C34: -2326500 | O34: =SUM(C34:N34) -> -2326500 | P34: =C35-D34 -> 1138389
A35: 3.1.06.116 | B35: UNIFORMES | C35: 1138389 | O35: =SUM(C35:N35) -> 1138389 | P35: =C36-D35 -> -505000
A36: 3.1.06.201 | B36: HONORARIOS PROFESIONALES | C36: -505000 | O36: =SUM(C36:N36) -> -505000 | P36: =C37-D36 -> -3101478
A37: 3.1.06.206 | B37: ASESORIA CONTABLE | C37: -3101478 | O37: =SUM(C37:N37) -> -3101478 | P37: =C38-D37 -> 0
A38: 3.1.06.209 | B38: HONORARIOS POR ASESORIAS INFORMATICAS | C38: 0 | O38: =SUM(C38:N38) -> 0 | P38: =C39-D38 -> -75994402 | R38: enero y feb
A39: 3.1.06.301 | B39: ARRIENDOS | C39: -75994402 | O39: =SUM(C39:N39) -> -75994402 | P39: =C40-D39 -> -3126087
A40: 3.1.06.302 | B40: ARRIENDO DE BODEGAS | C40: -3126087 | O40: =SUM(C40:N40) -> -3126087 | P40: =C41-D40 -> -631049
A41: 3.1.06.305 | B41: GASTOS DIVERSOS | C41: -631049 | O41: =SUM(C41:N41) -> -631049 | P41: =C42-D41 -> 0
A42: 3.1.06.306 | B42: SEGURIDAD INDUSTRIAL | C42: 0 | O42: =SUM(C42:N42) -> 0
A43: 3.1.06.401 | B43: SERVICIOS DE TELECOMUNICACION | C43: -177715 | O43: =SUM(C43:N43) -> -177715 | P43: =C44-D43 -> -131229
...

Sheet ER Centro de Costo
D1: 300 | E1: 130 | F1: 140 | G1: 150 | H1: 100 | I1: 2 | J1: 170 | K1: 180 | L1: 185 | M1: 500 | N1: 190 | O1: 195 | P1: 200 | Q1: 210
B2: Estado de Resultado por Centro de Costo
B3: =+'Estado de Resultados'!B3 -> Para el período comprendido entre el 01-01-2026 hasta el 31/01/2026
D5: =+D8/$R$8 -> 0 | E5: =+E8/$R$8 -> 0.13366972 | F5: =+F8/$R$8 -> 0 | G5: =+G8/$R$8 -> 0.093715277 | H5: =+H8/$R$8 -> 0.11146838 | J5: =+J8/$R$8 -> 0.19243443 | K5: =+K8/$R$8 -> 0.085159979 | L5: =+L8/$R$8 -> 0 | M5: =+M8/$R$8 -> 0 | N5: =+N8/$R$8 -> 0.14553252 | O5: =+O8/$R$8 -> 0.068649802 | P5: =+P8/$R$8 -> 0.068109589 | Q5: =+Q8/$R$8 -> 0.10126031
B6: N° CUENTA | C6: NOMBRE CUENTA | D6: CEDIS CHILE | E6: EGAÑA | F6: VESPUCIO | G6: TREBOL | H6: ONLINE | I6: ADMINISTRACION | J6: COSTANERA CENTER | K6: FLORIDA CENTER | L6: CONCEPCION CENTRO | M6: DEPARTAMENTAL | N6: SANTIAGO CENTRO | O6: MAULE TALCA | P6: PLAZA NORTE | Q6: PLAZA OESTE | R6: TOTAL
B8: 3.1.01.101 | C8: VENTAS CON BOLETA | D8: =SUM(D9:D10) -> 0 | E8: =SUM(E9:E10) -> 32964888 | F8: =SUM(F9:F10) -> 0 | G8: =SUM(G9:G10) -> 23111545 | H8: =SUM(H9:H10) -> 27489717 | I8: =SUM(I9:I10) -> 0 | J8: =SUM(J9:J10) -> 47457118 | K8: =SUM(K9:K10) -> 21001684 | ... Q8: =SUM(Q9:Q10) -> 24972259 | R8: =SUM(D8:Q8) -> 2.4661448e+08
C9: ACCESORIOS | E9: 438302.52 | G9: 622984.03 | H9: 59075.63 | J9: 791978.15 | K9: 394328.57 | N9: 439117.65 | O9: 208371.43 | P9: 403824.37 | Q9: 507118.49 | R9: =SUM(E9:Q9) -> 3865100.8
C10: CALZADO | E10: 32526586 | G10: 22488561 | H10: =35615436-8184795 -> 27430641 | J10: 46665139 | K10: 20607355 | N10: 35451308 | O10: 16721664 | P10: 16392987 | Q10: 24465140 | R10: =SUM(E10:Q10) -> 2.4274938e+08
B11: 3.1.02.101 | C11: COSTO DE VENTAS | E11: -17793331 | F11: 0 | G11: -11944357 | H11: -17445854 | I11: 0 | J11: -25211212 | K11: -11190542 | L11: 0 | N11: -19343670 | O11: -9135162 | P11: -9119820 | Q11: -13655123 | R11: =SUM(D11:Q11) -> -134839071
B12: Resultado por Centro de Beneficio | D12: =+D8+D11 -> 0 | E12: =+E8+E11 -> 15171557 | F12: =+F8+F11 -> 0 | G12: =+G8+G11 -> 11167188 | H12: =+H8+H11 -> 10043863 | I12: =+I8+I11 -> 0 | J12: =+J8+J11 -> 22245906 | K12: =+K8+K11 -> 9811142 | ... R12: =+R8+R11 -> 1.1177541e+08 | S12: OK
B14: N° CUENTA | C14: NOMBRE CUENTA | D14: CEDIS CHILE | E14: EGAÑA | F14: VESPUCIO | G14: TREBOL | H14: ONLINE | I14: ADMINISTRACION | J14: COSTANERA CENTER | K14: FLORIDA CENTER | L14: CONCEPCION CENTRO | M14: DEPARTAMENTAL | N14: SANTIAGO CENTRO | O14: MAULE TALCA | P14: PLAZA NORTE | Q14: PLAZA OESTE | R14: TOTAL
B16: 3.1.01.300 | C16: OTROS INGRESOS | D16: 0 | E16: 0 | F16: 0 | G16: 0 | H16: 3751074 | I16: 0 | J16: 0 | K16: 0 | L16: 0 | M16: 0 | N16: 0 | O16: 0 | P16: 0 | Q16: 0 | R16: =SUM(D16:Q16) -> 3751074
B17: 3.1.02.102 | C17: COSTOS OPERATIVOS - FLETES INTERNOS | D17: -2164695 | E17: 21780 | F17: 0 | G17: 21780 | H17: 150000 | I17: 0 | J17: 21780 | K17: 21780 | L17: 0 | M17: 0 | N17: 21780 | O17: 21780 | P17: 21780 | Q17: 21780 | R17: =SUM(D17:Q17) -> -1840455
B18: 3.1.02.104 | C18: COMISIÓN - CANAL DIGITAL | D18: 0 | E18: 0 | F18: 0 | G18: 0 | H18: -3004368 | I18: 0 | J18: 0 | K18: 0 | L18: 0 | M18: 304544 | N18: 0 | O18: 0 | P18: 0 | Q18: 0 | R18: =SUM(D18:Q18) -> -2699824
B19: 3.1.02.105 | C19: FLETES - CANAL DIGITAL | D19: 0 | E19: 0 | F19: 0 | G19: 0 | H19: 2066127 | I19: 0 | J19: 0 | K19: 0 | L19: 0 | M19: -2866174 | N19: 0 | O19: 0 | P19: 0 | Q19: 0 | R19: =SUM(D19:Q19) -> -800047
B20: 3.1.02.108 | C20: SERVICIOS - CANAL DIGITAL | D20: 0 | E20: 0 | F20: 0 | G20: 0 | H20: -129245 | I20: 0 | J20: 0 | K20: 0 | L20: 0 | M20: -1846777 | N20: 0 | O20: 0 | P20: 0 | Q20: 0 | R20: =SUM(D20:Q20) -> -1976022
B21: 3.1.02.109 | C21: DESCUENTOS GIFTCARD | D21: 0 | E21: 0 | F21: 0 | G21: 0 | H21: 0 | I21: 0 | J21: 0 | K21: 0 | L21: 0 | M21: 0 | N21: -44990 | O21: 0 | P21: 0 | Q21: 0 | R21: =SUM(D21:Q21) -> -44990
B22: 3.1.02.110 | C22: DESCUENTOS CLUB FLEXI | D22: 0 | E22: 0 | F22: 0 | G22: 0 | H22: 0 | I22: 0 | J22: -14372 | K22: -27334 | L22: 0 | M22: 0 | N22: -4801 | O22: 0 | P22: 0 | Q22: 0 | R22: =SUM(D22:Q22) -> -46507
B23: 3.1.05.101 | C23: REMUNERACIONES | D23: 0 | E23: -5471370 | F23: 0 | G23: -5105142 | H23: -3360231 | I23: -589781 | J23: -6163578 | K23: -4432782 | L23: 0 | M23: -1429576 | N23: -5819291 | O23: -3991543 | P23: -4129167 | Q23: -4624690 | R23: =SUM(D23:Q23) -> -45117151
B24: 3.1.05.102 | C24: BONOS | D24: 0 | E24: -273846 | F24: 0 | G24: -183785 | H24: -127312 | I24: 0 | J24: -295071 | K24: -167527 | L24: 0 | M24: 0 | N24: -668574 | O24: -17293 | P24: 805918 | Q24: -803000 | R24: =SUM(D24:Q24) -> -1730490
B25: 3.1.05.103 | C25: SEGURO DE CESANTIA | D25: 0 | E25: -190943 | F25: 0 | G25: -203449 | H25: -92175 | I25: -44143 | J25: -226386 | K25: -163670 | L25: 0 | M25: -34952 | N25: -219642 | O25: -149355 | P25: -149071 | Q25: -181297 | R25: =SUM(D25:Q25) -> -1655083
B26: 3.1.05.104 | C26: GRATIFICACION | D26: 0 | E26: -1260847 | F26: 0 | G26: -1345486 | H26: -460102 | I26: -215308 | J26: -1419780 | K26: -1136975 | L26: 0 | M26: -147415 | N26: -1338001 | O26: -1000642 | P26: -1039174 | Q26: -1220422 | R26: =SUM(D26:Q26) -> -10584152
B27: 3.1.05.107 | C27: FINIQUITOS | D27: 0 | E27: 0 | F27: 0 | G27: 0 | H27: 0 | I27: -4000 | J27: 0 | K27: 0 | L27: 0 | M27: 0 | N27: 0 | O27: 0 | P27: 0 | Q27: 0 | R27: =SUM(D27:Q27) -> -4000
... B69: 3.2.08.105 | C69: INTERESES POR PRESTAMO | D69: 0 | E69: 0 | F69: 0 | G69: 0 | H69: 0 | I69: 0 | J69: -8446 | K69: 0 | L69: 0 | M69: 0 | N69: 0 | O69: 0 | P69: -4101 | Q69: -6758 | R69: =SUM(D69:Q69) -> -19305
B70: 3.2.08.114 | C70: INTERESES DEVENGADOS FONDOS MU | D70: 0 | E70: 0 | F70: 0 | G70: 0 | H70: 0 | I70: 0 | J70: 0 | K70: 0 | L70: 0 | M70: 0 | N70: 0 | O70: 0 | R70: =SUM(D70:Q70) -> 0
B71: 3.2.08.116 | C71: INTERES GANADO POR DEPOSITO A PLAZO PESOS | D71: 0 | E71: 0 | F71: 0 | G71: 0 | H71: 0 | I71: 5791 | J71: 0 | K71: 0 | L71: 0 | M71: 0 | N71: 0 | O71: 0 | P71: 0 | Q71: 0 | R71: =SUM(D71:Q71) -> 5791
B72: 3.2.08.117 | C72: INTERES GANADO FONDOS MUTUOS | D72: 0 | E72: 0 | F72: 0 | G72: 0 | H72: 0 | I72: 0 | J72: 0 | K72: 0 | L72: 0 | M72: 0 | N72: 0 | O72: 0 | R72: =SUM(D72:Q72) -> 0
B73: 3.2.11.158 | C73: DIFERENCIA DE CAMBIO | H73: 0 | I73: 24026172 | M73: 0 | R73: =SUM(D73:Q73) -> 24026172
B74: 3.2.13.101 | C74: CORRECCION MONETARIA ACTIVOS | D74: 0 | E74: 0 | F74: 0 | G74: 0 | H74: 0 | I74: -623797 | J74: 0 | K74: 0 | L74: 0 | M74: 0 | N74: 0 | O74: 0 | P74: 0 | Q74: 0 | R74: =SUM(D74:Q74) -> -623797
B75: 3.2.13.109 | C75: AJUSTE REDONDEO AUTO | D75: 0 | E75: 0 | F75: 0 | G75: 0 | H75: 0 | I75: -34 | J75: 0 | K75: 0 | L75: 0 | M75: 0 | N75: 0 | O75: 0 | P75: 0 | Q75: 0 | R75: =SUM(D75:Q75) -> -34
B76: Resultado por Centro de Costo | D76: =SUM(D16:D75) -> -8834134 | E76: =SUM(E16:E75) -> -18557806 | F76: =SUM(F16:F75) -> -11619 | G76: =SUM(G16:G75) -> -17972450 | H76: =SUM(H16:H75) -> -5369377 | I76: =SUM(I16:I75) -> 11379261 | J76: =SUM(J16:J75) -> -32106886 | K76: =SUM(K16:K75) -> -19456181 | ... Q76: =SUM(Q16:Q75) -> -18312604 | R76: =SUM(D76:Q76) -> -164006834
B78: Resultado por Centro de Costo | D78: =D12+D76 -> -8834134 | E78: =E12+E76 -> -3386248.8 | F78: =F12+F76 -> -11619 | G78: =G12+G76 -> -6805262.5 | H78: =H12+H76 -> 4674485.6 | I78: =I12+I76 -> 11379261 | J78: =J12+J76 -> -9860980.4 | K78: =K12+K76 -> -9645039 | ... R78: =R12+R76 -> -52231423
R80: =+R78-'Balance 8 Columnas'!J118 -> 191.17647
B83: Distribución Remuneraciones | C83: 36260981 | D83: 0 | E83: 3466729 | F83: 3249093.5 | G83: 3569959.2 | H83: 6640432.4 | I83: 0 | J83: 4695061 | K83: 1699384.3 | L83: 1699384.3 | M83: 9529728.4 | R83: =+$C$83*R5 -> 0
A84: 3105101 | B84: REMUNERACIONES | C84: 33549150 | E84: 3207464.6 | F84: 3006105.2 | G84: 3302974.6 | H84: 6143817.9 | I84: 0 | J84: 4343934 | K84: 1572293.4 | L84: 1572293.4 | M84: 8817033.6
A85: 3105102 | B85: BONOS | C85: -1359336 | E85: -129959.24 | F85: -121800.61 | G85: -133829.09 | H85: -248933.66 | I85: 0 | J85: -176006.42 | K85: -63705.786 | L85: -63705.786 | M85: -357246.34
A86: 3105103 | B86: SEGURO DE CESANTIA | C86: 414120 | E86: 39591.919 | F86: 37106.404 | G86: 40770.864 | H86: 75837.327 | I86: 0 | J86: 53620.134 | K86: 19407.888 | L86: 19407.888 | M86: 108834.65
A87: 3105104 | B87: GRATIFICACION | C87: 1436130 | E87: 137301.13 | F87: 128681.59 | G87: 141389.6 | H87: 262996.86 | I87: 0 | J87: 185949.69 | K87: 67304.766 | L87: 67304.766 | M87: 377428.53
A88: 3105107 | B88: FINIQUITOS | C88: 634303 | E88: 60642.502 | F88: 56835.466 | G88: 62448.279 | H88: 116159.19 | I88: 0 | J88: 82129.364 | K88: 29726.846 | L88: 29726.846 | M88: 166700.82
A89: 3105108 | B89: ASIGNACION COLACION | C89: 608000 | E89: 58127.806 | F89: 54478.637 | G89: 59858.701 | H89: 111342.35 | I89: 0 | J89: 78723.659 | K89: 28494.146 | L89: 28494.146 | M89: 159788.14
...

Sheet ER Centro de Costo aperturado
D1: 300 | E1: 130 | F1: 140 | G1: 150 | H1: 100 | I1: 2 | J1: 170 | K1: 180 | L1: 185 | M1: 500 | N1: 190 | O1: 195 | P1: 200 | Q1: 210
B2: Estado de Resultado por Centro de Costo
B3: =+'Estado de Resultados'!B3 -> Para el período comprendido entre el 01-01-2026 hasta el 31/01/2026
C5: FLEXI | D5: =+D8/$R$8 -> 0 | E5: =+E8/$R$8 -> 0.13267171 | F5: =+F8/$R$8 -> 0 | G5: =+G8/$R$8 -> 0.092921499 | H5: =+H8/$R$8 -> 0.11890004 | J5: =+J8/$R$8 -> 0.18393545 | K5: =+K8/$R$8 -> 0.088426071 | L5: =+L8/$R$8 -> 0 | M5: =+M8/$R$8 -> 0 | N5: =+N8/$R$8 -> 0.14955484 | O5: =+O8/$R$8 -> 0.070423486 | P5: =+P8/$R$8 -> 0.067144825 | Q5: =+Q8/$R$8 -> 0.096022088
B6: N° CUENTA | C6: NOMBRE CUENTA | D6: CEDIS CHILE | E6: EGAÑA | F6: VESPUCIO | G6: TREBOL | H6: ONLINE | I6: ADMINISTRACION | J6: COSTANERA CENTER | K6: FLORIDA CENTER | L6: CONCEPCION CENTRO | M6: DEPARTAMENTAL | N6: SANTIAGO CENTRO | O6: MAULE TALCA | P6: PLAZA NORTE | Q6: PLAZA OESTE | R6: TOTAL
B8: 3.1.01.101 | C8: VENTAS CON BOLETA | D8: =SUM(D9:D10) -> 0 | E8: =SUM(E9:E10) -> 29741079 | F8: =SUM(F9:F10) -> 0 | G8: =SUM(G9:G10) -> 20830255 | H8: =SUM(H9:H10) -> 26653877 | I8: =SUM(I9:I10) -> 0 | J8: =SUM(J9:J10) -> 41232894 | K8: =SUM(K9:K10) -> 19822513 | M8: =SUM(M9:M10) -> 0 | N8: =SUM(N9:N10) -> 33525777 | O8: =SUM(O9:O10) -> 15786866 | P8: =SUM(P9:P10) -> 15051887 | Q8: =SUM(Q9:Q10) -> 21525316 | R8: =SUM(D8:Q8) -> 2.2417046e+08
C9: ACCESORIOS | E9: 438302.52 | G9: 622984.03 | H9: 59075.63 | J9: 791978.15 | K9: 394328.57 | N9: 439117.65 | O9: 208371.43 | P9: 403824.37 | Q9: 507118.49 | R9: =SUM(E9:Q9) -> 3865100.8
C10: CALZADO | E10: 29302776 | G10: 20207271 | H10: 26594801 | J10: 40440916 | K10: 19428185 | N10: 33086660 | O10: 15578494 | P10: 14648062 | Q10: 21018197 | R10: =SUM(E10:Q10) -> 2.2030536e+08
B11: 3.1.02.101 | C11: COSTO DE VENTAS | E11: -16286827 | F11: 0 | G11: -10948521 | H11: -17063296 | J11: -22321825 | K11: -10656695 | N11: -18278478 | O11: -8650021 | P11: -8315284 | Q11: -12089897 | R11: =SUM(D11:Q11) -> -124610844
B12: Resultado por Centro de Beneficio | D12: =+D8+D11 -> 0 | E12: =+E8+E11 -> 13454252 | F12: =+F8+F11 -> 0 | G12: =+G8+G11 -> 9881734.5 | H12: =+H8+H11 -> 9590580.6 | I12: =+I8+I11 -> 0 | J12: =+J8+J11 -> 18911069 | K12: =+K8+K11 -> 9165818.4 | M12: =+M8+M11 -> 0 | N12: =+N8+N11 -> 15247299 | O12: =+O8+O11 -> 7136844.5 | P12: =+P8+P11 -> 6736602.6 | Q12: =+Q8+Q11 -> 9435419 | R12: =+R8+R11 -> 99559620 | S12: OK
C14: TAMARIS | D14: =+D17/$R$17 -> 0 | E14: =+E17/$R$17 -> 0.14363779 | F14: =+F17/$R$17 -> 0 | G14: =+G17/$R$17 -> 0.10164352 | H14: =+H17/$R$17 -> 0.037241118 | J14: =+J17/$R$17 -> 0.27732215 | K14: =+K17/$R$17 -> 0.052538301 | L14: =+L17/$R$17 -> 0 | M14: =+M17/$R$17 -> 0 | N14: =+N17/$R$17 -> 0.10535764 | O14: =+O17/$R$17 -> 0.050934272 | P14: =+P17/$R$17 -> 0.077745631 | Q14: =+Q17/$R$17 -> 0.15357958
B15: N° CUENTA | C15: NOMBRE CUENTA | D15: CEDIS CHILE | E15: EGAÑA | F15: VESPUCIO | G15: TREBOL | H15: ONLINE | I15: ADMINISTRACION | J15: COSTANERA CENTER | K15: FLORIDA CENTER | L15: CONCEPCION CENTRO | M15: DEPARTAMENTAL | N15: SANTIAGO CENTRO | O15: MAULE TALCA | P15: PLAZA NORTE | Q15: PLAZA OESTE | R15: TOTAL
B17: 3.1.01.101 | C17: VENTAS CON BOLETA | D17: =SUM(D18:D19) -> 0 | E17: =SUM(E18:E19) -> 3223809.2 | F17: =SUM(F18:F19) -> 0 | G17: =SUM(G18:G19) -> 2281289.1 | H17: =SUM(H18:H19) -> 835840.34 | I17: =SUM(I18:I19) -> 0 | J17: =SUM(J18:J19) -> 6224223.5 | K17: =SUM(K18:K19) -> 1179170.6 | M17: =SUM(M18:M19) -> 0 | N17: =SUM(N18:N19) -> 2364648.7 | O17: =SUM(O18:O19) -> 1143169.7 | P17: =SUM(P18:P19) -> 1744924.4 | Q17: =SUM(Q18:Q19) -> 3446942.9 | R17: =SUM(D17:Q17) -> 22444018
C18: ACCESORIOS | R18: =SUM(E18:Q18) -> 0
C19: CALZADO | E19: 3223809.2 | F19: 0 | G19: 2281289.1 | H19: 835840.34 | J19: 6224223.5 | K19: 1179170.6 | N19: 2364648.7 | O19: 1143169.7 | P19: 1744924.4 | Q19: 3446942.9 | R19: =SUM(E19:Q19) -> 22444018
B20: 3.1.02.101 | C20: COSTO DE VENTAS | E20: -1506504 | F20: 0 | G20: -995836 | H20: -382558 | J20: -2889387 | K20: -533847 | N20: -1065192 | O20: -485141 | P20: -804536 | Q20: -1565226 | R20: =SUM(D20:Q20) -> -10228227
B21: Resultado por Centro de Beneficio | D21: =+D17+D20 -> 0 | E21: =+E17+E20 -> 1717305.2 | F21: =+F17+F20 -> 0 | G21: =+G17+G20 -> 1285453.1 | H21: =+H17+H20 -> 453282.34 | I21: =+I17+I20 -> 0 | J21: =+J17+J20 -> 3334836.5 | K21: =+K17+K20 -> 645323.59 | M21: =+M17+M20 -> 0 | N21: =+N17+N20 -> 1299456.7 | O21: =+O17+O20 -> 658028.75 | P21: =+P17+P20 -> 940388.37 | Q21: =+Q17+Q20 -> 1881716.9 | R21: =+R17+R20 -> 12215791 | S21: OK
B23: N° CUENTA | C23: NOMBRE CUENTA | D23: CEDIS CHILE | E23: EGAÑA | F23: VESPUCIO | G23: TREBOL | H23: ONLINE | I23: ADMINISTRACION | J23: COSTANERA CENTER | K23: FLORIDA CENTER | L23: CONCEPCION CENTRO | M23: DEPARTAMENTAL | N23: SANTIAGO CENTRO | O23: MAULE TALCA | P23: PLAZA NORTE | Q23: PLAZA OESTE | R23: TOTAL
B25: 3.1.01.300 | C25: OTROS INGRESOS | D25: 0 | E25: 0 | F25: 0 | G25: 0 | H25: 3751074 | I25: 0 | J25: 0 | K25: 0 | L25: 0 | M25: 0 | N25: 0 | O25: 0 | P25: 0 | Q25: 0 | R25: =SUM(D25:Q25) -> 3751074
B26: 3.1.02.102 | C26: COSTOS OPERATIVOS - FLETES INTERNOS | D26: -2164695 | E26: 21780 | F26: 0 | G26: 21780 | H26: 150000 | I26: 0 | J26: 21780 | K26: 21780 | L26: 0 | M26: 0 | N26: 21780 | O26: 21780 | P26: 21780 | Q26: 21780 | R26: =SUM(D26:Q26) -> -1840455
B27: 3.1.02.104 | C27: COMISIÓN - CANAL DIGITAL | D27: 0 | E27: 0 | F27: 0 | G27: 0 | H27: -3004368 | I27: 0 | J27: 0 | K27: 0 | L27: 0 | M27: 304544 | N27: 0 | O27: 0 | P27: 0 | Q27: 0 | R27: =SUM(D27:Q27) -> -2699824
B28: 3.1.02.105 | C28: FLETES - CANAL DIGITAL | D28: 0 | E28: 0 | F28: 0 | G28: 0 | H28: 2066127 | I28: 0 | J28: 0 | K28: 0 | L28: 0 | M28: -2866174 | N28: 0 | O28: 0 | P28: 0 | Q28: 0 | R28: =SUM(D28:Q28) -> -800047
B29: 3.1.02.108 | C29: SERVICIOS - CANAL DIGITAL | D29: 0 | E29: 0 | F29: 0 | G29: 0 | H29: -129245 | I29: 0 | J29: 0 | K29: 0 | L29: 0 | M29: -1846777 | N29: 0 | O29: 0 | P29: 0 | Q29: 0 | R29: =SUM(D29:Q29) -> -1976022
B30: 3.1.02.109 | C30: DESCUENTOS GIFTCARD | D30: 0 | E30: 0 | F30: 0 | G30: 0 | H30: 0 | I30: 0 | J30: 0 | K30: 0 | L30: 0 | M30: 0 | N30: -44990 | O30: 0 | P30: 0 | Q30: 0 | R30: =SUM(D30:Q30) -> -44990
B31: 3.1.02.110 | C31: DESCUENTOS CLUB FLEXI | D31: 0 | E31: 0 | F31: 0 | G31: 0 | H31: 0 | I31: 0 | J31: -14372 | K31: -27334 | L31: 0 | M31: 0 | N31: -4801 | O31: 0 | P31: 0 | Q31: 0 | R31: =SUM(D31:Q31) -> -46507
B32: 3.1.05.101 | C32: REMUNERACIONES | D32: 0 | E32: -5471370 | F32: 0 | G32: -5105142 | H32: -3360231 | I32: -589781 | J32: -6163578 | K32: -4432782 | L32: 0 | M32: -1429576 | N32: -5819291 | O32: -3991543 | P32: -4129167 | Q32: -4624690 | R32: =SUM(D32:Q32) -> -45117151
B33: 3.1.05.102 | C33: BONOS | D33: 0 | E33: -273846 | F33: 0 | G33: -183785 | H33: -127312 | I33: 0 | J33: -295071 | K33: -167527 | L33: 0 | M33: 0 | N33: -668574 | O33: -17293 | P33: 805918 | Q33: -803000 | R33: =SUM(D33:Q33) -> -1730490
B34: 3.1.05.103 | C34: SEGURO DE CESANTIA | D34: 0 | E34: -190943 | F34: 0 | G34: -203449 | H34: -92175 | I34: -44143 | J34: -226386 | K34: -163670 | L34: 0 | M34: -34952 | N34: -219642 | O34: -149355 | P34: -149071 | Q34: -181297 | R34: =SUM(D34:Q34) -> -1655083
B35: 3.1.05.104 | C35: GRATIFICACION | D35: 0 | E35: -1260847 | F35: 0 | G35: -1345486 | H35: -460102 | I35: -215308 | J35: -1419780 | K35: -1136975 | L35: 0 | M35: -147415 | N35: -1338001 | O35: -1000642 | P35: -1039174 | Q35: -1220422 | R35: =SUM(D35:Q35) -> -10584152
B36: 3.1.05.107 | C36: FINIQUITOS | D36: 0 | E36: 0 | F36: 0 | G36: 0 | H36: 0 | I36: -4000 | J36: 0 | K36: 0 | L36: 0 | M36: 0 | N36: 0 | O36: 0 | P36: 0 | Q36: 0 | R36: =SUM(D36:Q36) -> -4000
... B78: 3.2.08.105 | C78: INTERESES POR PRESTAMO | D78: 0 | E78: 0 | F78: 0 | G78: 0 | H78: 0 | I78: 0 | J78: -8446 | K78: 0 | L78: 0 | M78: 0 | N78: 0 | O78: 0 | P78: -4101 | Q78: -6758 | R78: =SUM(D78:Q78) -> -19305
B79: 3.2.08.114 | C79: INTERESES DEVENGADOS FONDOS MU | D79: 0 | E79: 0 | F79: 0 | G79: 0 | H79: 0 | I79: 0 | J79: 0 | K79: 0 | L79: 0 | M79: 0 | N79: 0 | O79: 0 | R79: =SUM(D79:Q79) -> 0
B80: 3.2.08.116 | C80: INTERES GANADO POR DEPOSITO A PLAZO PESOS | D80: 0 | E80: 0 | F80: 0 | G80: 0 | H80: 0 | I80: 5791 | J80: 0 | K80: 0 | L80: 0 | M80: 0 | N80: 0 | O80: 0 | P80: 0 | Q80: 0 | R80: =SUM(D80:Q80) -> 5791
B81: 3.2.08.117 | C81: INTERES GANADO FONDOS MUTUOS | D81: 0 | E81: 0 | F81: 0 | G81: 0 | H81: 0 | I81: 0 | J81: 0 | K81: 0 | L81: 0 | M81: 0 | N81: 0 | O81: 0 | R81: =SUM(D81:Q81) -> 0
B82: 3.2.11.158 | C82: DIFERENCIA DE CAMBIO | H82: 0 | I82: 24026172 | M82: 0 | R82: =SUM(D82:Q82) -> 24026172
B83: 3.2.13.101 | C83: CORRECCION MONETARIA ACTIVOS | D83: 0 | E83: 0 | F83: 0 | G83: 0 | H83: 0 | I83: -623797 | J83: 0 | K83: 0 | L83: 0 | M83: 0 | N83: 0 | O83: 0 | P83: 0 | Q83: 0 | R83: =SUM(D83:Q83) -> -623797
B84: 3.2.13.109 | C84: AJUSTE REDONDEO AUTO | D84: 0 | E84: 0 | F84: 0 | G84: 0 | H84: 0 | I84: -34 | J84: 0 | K84: 0 | L84: 0 | M84: 0 | N84: 0 | O84: 0 | P84: 0 | Q84: 0 | R84: =SUM(D84:Q84) -> -34
B85: Resultado por Centro de Costo | D85: =SUM(D25:D84) -> -8834134 | E85: =SUM(E25:E84) -> -18557806 | F85: =SUM(F25:F84) -> -11619 | G85: =SUM(G25:G84) -> -17972450 | H85: =SUM(H25:H84) -> -5369377 | I85: =SUM(I25:I84) -> 11379261 | J85: =SUM(J25:J84) -> -32106886 | K85: =SUM(K25:K84) -> -19456181 | ... Q85: =SUM(Q25:Q84) -> -18312604 | R85: =SUM(D85:Q85) -> -164006834
B87: Resultado por Centro de Costo | D87: =D21+D85+D12 -> -8834134 | E87: =E21+E85+E12 -> -3386248.8 | F87: =F21+F85+F12 -> -11619 | G87: =G21+G85+G12 -> -6805262.5 | H87: =H21+H85+H12 -> 4674486 | I87: =I21+I85+I12 -> 11379261 | J87: =J21+J85+J12 -> -9860980.4 | K87: =K21+K85+K12 -> -9645039 | ... R87: =R21+R85+R12 -> -52231422
R89: =+R87-'Balance 8 Columnas'!J118 -> 191.5126
...

Sheet Patrimonio
B1: Flexi Chile Spa
B2: Cuadro Patromonial
B3: =+'Balance 8 Columnas'!B4:K4 -> Al 31 de enero de 2026
B5: PATRIMONIO
B6: Movimientos de patrimonio durante el ejercicio 2026 - Moneda Local $
B7: Detalle | C7: Capital | D7: Aportes por Capitalizar | E7: Aportes por Enterar | F7: Resultados Acumulados | G7: Retiros | H7: Resultado del Periodo | I7: Totales
B10: Saldos al 31/12/2025 | C10: 4547054500 | D10: 0 | E10: 0 | F10: -2294052799 | G10: 0 | H10: -848054041 | I10: =SUM(C10:H10) -> 1404947660
B11: Distribución resultado ejercicio anterior | D11: 0 | F11: =+H10 -> -848054041 | G11: 0 | H11: =-H10 -> 848054041 | I11: =SUM(C11:H11) -> 0
B12: Aporte Capital 02-01-2025 | C12: 1223614367 | I12: =SUM(C12:H12) -> 1223614367
B13: Resultado del período | D13: 0 | F13: 0 | H13: =+-'Balance 8 Columnas'!N118 -> -52231614 | I13: =SUM(C13:H13) -> -52231614
B14: Saldos | C14: =ROUND(SUM(C10:C13),0) -> 5770668867 | D14: =ROUND(SUM(D10:D13),0) -> 0 | E14: =ROUND(SUM(E10:E13),0) -> 0 | F14: =ROUND(SUM(F10:F13),0) -> -3142106840 | G14: =ROUND(SUM(G10:G13),0) -> 0 | H14: =ROUND(SUM(H10:H13),0) -> -52231614 | I14: =ROUND(SUM(I10:I13),0) -> 2576330413
C16: =C14+'Balance 8 Columnas'!N60 -> 0 | F16: =+F14+'Balance 8 Columnas'!N61 -> -1
B17: Movimientos de patrimonio durante el ejercicio 2025 - Moneda Dólar
B18: Detalle | C18: Capital | D18: Aportes por Capitalizar | E18: Aportes por Enterar | F18: Resultados Acumulados | G18: Retiros | H18: Resultado del Periodo | I18: Totales
B21: Saldos al 31/12/2025 USD 5.075.000 | C21: 5075000 | D21: 0 | E21: 0 | F21: -2544044 | G21: 0 | H21: -907553 | I21: =SUM(C21:H21) -> 1623403
B22: Distribución resultado ejercicio anterior | D22: 0 | F22: =+H21 -> -907553 | G22: 0 | H22: =-H21 -> 907553 | I22: =SUM(C22:H22) -> 0
B23: Aporte Capital 02-01-2025 | C23: 1348885.4 | I23: =SUM(C23:H23) -> 1348885.4
B24: Resultado del período | D24: 0 | F24: 0 | H24: =H13/865.1 -> -60376.389 | I24: =SUM(C24:H24) -> -60376.389
B25: Saldos | C25: =ROUND(SUM(C21:C24),0) -> 6423885 | D25: =ROUND(SUM(D21:D24),0) -> 0 | E25: =ROUND(SUM(E21:E24),0) -> 0 | F25: =ROUND(SUM(F21:F24),0) -> -3451597 | G25: =ROUND(SUM(G21:G24),0) -> 0 | H25: =ROUND(SUM(H21:H24),0) -> -60376 | I25: =ROUND(SUM(I21:I24),0) -> 2911912
B29: Socios | C29: acciones | D29: % | F29: Monto USD | H29: Monto CLP
B30: Grupo Calzado Flexi, S.A.P.I de C.V | C30: 100 | D30: 2.08 | F30: 100000 | H30: 75000000
B31: Flexi Retail International, S.L., | C31: 4697 | D31: 97.92 | F31: 6323885 | H31: =5770668867-75000000 -> 5695668867
B32: Totales | C32: =SUM(C30:C31) -> 4797 | D32: =SUM(D30:D31) -> 100 | E32: =SUM(E30:E31) -> 0 | F32: =SUM(F30:F31) -> 6423885 | G32: =SUM(G30:G31) -> 0 | H32: =SUM(H30:H31) -> 5770668867

Sheet Cajas y Bancos
A1: Balance 8 Columnas'!A1 | B1: Flexi Chile Spa | I1: =+C12-'Balance Clasificado'!D10 -> 0.40250707
B2: Análisis y Detalle de Cuentas de Cajas y Bancos
B3: =+Patrimonio!B3 -> Al 31 de enero de 2026
F4: Volver
B5: CAJAS Y BANCOS - Agrupación:
B6: Cuentas | C6: Monto MN $
B7: Efectivo en transito | C7: =+E19 -> 74105055
B8: Fondos Fijos | C8: =+F33 -> 422630
B9: Bancos Cuenta Corriente $ | C9: =F52 -> 440582927
B10: Bancos Cuenta Corriente USD$ | C10: =+'Balance 8 Columnas'!H21 -> 371961813
B11: Deposito a Plazo | C11: =+H77 -> 4941276.4
B12: Total Cajas y Bancos | C12: =SUM(C7:C11) -> 8.920137e+08
B14: CAJAS Y BANCOS - Detalle:
B16: EFECTIVO EN TRANSITO
B17: Nombre Cuenta | C17: Nombre Titular | E17: Importe MN
B18: Efectivo en transito | C18: periodo de cierre | E18: 74105055
C19: Total | E19: =+E18 -> 74105055 | F19: ok
B21: Fondos Fijos
B22: Fecha | C22: Detalle | F22: Valor Actual
B23: 46053 | C23: Fondo Fijo Plaza Egaña | F23: =53286+46624-58308 -> 41602 | G23: OK
B24: =+B23 -> 46053 | C24: Fondo Fijo Vespucio | F24: 85990 | G24: OK
B25: =+B24 -> 46053 | C25: Fondo Fijo Trebol | F25: 2682 | G25: OK
B26: =+B25 -> 46053 | C26: Fondo Fijo Costanera Center | F26: -8130 | G26: OK
B27: =+B26 -> 46053 | C27: Fondo Fijo Florida Center | F27: 83000 | G27: OK
B28: =+B27 -> 46053 | C28: Fondo Fijo Santiago Centro | F28: 39570 | G28: OK
B29: =+B27 -> 46053 | C29: Fondo Fijo Concepcion Centro | F29: 57490 | G29: OK
B30: =+B27 -> 46053 | C30: Fondo Fijo Talca | F30: 13306 | G30: OK
B31: =+B27 -> 46053 | C31: Fondo Fijo Plaza Norte | F31: 47120 | G31: OK
B32: =+B28 -> 46053 | C32: Fondo Fijo Plaza Oeste | F32: 60000 | G32: OK
B33: Saldo Según Balance | F33: =SUM(F23:F32) -> 422630 | G33: ok
B36: Banco Santander
B38: Saldo Según Cartola Bancaria | F38: 440582927 | G38: OK
B39: Banco Santander Pesos - Cta. Cte. 0-000-7776441-0
B40: Cheques Girados y No cobrados
B41: Fecha Emisión | C41: Numero Cheque | D41: Detalle | F41: Valor
D44: Total Cheques no cobrados | F44: =SUM(E42:E43)*-1 -> 0
C46: Saldo según Conciliación | F46: =SUM(F38:F45) -> 440582927 | G46: ok
C48: Saldo según balance | F48: =+'Balance 8 Columnas'!H20 -> 440582927
C50: Control | F50: =+F46-F48 -> 0
B52: Total Banco santander | F52: =+F48 -> 440582927 | G52: OK
...

Sheet Otros Act no Fin
B1: Flexi Chile Spa | G1: =+C8-'Balance Clasificado'!D11 -> -88703455
B2: Análisis y Detalle de Otros Activos No Financieros, Corriente
B3: =+'Cajas y Bancos'!B3 -> Al 31 de enero de 2026
B5: Otros Activos No Financieros, Corriente - Agrupación
B6: Cuentas | C6: Monto MN $
B7: GARANTIAS OTORGADAS | C7: 0
B8: TOTAL ACTIVOS FINANCIEROS CORRIENTES | C8: =SUM(C7:C7) -> 0
B10: Otros Activos No Financieros, Corriente - Detalle
B12: GARANTIAS OTORGADAS
B13: DETALLE | C13: Fecha | D13: Valor Actual
B14: BOLETA DE GARANTIA - Plaza Egaña | C14: 44176 | D14: 13164563
B15: BOLETA DE GARANTIA - Plaza el Trebol | C15: 44176 | D15: 11854972
B16: BOLETA DE GARANTIA - Plaza Vespucio | C16: 44176 | D16: 10592505
B17: BOLETA DE GARANTIA - Arauco Maipu | C17: 44176 | D17: 10250999
B18: BOLETA DE GARANTIA - Plaza Los Dominicos | C18: 44176 | D18: 2264005
B19: BOLETA DE GARANTIA - Costanera Center | C19: 44392 | D19: 22306718
B20: BOLETA DE GARANTIA - Costanera Center | C20: 44392 | D20: 9814956
B21: Saldo Según Balance | D21: =SUM(D14:D20) -> 80248718

Sheet Derechos de arrendamiento
A1: Balance 8 Columnas'!A1 | B1: Flexi Chile Spa | H1: =+C9-'Balance Clasificado'!D11 -> 0
B2: Análisis y Detalle de Derechos de arrendamiento
B3: =+Carátula!A9 -> Al 31 de enero de 2026
B5: Derechos de arrendamiento - Agrupación
B6: Cuentas | C6: Monto MN $
B7: GASTOS PAGADOS POR ANTICIPADO | C7: =+D331 -> 31375083
B8: GARANTIAS ARRIENDO | C8: =$D$344 -> 57328372
B9: TOTAL Derechos de arrendamiento | C9: =SUM(C7:C8) -> 88703455
B11: Derechos de arrendamiento - Detalle
B13: GASTOS PAGADOS POR ANTICIPADO
B14: DETALLE | D14: Valor Actual
B15: VMM COSTANERA CENTER | D15: 16213165
B16: VMM COSTANERA CENTER | C16: 44473 | D16: 5765894
B17: *01.10.2021-01.10.2021-Recargo VMM Costanera Center | C17: 44505 | D17: 16437082
B18: *01.11.2021-01.11.2021-Recargo VMM Florida Center | C18: 44501 | D18: 10941199
B19: *01.10.2021-01.10.2021-Fondo Inicial Pub Costanera Center | C19: 44516 | D19: 7583329
B20: *01.11.2021-01.11.2021-Fondo Inicial Pub Florida Center | C20: 44516 | D20: 3883398
B21: Amortización VMN Costanera Center 1/60 | C21: 44500 | D21: =-(D15+D16)/60 -> -366317.65
B22: Amortización VMN Costanera Center 2/60 | C22: 44530 | D22: =-(D16+D17+D15+D19)/60 -> -766657.83
B23: Amortización VMN Florida Center 1/60 | C23: 44530 | D23: =-(D18+D20)/60 -> -247076.62
B24: Recargo VMM Florida Center | C24: 44561 | D24: 11088922
B25: *01.12.2021-01.12.2021-Fondo Inicial Pub Florida Center | C25: 44561 | D25: 3911925
B26: *01.12.2021-01.12.2021-Aporte Mensual PU Florida Center | C26: 44561 | D26: 193748
B27: Amortización VMN Costanera Center 3/60 | C27: 44530 | D27: -766657.83
B28: Amortización VMN Florida Center 2/60 | C28: 44530 | D28: =-SUM(D18,D20,D24,D25,D26)/60 -> -500319.87
B29: Amortización VMN Costanera Center 4/60 | C29: 44592 | D29: -766658
B30: Amortización VMN Florida Center 3/60 | C30: 44592 | D30: -500319
B31: *04.01.2022-04.01.2022-Recargo VMM Florida Center | C31: 44599 | D31: =11256790-2047063 -> 9209727
B32: *04.01.2022-04.01.2022-Fondo Inicial Pub Florida Center | C32: 44599 | D32: =3971145-195032 -> 3776113
B33: Amortización VMN Costanera Center 5/60 | C33: 44620 | D33: -766658
B34: Amortización VMN Florida Center 4/60 | C34: 44620 | D34: =-500319.866666667+((-D31+D32)/60) -> -590880.1
B35: Amortización VMN Costanera Center 6/60 | C35: 44651 | D35: -766657.83
B36: Amortización VMN Florida Center 5/60 | C36: 44651 | D36: -590880
B37: Amortización VMN Costanera Center 7/60 | C37: 44681 | D37: -766657.83
B38: Amortización VMN Florida Center 6/60 | C38: 44681 | D38: -590880
B39: Amortización VMN Costanera Center 8/60 | C39: 44712 | D39: -766657.83
B40: Amortización VMN Florida Center 7/60 | C40: 44712 | D40: -590880
B41: Amortización VMN Costanera Center 9/60 | C41: 44742 | D41: -766657.83
B42: Amortización VMN Florida Center 8/60 | C42: 44742 | D42: -590880
B43: Amortización VMN Costanera Center 10/60 | C43: 44773 | D43: -766657.83
...

Sheet Deudores Diversos
A1: Balance 8 Columnas'!A1 | B1: Flexi Chile Spa | H1: =+D16-'Balance Clasificado'!D14 -> 0
B2: Análisis y Detalle de Deudores Diversos
B3: =+Carátula!A9 -> Al 31 de enero de 2026
B6: DEUDORES DIVERSOS - Agrupación:
B7: Cuentas | D7: Monto
B8: 1104102 | C8: CLIENTES BOLETAS | D8: =+E23 -> -3158489
B9: 1104105 | C9: TRANSBANK POR COBRAR TC | D9: =+E28 -> 54573495
B10: 1104106 | C10: TRANSBANK POR COBRAR TD | D10: =+E32 -> 71836904
B11: 1104108 | C11: GIFTCARD | D11: =+E38 -> 480400
B12: 1104109 | C12: ECOMMERCE | D12: =+E43 -> 201859659
B13: 1104112 | C13: GETNET TC | D13: =+E48 -> 9764312
B14: 1104113 | C14: GETNET TD | D14: =+E53 -> 1531859
B15: 1104200 | C15: CUENTA POR COBRAR | D15: =+E60 -> 6734121
B16: TOTAL Deudores Diversos | D16: =SUM(D8:D15) -> 343622261
B18: DEUDORES DEUDORES DIVERSOS - Detalle:
B20: CLIENTES BOLETAS
B21: Nombre Cuenta | C21: Detalle/Fecha | E21: Importe MN
B22: Clientes Boletas | C22: Saldo al cierre | E22: -3158489
B23: CLIENTES BOLETAS Total | E23: =+E22 -> -3158489 | F23: ok
B25: TRANSBANK POR COBRAR TC
B26: Nombre Cuenta | C26: Detalle | E26: Importe MN
B27: TRANSBANK POR COBRAR TC | C27: al cierre | E27: 54573495
C28: Total | E28: =SUM(E27:E27) -> 54573495 | F28: ok
B30: TRANSBANK POR COBRAR TD
B31: Nombre Cuenta | C31: Nombre Titular | E31: Importe MN
B32: TRANSBANK POR COBRAR TD | C32: periodo cierre | E32: 71836904
C33: Total | E33: =+E32 -> 71836904 | F33: ok
B35: GIFTCARD
B36: Nombre Cuenta | C36: Detalle | E36: Importe MN
B37: Giftcard | C37: periodo Cierre | E37: 480400
C38: Total | E38: =SUM(E37:E37) -> 480400 | F38: ok
B40: ECOMMERCE
B41: Nombre Cuenta | C41: Detalle | E41: Importe MN
B42: Ecommerce | C42: periodo Cierre | E42: 201859659
C43: Total | E43: =SUM(E42:E42) -> 201859659 | F43: ok
B45: GETNET TC
B46: Nombre Cuenta | C46: Detalle | E46: Importe MN
B47: Tarjeta de credito | C47: periodo Cierre | E47: 9764312
C48: Total | E48: =SUM(E47:E47) -> 9764312 | F48: ok
B50: GETNET TD
...

Sheet Pagos Anticipados
A1: Balance 8 Columnas'!A1 | B1: Flexi Chile Spa | H1: =+D13-'Balance Clasificado'!D13 -> 0
B2: Análisis y Detalle de Pagos Anticipados
B3: =+Carátula!A9 -> Al 31 de enero de 2026
B6: PAGOS ANTICIPADOS - Agrupación:
