Workbook

Sheet Balanza ok
B2: Cuenta Mexico | C2: Texto | D2: Cuenta Chile
A3: ok | B3: 111100 | C3: FONDOS FIJOS | D3: 1.1.01.201 | E3: FONDO FIJO LOS DOMINICOS
B4: 111100 | C4: FONDOS FIJOS | D4: 1.1.01.202 | E4: FONDO FIJO MAIPU
B5: 111100 | C5: FONDOS FIJOS | D5: 1.1.01.203 | E5: FONDO FIJO PLAZA EGAÑA
B6: 111100 | C6: FONDOS FIJOS | D6: 1.1.01.204 | E6: FONDO FIJO VESPUCIO
B7: 111100 | C7: FONDOS FIJOS | D7: 1.1.01.205 | E7: FONDO FIJO TREBOL
B8: 111100 | C8: FONDOS FIJOS | D8: 1.1.01.206 | E8: FONDO FIJO COSTANERA CENTER
B9: 111100 | C9: FONDOS FIJOS | D9: 1.1.01.207 | E9: FONDO FIJO FLORIDA CENTER
B10: 111100 | C10: FONDOS FIJOS | D10: 1.1.01.208 | E10: FONDO FIJO SANTIAGO CENTRO
B11: 111100 | C11: FONDOS FIJOS | D11: 1.1.01.209 | E11: FONDO FIJO CONCEPCION CENTRO
B12: 111100 | C12: FONDOS FIJOS | D12: 1.1.01.210 | E12: FONDO FIJO TALCA
B13: 111100 | C13: FONDOS FIJOS | D13: 1.1.01.211 | E13: FONDO FIJO PLAZA NORTE
B14: 111100 | C14: FONDOS FIJOS | D14: 1.1.01.212 | E14: FONDO FIJO PLAZA OESTE
A15: ok | B15: 112093 | C15: SANTANDER CHILE ( 89 ) SALDO | D15: 1.1.01.301 | E15: BANCOS CTA CTE $
A16: ok | B16: 112094 | C16: SANTANDER ( 89 ) INVERSION | D16: 1.1.02.106 | E16: DEPOSITO A PLAZO CORREDORA
B17: 112094 | C17: SANTANDER ( 89 ) INVERSION | D17: 1.1.01.501 | E17: INVERSION FONDO MUTUO
B18: 112095 | C18: SANTANDER ( 89 ) USD | D18: 1.1.01.502 | E18: INVERIOSN FONDO MUTUO USD
A19: ok | B19: 112095 | C19: SANTANDER ( 89 ) USD | D19: 1.1.01.302 | E19: BANCOS CTA CTE US$
A20: ok | B20: 113100 | C20: CLIENTES | D20: 1.1.04.102 | E20: CLIENTES BOLETAS | F20: Sin factura
B21: 111100 | C21: DEUDORES DIVERSOS | D21: 1.1.04.101 | E21: CLIENTES NACIONALES | F21: Con factura
B22: 113103 | C22: CLIENTES PARTES RELACIONADAS
B23: 115000 | C23: DOCUMENTOS POR COBRAR
B24: 111100 | C24: DEUDORES DIVERSOS | D24: 1.1.01.101 | E24: EFECTIVO EN TRANSITO
B25: 115010 | C25: DEUDORES DIVERSOS | D25: 1.1.04.105 | E25: TRANSBANK POR COBRAR TC
A26: ok | B26: 115010 | C26: DEUDORES DIVERSOS | D26: 1.1.04.106 | E26: TRANSBANK POR COBRAR TD
B27: 115010 | C27: DEUDORES DIVERSOS | D27: 1.1.04.112 | E27: GETNET TC
B28: 115010 | C28: DEUDORES DIVERSOS | D28: 1.1.04.113 | E28: GETNET TD/ PREPAGO
B29: 115010 | C29: DEUDORES DIVERSOS | D29: 1.1.04.108 | E29: GIFTCARD
B30: 115010 | C30: DEUDORES DIVERSOS | D30: 1.1.04.109 | E30: ECOMMERCE
B31: 115010 | C31: DEUDORES DIVERSOS | D31: 1.1.04.200 | E31: CUENTAS POR COBRAR
B32: 115010 | C32: DEUDORES DIVERSOS | D32: 1.1.04.201 | E32: CUENTAS POR COBRAR USD
B33: 115010 | C33: DEUDORES DIVERSOS | D33: 1.1.04.300 | E33: PROVISION INGRESOS | F33: (para pago publicidad recibido en enero)
B34: 115025 | C34: RESERVA CUENTAS INCOBRABLES DEUDORES
B35: 115026 | C35: RETENCIONES POR COBRAR
B36: 115050 | C36: ANTICIPOS PARA VIATICOS
B37: 115061 | C37: ANTICIPOS PROVEEDORES | D37: 1.1.04.104 | E37: FONDOS POR RENDIR
B38: 115060 | C38: ANTICIPOS EMPLEADOS | D38: 1.1.05.302 | E38: ANTICIPOS SUELDOS
A39: ok | B39: 115055 | C39: ANTICIPOS PARA GASTOS | D39: 1.1.05.405 | E39: ANTICIPO AGENCIA DE ADUANAS
A40: OK | B40: 115061 | C40: ANTICIPOS PROVEEDORES | D40: 1.1.05.403 | E40: ANTICIPO PROVEEDORES
A41: ok | B41: 115055 | C41: ANTICIPOS PARA GASTOS | D41: 1.1.05.404 | E41: ANTICIPO HONORARIOS
...

Sheet BCE
D2: Flexi Chile SpA
D3: Al 30 de abril de 2026
A5: MEX | B5: CHILE | C5: MEX
A7: Nombre Cuenta | B7: Clasificacion | C7: Numero Cuenta | D7: Numero Cuenta | E7: Nombre Cuenta | F7: Valores Acumulados | H7: Saldos | J7: Inventario | L7: Resultados | P7: Saldos | Q7: T/C Cierre | R7: Transacioanal | S7: Saldo (R) | U7: Saldos CLP sumados | V7: Dif
F8: Debitos | G8: Creditos | H8: Deudor | I8: Acreedor | J8: Activo | K8: Pasivo | L8: Perdidas | M8: Ganancias | Q8: 903.05
A9: FONDOS FIJOS | B9: Caja y Bancos | C9: 111100 | D9: 1.1.01.101 | E9: EFECTIVO EN TRANSITO | F9: 270743555 | G9: 186333119 | H9: 84410436 | I9: 0 | J9: 84410436 | K9: 0 | L9: 0 | M9: 0 | O9: Monetaria | P9: =+J9-K9+L9-M9 -> 84410436 | Q9: =P9/$Q$8 -> 93472.605 | X9: 1.1.01.101 | Y9: =EXACT(X9,D9) -> TRUE
A10: FONDOS FIJOS | B10: Caja y Bancos | C10: 111100 | D10: 1.1.01.203 | E10: FONDO FIJO PLAZA EGAÑA | F10: 330048 | G10: 292628 | H10: 37420 | I10: 0 | J10: 37420 | K10: 0 | L10: 0 | M10: 0 | O10: Monetaria | P10: =+J10-K10+L10-M10 -> 37420 | Q10: =P10/$Q$8 -> 41.437351 | V10: =U10-P10 -> -37420 | X10: 1.1.01.203 | Y10: =EXACT(X10,D10) -> TRUE
A11: FONDOS FIJOS | B11: Caja y Bancos | C11: 111100 | D11: 1.1.01.204 | E11: FONDO FIJO VESPUCIO | F11: 140340 | G11: 267114 | H11: 0 | I11: 126774 | J11: 0 | K11: 126774 | L11: 0 | M11: 0 | O11: Monetaria | P11: =+J11-K11+L11-M11 -> -126774 | Q11: =P11/$Q$8 -> -140.38425 | V11: =U11-P11 -> 126774 | X11: 1.1.01.204 | Y11: =EXACT(X11,D11) -> TRUE
A12: FONDOS FIJOS | B12: Caja y Bancos | C12: 111100 | D12: 1.1.01.205 | E12: FONDO FIJO TREBOL | F12: 385201 | G12: 352851 | H12: 32350 | I12: 0 | J12: 32350 | K12: 0 | L12: 0 | M12: 0 | O12: Monetaria | P12: =+J12-K12+L12-M12 -> 32350 | Q12: =P12/$Q$8 -> 35.823044 | V12: =U12-P12 -> -32350 | X12: 1.1.01.205 | Y12: =EXACT(X12,D12) -> TRUE
A13: FONDOS FIJOS | B13: Caja y Bancos | C13: 111100 | D13: 1.1.01.206 | E13: FONDO FIJO COSTANERA CENTER | F13: 352120 | G13: 307150 | H13: 44970 | I13: 0 | J13: 44970 | K13: 0 | L13: 0 | M13: 0 | O13: Monetaria | P13: =+J13-K13+L13-M13 -> 44970 | Q13: =P13/$Q$8 -> 49.797907 | V13: =U13-P13 -> -44970 | X13: 1.1.01.206 | Y13: =EXACT(X13,D13) -> TRUE
A14: FONDOS FIJOS | B14: Caja y Bancos | C14: 111100 | D14: 1.1.01.207 | E14: FONDO FIJO FLORIDA CENTER | F14: 407078 | G14: 374218 | H14: 32860 | I14: 0 | J14: 32860 | K14: 0 | L14: 0 | M14: 0 | O14: Monetaria | P14: =+J14-K14+L14-M14 -> 32860 | Q14: =P14/$Q$8 -> 36.387797 | V14: =U14-P14 -> -32860 | X14: 1.1.01.207 | Y14: =EXACT(X14,D14) -> TRUE
A15: FONDOS FIJOS | B15: Caja y Bancos | C15: 111100 | D15: 1.1.01.208 | E15: FONDO FIJO SANTIAGO CENTRO | F15: 215730 | G15: 204370 | H15: 11360 | I15: 0 | J15: 11360 | K15: 0 | L15: 0 | M15: 0 | O15: Monetaria | P15: =+J15-K15+L15-M15 -> 11360 | Q15: =P15/$Q$8 -> 12.579591 | V15: =U15-P15 -> -11360 | X15: 1.1.01.208 | Y15: =EXACT(X15,D15) -> TRUE
A16: FONDOS FIJOS | B16: Caja y Bancos | C16: 111100 | D16: 1.1.01.209 | E16: FONDO FIJO CONCEPCION CENTRO | F16: 103980 | G16: 103980 | H16: 0 | I16: 0 | J16: 0 | K16: 0 | L16: 0 | M16: 0 | O16: Monetaria | P16: =+J16-K16+L16-M16 -> 0 | Q16: =P16/$Q$8 -> 0 | V16: =U16-P16 -> 0 | X16: 1.1.01.209 | Y16: =EXACT(X16,D16) -> TRUE
A17: FONDOS FIJOS | B17: Caja y Bancos | C17: 111100 | D17: 1.1.01.210 | E17: FONDO FIJO TALCA | F17: 389445 | G17: 351423 | H17: 38022 | I17: 0 | J17: 38022 | K17: 0 | L17: 0 | M17: 0 | O17: Monetaria | P17: =+J17-K17+L17-M17 -> 38022 | Q17: =P17/$Q$8 -> 42.103981 | V17: =U17-P17 -> -38022 | X17: 1.1.01.210 | Y17: =EXACT(X17,D17) -> TRUE
A18: FONDOS FIJOS | B18: Caja y Bancos | C18: 111100 | D18: 1.1.01.211 | E18: FONSO FIJO PLAZA NORTE | F18: 262035 | G18: 225915 | H18: 36120 | I18: 0 | J18: 36120 | K18: 0 | L18: 0 | M18: 0 | O18: Monetaria | P18: =+J18-K18+L18-M18 -> 36120 | Q18: =P18/$Q$8 -> 39.997785 | X18: 1.1.01.211 | Y18: =EXACT(X18,D18) -> TRUE
A19: FONDOS FIJOS | B19: Caja y Bancos | C19: 111100 | D19: 1.1.01.212 | E19: FONDO FIJO PLAZA OESTE | F19: 279193 | G19: 237595 | H19: 41598 | I19: 0 | J19: 41598 | K19: 0 | L19: 0 | M19: 0 | O19: Monetaria | P19: =+J19-K19+L19-M19 -> 41598 | Q19: =P19/$Q$8 -> 46.063895 | X19: 1.1.01.212 | Y19: =EXACT(X19,D19) -> TRUE
A20: SANTANDER CHILE | B20: Caja y Bancos | C20: 112093 | D20: 1.1.01.301 | E20: BANCOS CTA CTE $ | F20: 1674610704 | G20: 1460796887 | H20: 213813817 | I20: 0 | J20: 213813817 | K20: 0 | L20: 0 | M20: 0 | O20: Monetaria | P20: =+J20-K20+L20-M20 -> 213813817 | Q20: =P20/$Q$8 -> 236768.53 | V20: =U20-P20 -> -213813817 | X20: 1.1.01.301 | Y20: =EXACT(X20,D20) -> TRUE
A21: SANTANDER CH USD | B21: Caja y Bancos | C21: 112095 | D21: 1.1.01.302 | E21: BANCOS CTA CTE US$ | F21: 1448479616 | G21: 1434002975 | H21: 14476641 | I21: 0 | J21: 14476641 | K21: 0 | L21: 0 | M21: 0 | O21: Monetaria | P21: =+J21-K21+L21-M21 -> 14476641 | Q21: =P21/$Q$8 -> 16030.83 | V21: =U21-P21 -> -14476641 | X21: 1.1.01.302 | Y21: =EXACT(X21,D21) -> TRUE
A22: SANTANDER CH INV | B22: Caja y Bancos | C22: 112094 | D22: 1.1.01.501 | E22: INVERSION FONDO MUTUO | F22: 302389138 | G22: 0 | H22: 302389138 | I22: 0 | J22: 302389138 | K22: 0 | L22: 0 | M22: 0 | O22: Monetaria | P22: =+J22-K22+L22-M22 -> 302389138 | Q22: =P22/$Q$8 -> 334853.15 | V22: =U22-P22 -> -302389138 | X22: 1.1.01.501 | Y22: =EXACT(X22,D22) -> TRUE
A23: SANTANDER CH INV | B23: Caja y Bancos | C23: 112094 | D23: 1.1.01.502 | E23: INVERIOSN FONDO MUTUO USD | F23: 324679550 | G23: 144084902 | H23: 180594648 | I23: 0 | J23: 180594648 | K23: 0 | L23: 0 | M23: 0 | O23: Monetaria | P23: =+J23-K23+L23-M23 -> 180594648 | Q23: =P23/$Q$8 -> 199983 | V23: =U23-P23 -> -180594648 | X23: 1.1.01.502 | Y23: =EXACT(X23,D23) -> TRUE
A24: SANTANDER CH INV | B24: Caja y Bancos | C24: 112094 | D24: 1.1.02.106 | E24: DEPOSITO A PLAZO CORREDORA | F24: 4970977 | G24: 0 | H24: 4970977 | I24: 0 | J24: 4970977 | K24: 0 | L24: 0 | M24: 0 | O24: Monetaria | P24: =+J24-K24+L24-M24 -> 4970977 | Q24: =P24/$Q$8 -> 5504.6531 | V24: =U24-P24 -> -4970977 | X24: 1.1.02.106 | Y24: =EXACT(X24,D24) -> TRUE
A25: DEPOSITOS GARANTIA | B25: Derechos de arrendamiento | C25: 170013 | D25: 1.1.03.201 | E25: GASTOS PAGADOS POR ANTICIPADO | F25: 54550224 | G25: 26359837 | H25: 28190387 | I25: 0 | J25: 28190387 | K25: 0 | L25: 0 | M25: 0 | O25: Monetaria | P25: =+J25-K25+L25-M25 -> 28190387 | Q25: =P25/$Q$8 -> 31216.862 | V25: =U25-P25 -> -28190387 | X25: 1.1.03.201 | Y25: =EXACT(X25,D25) -> TRUE
A26: DEUDORES DIVERSOS | B26: Deudores Diversos | C26: 115010 | D26: 1.1.04.102 | E26: CLIENTES BOLETAS | F26: 1254176241 | G26: 1254176241 | H26: 0 | I26: 0 | J26: 0 | K26: 0 | L26: 0 | M26: 0 | O26: Monetaria | P26: =+J26-K26+L26-M26 -> 0 | Q26: =P26/$Q$8 -> 0 | V26: =U26-P26 -> 0 | X26: 1.1.04.102 | Y26: =EXACT(X26,D26) -> TRUE
A27: ANTICIPOS PROVEEDORE | B27: Pagos anticipados | C27: 115061 | D27: 1.1.04.104 | E27: FONDOS POR RENDIR | F27: 11021221 | G27: 8392663 | H27: 2628558 | I27: 0 | J27: 2628558 | K27: 0 | L27: 0 | M27: 0 | O27: Monetaria | P27: =+J27-K27+L27-M27 -> 2628558 | Q27: =P27/$Q$8 -> 2910.7558 | V27: =U27-P27 -> -2628558 | X27: 1.1.04.104 | Y27: =EXACT(X27,D27) -> TRUE
A28: DEUDORES DIVERSOS | B28: Deudores Diversos | C28: 115010 | D28: 1.1.04.105 | E28: TRANSBANK POR COBRAR TC | F28: 675298550 | G28: 675836139 | H28: 0 | I28: 537589 | J28: 0 | K28: 537589 | L28: 0 | M28: 0 | O28: Monetaria | P28: =+J28-K28+L28-M28 -> -537589 | Q28: =P28/$Q$8 -> -595.30369 | V28: =U28-P28 -> 537589 | X28: 1.1.04.105 | Y28: =EXACT(X28,D28) -> TRUE
A29: DEUDORES DIVERSOS | B29: Deudores Diversos | C29: 115010 | D29: 1.1.04.106 | E29: TRANSBANK POR COBRAR TD | F29: 732267924 | G29: 692327810 | H29: 39940114 | I29: 0 | J29: 39940114 | K29: 0 | L29: 0 | M29: 0 | O29: Monetaria | P29: =+J29-K29+L29-M29 -> 39940114 | Q29: =P29/$Q$8 -> 44228.021 | V29: =U29-P29 -> -39940114 | X29: 1.1.04.106 | Y29: =EXACT(X29,D29) -> TRUE
A30: DEUDORES DIVERSOS | B30: Deudores Diversos | C30: 115010 | D30: 1.1.04.108 | E30: GIFTCARD | F30: 585390 | G30: 104990 | H30: 480400 | I30: 0 | J30: 480400 | K30: 0 | L30: 0 | M30: 0 | O30: Monetaria | P30: =+J30-K30+L30-M30 -> 480400 | Q30: =P30/$Q$8 -> 531.97497 | V30: =U30-P30 -> -480400 | X30: 1.1.04.108 | Y30: =EXACT(X30,D30) -> TRUE
A31: DEUDORES DIVERSOS | B31: Deudores Diversos | C31: 115010 | D31: 1.1.04.109 | E31: ECOMMERCE | F31: 1371322273 | G31: 1083308831 | H31: 288013442 | I31: 0 | J31: 288013442 | K31: 0 | L31: 0 | M31: 0 | O31: Monetaria | P31: =+J31-K31+L31-M31 -> 288013442 | Q31: =P31/$Q$8 -> 318934.1 | V31: =U31-P31 -> -288013442 | X31: 1.1.04.109 | Y31: =EXACT(X31,D31) -> TRUE
... A33: DEUDORES DIVERSOS | B33: Deudores Diversos | C33: 115010 | D33: 1.1.04.113 | E33: GETNET TD/ PREPAGO | F33: 89987722 | G33: 88445522 | H33: 1542200 | I33: 0 | J33: 1542200 | K33: 0 | L33: 0 | M33: 0 | O33: Monetaria | P33: =+J33-K33+L33-M33 -> 1542200 | Q33: =P33/$Q$8 -> 1707.7681 | V33: =U33-P33 -> -1542200 | X33: 1.1.04.113 | Y33: =EXACT(X33,D33) -> TRUE
A34: DEUDORES DIVERSOS | B34: Deudores Diversos | C34: 115010 | D34: 1.1.04.200 | E34: CUENTAS POR COBRAR | F34: 6734121 | G34: 0 | H34: 6734121 | I34: 0 | J34: 6734121 | K34: 0 | L34: 0 | M34: 0 | O34: Monetaria | P34: =+J34-K34+L34-M34 -> 6734121 | Q34: =P34/$Q$8 -> 7457.0854 | X34: 1.1.04.200 | Y34: =EXACT(X34,D34) -> TRUE
A35: ANTICIPOS PROVEEDORE | B35: Pagos anticipados | C35: 115061 | D35: 1.1.05.403 | E35: ANTICIPO PROVEEDORES | F35: 288303448 | G35: 54409745 | H35: 233893703 | I35: 0 | J35: 233893703 | K35: 0 | L35: 0 | M35: 0 | O35: Monetaria | P35: =+J35-K35+L35-M35 -> 233893703 | Q35: =P35/$Q$8 -> 259004.16 | V35: =U35-P35 -> -233893703 | X35: 1.1.05.403 | Y35: =EXACT(X35,D35) -> TRUE
A36: ANTICIPOS PROVEEDORE | B36: Pagos anticipados | C36: 115061 | D36: 1.1.05.404 | E36: ANTICIPO HONORARIOS | F36: 100000 | G36: 20000 | H36: 80000 | I36: 0 | J36: 80000 | K36: 0 | L36: 0 | M36: 0 | O36: Monetaria | P36: =+J36-K36+L36-M36 -> 80000 | Q36: =P36/$Q$8 -> 88.588672 | V36: =U36-P36 -> -80000 | X36: 1.1.05.404 | Y36: =EXACT(X36,D36) -> TRUE
A37: ANTICIPOS PARA GASTOS | B37: Pagos anticipados | C37: 115055 | D37: 1.1.05.405 | E37: ANTICIPO AGENCIA DE ADUANAS | F37: 183281799 | G37: 181910308 | H37: 1371491 | I37: 0 | J37: 1371491 | K37: 0 | L37: 0 | M37: 0 | O37: Monetaria | P37: =+J37-K37+L37-M37 -> 1371491 | Q37: =P37/$Q$8 -> 1518.7321 | V37: =U37-P37 -> -1371491 | X37: 1.1.05.405 | Y37: =EXACT(X37,D37) -> TRUE
A38: INV PROD TERMINADO | B38: Inventarios | C38: 116050 | D38: 1.1.06.401 | E38: EXISTENCIAS NACIONALES | F38: 2012343198 | G38: 534509537 | H38: 1477833661 | I38: 0 | J38: 1477833661 | K38: 0 | L38: 0 | M38: 0 | O38: NO Monetario | P38: =+J38-K38+L38-M38 -> 1477833661 | Q38: =P38/$Q$8 -> 1636491.5 | V38: =U38-P38 -> -1477833661 | X38: 1.1.06.401 | Y38: =EXACT(X38,D38) -> TRUE
A39: INVENTARIO TRANSITO | B39: Inventarios | C39: 116072 | D39: 1.1.06.801 | E39: MERCADERIA EN TRANSITO | F39: 35497364 | G39: 35497364 | H39: 0 | I39: 0 | J39: 0 | K39: 0 | L39: 0 | M39: 0 | O39: Monetaria | P39: =+J39-K39+L39-M39 -> 0 | Q39: =P39/$Q$8 -> 0 | V39: =U39-P39 -> 0 | X39: 1.1.06.801 | Y39: =EXACT(X39,D39) -> TRUE
A40: INVENTARIO TRANSITO | B40: Inventarios | C40: 116072 | D40: 1.1.06.802 | E40: MERCADERIA EN TRANSITO USD | F40: 835086075 | G40: 561260345 | H40: 273825730 | I40: 0 | J40: 273825730 | K40: 0 | L40: 0 | M40: 0 | O40: Monetaria | P40: =+J40-K40+L40-M40 -> 273825730 | Q40: =P40/$Q$8 -> 303223.22 | V40: =U40-P40 -> -273825730 | X40: 1.1.06.802 | Y40: =EXACT(X40,D40) -> TRUE
A41: IVA A FAVOR | B41: Impuestos a favor | C41: 115082 | D41: 1.1.09.101 | E41: IVA CREDITO FISCAL (COMPRAS) | F41: 262722387 | G41: 262722387 | H41: 0 | I41: 0 | J41: 0 | K41: 0 | L41: 0 | M41: 0 | O41: Monetaria | P41: =+J41-K41+L41-M41 -> 0 | Q41: =P41/$Q$8 -> 0 | V41: =U41-P41 -> 0 | X41: 1.1.09.101 | Y41: =EXACT(X41,D41) -> TRUE
A42: IVA A FAVOR | B42: Impuestos a favor | C42: 115082 | D42: 1.1.09.103 | E42: REMANENTE IVA CREDITO FISCAL | F42: 456135707 | G42: 99687425 | H42: 356448282 | I42: 0 | J42: 356448282 | K42: 0 | L42: 0 | M42: 0 | O42: Monetaria | P42: =+J42-K42+L42-M42 -> 356448282 | Q42: =P42/$Q$8 -> 394716 | V42: =U42-P42 -> -356448282 | X42: 1.1.09.103 | Y42: =EXACT(X42,D42) -> TRUE
A43: DERECHOS ARRENDAMIEN | B43: Derechos de arrendamiento | C43: 141195 | D43: 1.2.02.101 | E43: GARANTIAS DE ARRIENDO | F43: 83146237 | G43: 25817865 | H43: 57328372 | I43: 0 | J43: 57328372 | K43: 0 | L43: 0 | M43: 0 | O43: Monetaria | P43: =+J43-K43+L43-M43 -> 57328372 | Q43: =P43/$Q$8 -> 63483.054 | V43: =U43-P43 -> -57328372 | X43: 1.2.02.101 | Y43: =EXACT(X43,D43) -> TRUE
A44: MOB Y EQ OFNA | B44: Equipo de tiendas | C44: 141080 | D44: 1.2.02.401 | E44: MUEBLES, UTILES Y OTROS | F44: 749360787 | G44: 0 | H44: 749360787 | I44: 0 | J44: 749360787 | K44: 0 | L44: 0 | M44: 0 | O44: NO Monetario | P44: =+J44-K44+L44-M44 -> 749360787 | Q44: =P44/$Q$8 -> 829810.96 | V44: =U44-P44 -> -749360787 | X44: 1.2.02.401 | Y44: =EXACT(X44,D44) -> TRUE
...

Sheet Balance
C1: Valor | D1: Cuenta México | E1: Registro SAP | F1: 903.05 | H1: Monetarias | I1: TC cierre | J1: No monetarias | K1: TC Historico transaccional
A2: 1.1.01.101 | B2: EFECTIVO EN TRANSITO | C2: =VLOOKUP(A2,BCE!$D$9:$P$131,13) -> 84410436 | D2: =SUMIF('Balanza ok'!D:D,A2,'Balanza ok'!B:B) -> 111100 | E2: 40 | F2: =C2/$F$1 -> 93472.605
A3: 1.1.01.203 | B3: FONDO FIJO PLAZA EGAÑA | C3: =VLOOKUP(A3,BCE!$D$9:$P$131,13) -> 37420 | D3: =SUMIF('Balanza ok'!D:D,A3,'Balanza ok'!B:B) -> 111100 | E3: 40 | F3: =C3/$F$1 -> 41.437351
A4: 1.1.01.204 | B4: FONDO FIJO VESPUCIO | C4: =VLOOKUP(A4,BCE!$D$9:$P$131,13) -> -126774 | D4: =SUMIF('Balanza ok'!D:D,A4,'Balanza ok'!B:B) -> 111100 | E4: 50 | F4: =C4/$F$1 -> -140.38425
A5: 1.1.01.205 | B5: FONDO FIJO TREBOL | C5: =VLOOKUP(A5,BCE!$D$9:$P$131,13) -> 32350 | D5: =SUMIF('Balanza ok'!D:D,A5,'Balanza ok'!B:B) -> 111100 | E5: 40 | F5: =C5/$F$1 -> 35.823044
A6: 1.1.01.206 | B6: FONDO FIJO COSTANERA CENTER | C6: =VLOOKUP(A6,BCE!$D$9:$P$131,13) -> 44970 | D6: =SUMIF('Balanza ok'!D:D,A6,'Balanza ok'!B:B) -> 111100 | E6: 40 | F6: =C6/$F$1 -> 49.797907
A7: 1.1.01.207 | B7: FONDO FIJO FLORIDA CENTER | C7: =VLOOKUP(A7,BCE!$D$9:$P$131,13) -> 32860 | D7: =SUMIF('Balanza ok'!D:D,A7,'Balanza ok'!B:B) -> 111100 | E7: 40 | F7: =C7/$F$1 -> 36.387797
A8: 1.1.01.208 | B8: FONDO FIJO SANTIAGO CENTRO | C8: =VLOOKUP(A8,BCE!$D$9:$P$131,13) -> 11360 | D8: =SUMIF('Balanza ok'!D:D,A8,'Balanza ok'!B:B) -> 111100 | E8: 40 | F8: =C8/$F$1 -> 12.579591
A9: 1.1.01.209 | B9: FONDO FIJO CONCEPCION CENTRO | C9: =VLOOKUP(A9,BCE!$D$9:$P$131,13) -> 0 | D9: =SUMIF('Balanza ok'!D:D,A9,'Balanza ok'!B:B) -> 111100 | E9: 40 | F9: =C9/$F$1 -> 0
A10: 1.1.01.210 | B10: FONDO FIJO TALCA | C10: =VLOOKUP(A10,BCE!$D$9:$P$131,13) -> 38022 | D10: =SUMIF('Balanza ok'!D:D,A10,'Balanza ok'!B:B) -> 111100 | E10: 40 | F10: =C10/$F$1 -> 42.103981
A11: 1.1.01.211 | B11: FONDO FIJO PLAZA NORTE | C11: =VLOOKUP(A11,BCE!$D$9:$P$131,13) -> 36120 | D11: =SUMIF('Balanza ok'!D:D,A11,'Balanza ok'!B:B) -> 111100 | E11: 40 | F11: =C11/$F$1 -> 39.997785
A12: 1.1.01.212 | B12: FONDO FIJO PLAZA OESTE | C12: =VLOOKUP(A12,BCE!$D$9:$P$131,13) -> 41598 | D12: =SUMIF('Balanza ok'!D:D,A12,'Balanza ok'!B:B) -> 111100 | E12: 40 | F12: =C12/$F$1 -> 46.063895
A13: 1.1.01.301 | B13: BANCOS CTA CTE $ | C13: =VLOOKUP(A13,BCE!$D$9:$P$131,13) -> 213813817 | D13: =SUMIF('Balanza ok'!D:D,A13,'Balanza ok'!B:B) -> 112093 | E13: 40 | F13: =C13/$F$1 -> 236768.53
... A41: 1.2.02.905 | B41: DEPRECIACION ACUMULADA EQUIPOS COMPUTACIONALES | C41: =VLOOKUP(A41,BCE!$D$9:$P$131,13) -> -41292706 | D41: =SUMIF('Balanza ok'!D:D,A41,'Balanza ok'!B:B) -> 142070 | E41: 50 | F41: =C41/$F$1 -> -45725.825
A42: 2.1.01.203 | B42: PRESTAMOS NO BANCARIOS MONTO A | C42: =VLOOKUP(A42,BCE!$D$9:$P$131,13) -> -153102751 | D42: =SUMIF('Balanza ok'!D:D,A42,'Balanza ok'!B:B) -> 224000 | E42: 50 | F42: =C42/$F$1 -> -169539.62 | G42: S17 | H42: Grupo Flexi de León S.A.P.I de CV
A43: 2.1.01.204 | B43: CUENTAS POR PAGAR | C43: =VLOOKUP(A43,BCE!$D$9:$P$131,13) -> -3101856 | D43: =SUMIF('Balanza ok'!D:D,A43,'Balanza ok'!B:B) -> 224000 | E43: 50 | F43: =C43/$F$1 -> -3434.8663
A44: 2.1.01.601 | B44: TARJETA CREDITO CLP | C44: =VLOOKUP(A44,BCE!$D$9:$P$131,13) -> 0 | D44: =SUMIF('Balanza ok'!D:D,A44,'Balanza ok'!B:B) -> 224000 | E44: 50 | F44: =C44/$F$1 -> 0
A45: 2.1.02.102 | B45: PROVEEDORES US$ | C45: =VLOOKUP(A45,BCE!$D$9:$P$131,13) -> -1542217800 | D45: =SUMIF('Balanza ok'!D:D,A45,'Balanza ok'!B:B) -> 210020 | E45: 50 | F45: =C45/$F$1 -> -1707787.8 | G45: S07 y S87 | H45: Alyc-Distrib Flexi - Qli
A46: 2.1.02.103 | B46: PROVEEDORES $ | C46: =VLOOKUP(A46,BCE!$D$9:$P$131,13) -> -16895791 | D46: =SUMIF('Balanza ok'!D:D,A46,'Balanza ok'!B:B) -> 210010 | E46: 50 | F46: =C46/$F$1 -> -18709.696
A47: 2.1.02.401 | B47: HONORARIOS POR PAGAR | C47: =VLOOKUP(A47,BCE!$D$9:$P$131,13) -> -2728385 | D47: =SUMIF('Balanza ok'!D:D,A47,'Balanza ok'!B:B) -> 210030 | E47: 50 | F47: =C47/$F$1 -> -3021.3
A48: 2.1.02.503 | B48: PREVIRED POR PAGAR | C48: =VLOOKUP(A48,BCE!$D$9:$P$131,13) -> -9447850 | D48: =SUMIF('Balanza ok'!D:D,A48,'Balanza ok'!B:B) -> 226030 | E48: 50 | F48: =C48/$F$1 -> -10462.156
A49: 2.1.02.604 | B49: ACREEDORES VARIOS | C49: =VLOOKUP(A49,BCE!$D$9:$P$131,13) -> -31127797 | D49: =SUMIF('Balanza ok'!D:D,A49,'Balanza ok'!B:B) -> 228050 | E49: 50 | F49: =C49/$F$1 -> -34469.627
A50: 2.1.02.605 | B50: PROVISIONES VARIAS | C50: =VLOOKUP(A50,BCE!$D$9:$P$131,13) -> -45893120 | D50: =SUMIF('Balanza ok'!D:D,A50,'Balanza ok'!B:B) -> 228050 | E50: 50 | F50: =C50/$F$1 -> -50820.132
A51: 2.1.05.101 | B51: IMPUESTO ÚNICO TRABAJADORES | C51: =VLOOKUP(A51,BCE!$D$9:$P$131,13) -> 0 | D51: =SUMIF('Balanza ok'!D:D,A51,'Balanza ok'!B:B) -> 227010 | E51: 50 | F51: =C51/$F$1 -> 0
A52: 2.1.05.102 | B52: RETENCION DE HONORARIOS | C52: =VLOOKUP(A52,BCE!$D$9:$P$131,13) -> 0 | D52: =SUMIF('Balanza ok'!D:D,A52,'Balanza ok'!B:B) -> 227050 | E52: 50 | F52: =C52/$F$1 -> 0
A53: 2.1.05.103 | B53: IVA DEBITO FISCAL (VENTAS) | C53: =VLOOKUP(A53,BCE!$D$9:$P$131,13) -> 0 | D53: =SUMIF('Balanza ok'!D:D,A53,'Balanza ok'!B:B) -> 226050 | E53: 50 | F53: =C53/$F$1 -> 0
A54: 2.1.05.106 | B54: IMPUESTO POR PAGAR FORM. 29 | C54: =VLOOKUP(A54,BCE!$D$9:$P$131,13) -> -3873394 | D54: =SUMIF('Balanza ok'!D:D,A54,'Balanza ok'!B:B) -> 226060 | E54: 50 | F54: =C54/$F$1 -> -4289.2354
A55: 2.1.06.103 | B55: SUELDOS POR PAGAR | C55: =VLOOKUP(A55,BCE!$D$9:$P$131,13) -> -11500335 | D55: =SUMIF('Balanza ok'!D:D,A55,'Balanza ok'!B:B) -> 228011 | E55: 50 | F55: =C55/$F$1 -> -12734.993
A56: 2.3.01.101 | B56: CAPITAL | C56: =VLOOKUP(A56,BCE!$D$9:$P$131,13) -> -5770668867 | D56: =SUMIF('Balanza ok'!D:D,A56,'Balanza ok'!B:B) -> 310100 | E56: 50 | F56: =C56/$F$1 -> -6390198.6
A57: 2.3.02.101 | B57: RESULTADOS ACUMULADOS | C57: =VLOOKUP(A57,BCE!$D$9:$P$131,13) -> 3154549713 | D57: =SUMIF('Balanza ok'!D:D,A57,'Balanza ok'!B:B) -> 340100 | E57: 40 | F57: =C57/$F$1 -> 3493217.1
C59: =SUM(C2:C58) -> -277482731 | F59: =C59/$F$1 -> -307272.83
C60: =EXACT(C59,BCE!L130) -> TRUE

Sheet Resultados
C1: HMARKETPLAZ | E1: HEGAÑA | F1: HVESPUCIO | G1: TREBOL | H1: HONLINE | J1: HCOSTANERA | K1: HFLORIDA | L1: HDEPARTAME | M1: HSANTIAGO CENTRO | N1: HMAULE TALCA | R1: Valor transaccional | S1: Tipo de cambio transaccional | U1: HDOMINICOS | V1: HMAIPU | W1: HEGAÑA | X1: HVESPUCIO | Y1: HTREBOL | Z1: HONLINE | AA1: HDEPARTAME | AB1: HCOSTANERA | AC1: HFLORIDA | AD1: HDEPARTAME | AE1: HSANTIAGO | AF1: HCONCEPCIO | AG1: HMAULETALC | AH1: HNORTE | AI1: HOESTE
C2: FLEXI
A3: Cuenta México | B3: N° CUENTA | C3: NOMBRE CUENTA | D3: CEDIS CHILE | E3: EGAÑA | F3: VESPUCIO | G3: TREBOL | H3: ONLINE | I3: ADMINISTRACION | J3: COSTANERA CENTER | K3: FLORIDA CENTER | L3: DEPARTAMENTALES | M3: SANTIAGO CENTRO | N3: TALCA | O3: PLAZA NORTE | P3: PLAZA OESTE | Q3: TOTAL | T3: CEDIS CHILE | U3: DOMINICOS | V3: MAIPU | W3: EGAÑA | X3: VESPUCIO | Y3: TREBOL | Z3: ONLINE | AA3: ADMINISTRACION | AB3: COSTANERA CENTER | AC3: FLORIDA CENTER | AD3: DEPARTAMENTALES | AE3: SANTIAGO CENTRO | AF3: CONCEPCION CENTRO | AG3: TALCA | AH3: PLAZA NORTE | AI3: PLAZA OESTE | AJ3: TOTAL
A5: =SUMIF('Balanza ok'!D:D,B5,'Balanza ok'!B:B) -> 0 | B5: 3.1.01.101 | C5: VENTAS CON BOLETA | D5: =SUM(D6:D7) -> 0 | E5: =SUM(E6:E7) -> 98849734 | F5: =SUM(F6:F7) -> 23271304 | G5: =SUM(G6:G7) -> 68376719 | H5: =SUM(H6:H7) -> 128312918 | I5: =SUM(I6:I7) -> 0 | J5: =SUM(J6:J7) -> 1.3888742e+08 | K5: =SUM(K6:K7) -> 57892370 | ... Q5: =SUM(Q6:Q7) -> 7.8920614e+08 | R5: =Q5/S5 -> 873934.04 | S5: 903.05 | T5: =IFERROR((D5/#REF!),0) -> 0 | V5: =+V6+V7 -> 0 | W5: =+W6+W7 -> 109462.08 | X5: =+X6+X7 -> 25769.674 | Y5: =+Y6+Y7 -> 75717.534 | Z5: =+Z6+Z7 -> 142088.39 | AA5: =+AA6+AA7 -> 0 | AB5: =+AB6+AB7 -> 153798.15 | AC5: =+AC6+AC7 -> 64107.602 | ... AJ5: =+AJ6+AJ7 -> 873934.04 | AK5: =+AJ5 -> 873934.04
A6: 510060 | B6: ACC | C6: ACCESORIOS | E6: 1460319.3 | F6: 176722.69 | G6: 1900809.2 | H6: 267353 | J6: 3361368.1 | K6: 1122858.8 | M6: 1530563.9 | N6: 770665.55 | O6: 1330168.9 | P6: 1282000.8 | Q6: =SUM(D6:P6) -> 13202830 | R6: =Q6/S6 -> 14620.265 | S6: =+S5 -> 903.05 | T6: =IFERROR((D6/$S$5),0) -> 0 | U6: =IFERROR((#REF!/$S$5),0) -> 0 | V6: =IFERROR((#REF!/$S$5),0) -> 0 | W6: =IFERROR((E6/$S$5),0) -> 1617.0969 | X6: =IFERROR((F6/$S$5),0) -> 195.69535 | Y6: =IFERROR((G6/$S$5),0) -> 2104.8771 | Z6: =IFERROR((H6/$S$5),0) -> 296.05559 | AA6: =IFERROR((I6/$S$5),0) -> 0 | AB6: =IFERROR((J6/$S$5),0) -> 3722.2392 | AC6: =IFERROR((K6/$S$5),0) -> 1243.4071 | AD6: =IFERROR((L6/$S$5),0) -> 0 | AE6: =IFERROR((M6/$S$5),0) -> 1694.8827 | AF6: =IFERROR((#REF!/$S$5),0) -> 0 | AG6: =IFERROR((N6/$S$5),0) -> 853.40296 | AH6: =IFERROR((O6/$S$5),0) -> 1472.9737 | AI6: =IFERROR((P6/$S$5),0) -> 1419.6344 | AJ6: =SUM(T6:AI6) -> 14620.265
A7: 510020 | B7: CAL | C7: CALZADO | E7: 97389415 | F7: 23094582 | G7: 66475910 | H7: 128045565 | J7: 1.3552605e+08 | K7: 56769511 | M7: 1.0555948e+08 | N7: 51282706 | O7: 46624103 | P7: 65235983 | Q7: =SUM(D7:P7) -> 7.7600331e+08 | R7: =Q7/S7 -> 859313.78 | S7: =+S6 -> 903.05 | T7: =IFERROR((D7/$S$5),0) -> 0 | U7: =IFERROR((#REF!/$S$5),0) -> 0 | V7: =IFERROR((#REF!/$S$5),0) -> 0 | W7: =IFERROR((E7/$S$5),0) -> 107844.99 | X7: =IFERROR((F7/$S$5),0) -> 25573.979 | Y7: =IFERROR((G7/$S$5),0) -> 73612.657 | Z7: =IFERROR((H7/$S$5),0) -> 141792.33 | AA7: =IFERROR((I7/$S$5),0) -> 0 | AB7: =IFERROR((J7/$S$5),0) -> 150075.91 | AC7: =IFERROR((K7/$S$5),0) -> 62864.195 | AD7: =IFERROR((L7/$S$5),0) -> 0 | AE7: =IFERROR((M7/$S$5),0) -> 116892.18 | AF7: =IFERROR((#REF!/$S$5),0) -> 0 | AG7: =IFERROR((N7/$S$5),0) -> 56788.335 | AH7: =IFERROR((O7/$S$5),0) -> 51629.591 | AI7: =IFERROR((P7/$S$5),0) -> 72239.614 | AJ7: =SUM(T7:AI7) -> 859313.78
A8: =SUMIF('Balanza ok'!D:D,B8,'Balanza ok'!B:B) -> 610000 | B8: 3.1.02.101 | C8: COSTO DE VENTAS | E8: -52077833 | F8: -11212926 | G8: -33973126 | H8: -83073137 | J8: -73387032 | K8: -29634483 | M8: -56640704 | N8: -27289574 | O8: -24878624 | P8: -34956397 | Q8: =SUM(D8:P8) -> -427123836 | R8: =Q8/S8 -> -472979.17 | S8: =+S7 -> 903.05 | T8: =IFERROR((D8/$S$8),0) -> 0 | U8: =IFERROR((#REF!/$S$8),0) -> 0 | V8: =IFERROR((#REF!/$S$8),0) -> 0 | W8: =IFERROR((E8/$S$8),0) -> -57668.826 | X8: =IFERROR((F8/$S$8),0) -> -12416.728 | Y8: =IFERROR((G8/$S$8),0) -> -37620.426 | Z8: =IFERROR((H8/$S$8),0) -> -91991.736 | AA8: =IFERROR((I8/$S$8),0) -> 0 | AB8: =IFERROR((J8/$S$8),0) -> -81265.746 | AC8: =IFERROR((K8/$S$8),0) -> -32815.994 | AD8: =IFERROR((L8/$S$8),0) -> 0 | AE8: =IFERROR((M8/$S$8),0) -> -62721.559 | AF8: =IFERROR((#REF!/$S$8),0) -> 0 | AG8: =IFERROR((N8/$S$8),0) -> -30219.339 | AH8: =IFERROR((O8/$S$8),0) -> -27549.553 | AI8: =IFERROR((P8/$S$8),0) -> -38709.26 | AJ8: =SUM(T8:AI8) -> -472979.17 | AK8: =+AJ8 -> -472979.17
B9: Resultado por Centro de Beneficio | D9: =+D5+D8 -> 0 | E9: =+E5+E8 -> 46771901 | F9: =+F5+F8 -> 12058378 | G9: =+G5+G8 -> 34403593 | H9: =+H5+H8 -> 45239781 | I9: =+I5+I8 -> 0 | J9: =+J5+J8 -> 65500388 | K9: =+K5+K8 -> 28257887 | ... R9: =+R5+R8 -> 400954.88 | T9: =SUM(T6:T8) -> 0 | U9: =SUM(U6:U8) -> 0 | V9: =SUM(V6:V8) -> 0 | W9: =SUM(W6:W8) -> 51793.257 | X9: =SUM(X6:X8) -> 13352.946 | Y9: =SUM(Y6:Y8) -> 38097.108 | Z9: =SUM(Z6:Z8) -> 50096.651 | AA9: =SUM(AA6:AA8) -> 0 | ... AJ9: =SUM(AJ6:AJ8) -> 400954.88 | AK9: =SUM(AK5:AK8) -> 400954.88
AD10: C89004570 | AE10: C89004630 | AF10: C89004620 | AG10: C89004640 | AH10: C89004660 | AI10: C89004650
C11: TAMARIS
A12: Cuenta México | B12: N° CUENTA | C12: NOMBRE CUENTA | D12: CEDIS CHILE | E12: EGAÑA | F12: VESPUCIO | G12: TREBOL | H12: ONLINE | I12: ADMINISTRACION | J12: COSTANERA CENTER | K12: FLORIDA CENTER | L12: DEPARTAMENTALES | M12: SANTIAGO CENTRO | N12: TALCA | O12: PLAZA NORTE | P12: PLAZA OESTE | Q12: TOTAL | T12: CEDIS CHILE | U12: DOMINICOS | V12: MAIPU | W12: EGAÑA | X12: VESPUCIO | Y12: TREBOL | Z12: ONLINE | AA12: ADMINISTRACION | AB12: COSTANERA CENTER | AC12: FLORIDA CENTER | AD12: DEPARTAMENTALES | AE12: SANTIAGO CENTRO | AF12: CONCEPCION CENTRO | AG12: TALCA | AH12: PLAZA NORTE | AI12: PLAZA OESTE | AJ12: TOTAL
A14: =SUMIF('Balanza ok'!D:D,B14,'Balanza ok'!B:B) -> 0 | B14: 3.1.01.101 | C14: VENTAS CON BOLETA | D14: =SUM(D15:D16) -> 0 | E14: =SUM(E15:E16) -> 20188230 | F14: =SUM(F15:F16) -> 9144942.9 | G14: =SUM(G15:G16) -> 18738756 | H14: =SUM(H15:H16) -> 4629941.2 | I14: =SUM(I15:I16) -> 0 | J14: =SUM(J15:J16) -> 47691077 | K14: =SUM(K15:K16) -> 10781589 | ... Q14: =SUM(Q15:Q16) -> 1.7763436e+08 | R14: =Q14/S14 -> 203847.05 | S14: 871.41 | T14: =IFERROR((D14/#REF!),0) -> 0 | V14: =+V15+V16 -> 0 | W14: =+W15+W16 -> 22355.606 | X14: =+X15+X16 -> 10126.729 | Y14: =+Y15+Y16 -> 20750.519 | Z14: =+Z15+Z16 -> 5127.0042 | AA14: =+AA15+AA16 -> 0 | AB14: =+AB15+AB16 -> 52811.115 | AC14: =+AC15+AC16 -> 11939.083 | ... AJ14: =+AJ15+AJ16 -> 196704.9 | AK14: =+AJ14 -> 196704.9
A15: 510060 | B15: ACC | C15: ACCESORIOS | Q15: =SUM(D15:P15) -> 0 | R15: =Q15/S15 -> 0 | S15: =+S14 -> 871.41 | T15: =IFERROR((D15/$S$5),0) -> 0 | U15: =IFERROR((#REF!/$S$5),0) -> 0 | V15: =IFERROR((#REF!/$S$5),0) -> 0 | W15: =IFERROR((E15/$S$5),0) -> 0 | X15: =IFERROR((F15/$S$5),0) -> 0 | Y15: =IFERROR((G15/$S$5),0) -> 0 | Z15: =IFERROR((H15/$S$5),0) -> 0 | AA15: =IFERROR((I15/$S$5),0) -> 0 | AB15: =IFERROR((J15/$S$5),0) -> 0 | AC15: =IFERROR((K15/$S$5),0) -> 0 | AD15: =IFERROR((L15/$S$5),0) -> 0 | AE15: =IFERROR((M15/$S$5),0) -> 0 | AF15: =IFERROR((#REF!/$S$5),0) -> 0 | AG15: =IFERROR((N15/$S$5),0) -> 0 | AH15: =IFERROR((O15/$S$5),0) -> 0 | AI15: =IFERROR((P15/$S$5),0) -> 0 | AJ15: =SUM(T15:AI15) -> 0
A16: 510020 | B16: CAL | C16: CALZADO | E16: 20188230 | F16: 9144942.9 | G16: 18738756 | H16: 4629941.2 | J16: 47691077 | K16: 10781589 | M16: 21770211 | N16: 10644697 | O16: 11782568 | P16: 22262344 | Q16: =SUM(D16:P16) -> 1.7763436e+08 | R16: =Q16/S16 -> 203847.05 | S16: =+S15 -> 871.41 | T16: =IFERROR((D16/$S$5),0) -> 0 | U16: =IFERROR((#REF!/$S$5),0) -> 0 | V16: =IFERROR((#REF!/$S$5),0) -> 0 | W16: =IFERROR((E16/$S$5),0) -> 22355.606 | X16: =IFERROR((F16/$S$5),0) -> 10126.729 | Y16: =IFERROR((G16/$S$5),0) -> 20750.519 | Z16: =IFERROR((H16/$S$5),0) -> 5127.0042 | AA16: =IFERROR((I16/$S$5),0) -> 0 | AB16: =IFERROR((J16/$S$5),0) -> 52811.115 | AC16: =IFERROR((K16/$S$5),0) -> 11939.083 | AD16: =IFERROR((L16/$S$5),0) -> 0 | AE16: =IFERROR((M16/$S$5),0) -> 24107.426 | AF16: =IFERROR((#REF!/$S$5),0) -> 0 | AG16: =IFERROR((N16/$S$5),0) -> 11787.494 | AH16: =IFERROR((O16/$S$5),0) -> 13047.526 | AI16: =IFERROR((P16/$S$5),0) -> 24652.393 | AJ16: =SUM(T16:AI16) -> 196704.9
A17: =SUMIF('Balanza ok'!D:D,B17,'Balanza ok'!B:B) -> 610000 | B17: 3.1.02.101 | C17: COSTO DE VENTAS | E17: -8579160 | F17: -3710766 | G17: -7603450 | H17: -2079036 | J17: -20233730 | K17: -4493616 | M17: -9071392 | N17: -4524686 | O17: -5028056 | P17: -9210647 | Q17: =SUM(D17:P17) -> -74534539 | R17: =Q17/S17 -> -85533.261 | S17: =+S16 -> 871.41 | T17: =IFERROR((D17/$S$8),0) -> 0 | U17: =IFERROR((#REF!/$S$8),0) -> 0 | V17: =IFERROR((#REF!/$S$8),0) -> 0 | W17: =IFERROR((E17/$S$8),0) -> -9500.2049 | X17: =IFERROR((F17/$S$8),0) -> -4109.1479 | Y17: =IFERROR((G17/$S$8),0) -> -8419.7442 | Z17: =IFERROR((H17/$S$8),0) -> -2302.238 | AA17: =IFERROR((I17/$S$8),0) -> 0 | AB17: =IFERROR((J17/$S$8),0) -> -22405.991 | AC17: =IFERROR((K17/$S$8),0) -> -4976.0434 | AD17: =IFERROR((L17/$S$8),0) -> 0 | AE17: =IFERROR((M17/$S$8),0) -> -10045.282 | AF17: =IFERROR((#REF!/$S$8),0) -> 0 | AG17: =IFERROR((N17/$S$8),0) -> -5010.449 | AH17: =IFERROR((O17/$S$8),0) -> -5567.86 | AI17: =IFERROR((P17/$S$8),0) -> -10199.487 | AJ17: =SUM(T17:AI17) -> -82536.448 | AK17: =+AJ17 -> -82536.448
B18: Resultado por Centro de Beneficio | D18: =+D14+D17 -> 0 | E18: =+E14+E17 -> 11609070 | F18: =+F14+F17 -> 5434176.9 | G18: =+G14+G17 -> 11135306 | H18: =+H14+H17 -> 2550905.2 | I18: =+I14+I17 -> 0 | J18: =+J14+J17 -> 27457347 | K18: =+K14+K17 -> 6287973.1 | ... R18: =+R14+R17 -> 118313.79 | T18: =SUM(T15:T17) -> 0 | U18: =SUM(U15:U17) -> 0 | V18: =SUM(V15:V17) -> 0 | W18: =SUM(W15:W17) -> 12855.401 | X18: =SUM(X15:X17) -> 6017.5814 | Y18: =SUM(Y15:Y17) -> 12330.775 | Z18: =SUM(Z15:Z17) -> 2824.7663 | AA18: =SUM(AA15:AA17) -> 0 | ... AJ18: =SUM(AJ15:AJ17) -> 114168.45 | AK18: =SUM(AK14:AK17) -> 114168.45
D20: C89004120 | E20: C89004530 | F20: C89004540 | G20: C89004550 | H20: C89004560 | I20: C89005070 | J20: C89004580 | K20: C89004590 | M20: C89004610 | N20: C89004640 | T20: C89004120 | U20: C89004510 | V20: C89004520 | W20: C89004530 | X20: C89004540 | Y20: C89004550 | Z20: C89004560 | AA20: C89005070 | AB20: C89004580 | AC20: C89004590 | AD20: C89004570 | AE20: C89004630 | AF20: C89004620 | AG20: C89004640 | AH20: C89004660 | AI20: C89004650
B21: N° CUENTA | C21: NOMBRE CUENTA | D21: CEDIS CHILE | E21: EGAÑA | F21: VESPUCIO | G21: TREBOL | H21: ONLINE | I21: ADMINISTRACION | J21: COSTANERA CENTER | K21: FLORIDA CENTER | L21: DEPARTAMENTALES | M21: SANTIAGO CENTRO | N21: TALCA | O21: PLAZA NORTE | P21: PLAZA OESTE | Q21: TOTAL | T21: CEDIS CHILE | U21: DOMINICOS | V21: MAIPU | W21: EGAÑA | X21: VESPUCIO | Y21: TREBOL | Z21: ONLINE | AA21: ADMINISTRACION | AB21: COSTANERA CENTER | AC21: FLORIDA CENTER | AD21: DEPARTAMENTALES | AE21: SANTIAGO CENTRO | AF21: CONCEPCION CENTRO | AG21: TALCA | AH21: PLAZA NORTE | AI21: PLAZA OESTE | AJ21: TOTAL
AK22: =-AK9 -> -400954.88
A23: =SUMIF('Balanza ok'!D:D,B23,'Balanza ok'!B:B) -> 570500 | B23: 3.1.01.300 | C23: OTROS INGRESOS | D23: 0 | E23: 0 | F23: 0 | G23: 0 | H23: 10765435 | I23: 0 | J23: 0 | K23: 0 | L23: 0 | M23: 0 | N23: 0 | O23: 0 | P23: 0 | Q23: =SUM(D23:P23) -> 10765435 | R23: =Q23/S23 -> 11921.195 | S23: =+S8 -> 903.05 | T23: =IFERROR((D23/$S23),0) -> 0 | U23: =IFERROR((#REF!/$S23),0) -> 0 | V23: =IFERROR((#REF!/$S23),0) -> 0 | W23: =IFERROR((E23/$S23),0) -> 0 | X23: =IFERROR((F23/$S23),0) -> 0 | Y23: =IFERROR((G23/$S23),0) -> 0 | Z23: =IFERROR((H23/$S23),0) -> 11921.195 | AA23: =IFERROR((I23/$S23),0) -> 0 | AB23: =IFERROR((J23/$S23),0) -> 0 | AC23: =IFERROR((K23/$S23),0) -> 0 | AD23: =IFERROR((L23/$S23),0) -> 0 | AE23: =IFERROR((M23/$S23),0) -> 0 | AF23: =IFERROR((#REF!/$S23),0) -> 0 | AG23: =IFERROR((N23/$S23),0) -> 0 | AH23: =IFERROR((O23/$S23),0) -> 0 | AI23: =IFERROR((P23/$S23),0) -> 0 | AJ23: =SUM(T23:AI23) -> 11921.195 | AK23: =+AJ23 -> 11921.195 | AL23: =+R23-AJ23 -> 0 | AN23: 3.1.01.300 | AO23: =EXACT(B23,AN23) -> TRUE
A24: =SUMIF('Balanza ok'!D:D,B24,'Balanza ok'!B:B) -> 708130 | B24: 3.1.02.102 | C24: COSTOS OPERATIVOS - FLETES INTERNOS | D24: -9366599 | E24: -311388 | F24: -108593 | G24: -311388 | H24: 150000 | I24: 0 | J24: -311388 | K24: -311388 | L24: 0 | M24: -311388 | N24: -311388 | O24: -311388 | P24: -311388 | Q24: =SUM(D24:P24) -> -11816296 | R24: =Q24/S24 -> -13084.875 | S24: =+S23 -> 903.05 | T24: =IFERROR((D24/$S24),0) -> -10372.182 | U24: =IFERROR((#REF!/$S24),0) -> 0 | V24: =IFERROR((#REF!/$S24),0) -> 0 | W24: =IFERROR((E24/$S24),0) -> -344.81812 | X24: =IFERROR((F24/$S24),0) -> -120.25137 | Y24: =IFERROR((G24/$S24),0) -> -344.81812 | Z24: =IFERROR((H24/$S24),0) -> 166.10376 | AA24: =IFERROR((I24/$S24),0) -> 0 | AB24: =IFERROR((J24/$S24),0) -> -344.81812 | AC24: =IFERROR((K24/$S24),0) -> -344.81812 | AD24: =IFERROR((L24/$S24),0) -> 0 | AE24: =IFERROR((M24/$S24),0) -> -344.81812 | AF24: =IFERROR((#REF!/$S24),0) -> 0 | AG24: =IFERROR((N24/$S24),0) -> -344.81812 | AH24: =IFERROR((O24/$S24),0) -> -344.81812 | AI24: =IFERROR((P24/$S24),0) -> -344.81812 | AJ24: =SUM(T24:AI24) -> -13084.875 | AK24: =+AJ24 -> -13084.875 | AL24: =+R24-AJ24 -> 0 | AN24: 3.1.02.102 | AO24: =EXACT(B24,AN24) -> TRUE
A25: =SUMIF('Balanza ok'!D:D,B25,'Balanza ok'!B:B) -> 709226 | B25: 3.1.02.104 | C25: COMISIÓN - CANAL DIGITAL | D25: 0 | E25: 0 | F25: 0 | G25: 0 | H25: -4702554 | I25: 0 | J25: 0 | K25: 0 | L25: -7242837 | M25: 0 | N25: 0 | O25: 0 | P25: 0 | Q25: =SUM(D25:P25) -> -11945391 | R25: =Q25/S25 -> -13227.829 | S25: =+S24 -> 903.05 | T25: =IFERROR((D25/$S25),0) -> 0 | U25: =IFERROR((#REF!/$S25),0) -> 0 | V25: =IFERROR((#REF!/$S25),0) -> 0 | W25: =IFERROR((E25/$S25),0) -> 0 | X25: =IFERROR((F25/$S25),0) -> 0 | Y25: =IFERROR((G25/$S25),0) -> 0 | Z25: =IFERROR((H25/$S25),0) -> -5207.4127 | AA25: =IFERROR((I25/$S25),0) -> 0 | AB25: =IFERROR((J25/$S25),0) -> 0 | AC25: =IFERROR((K25/$S25),0) -> 0 | AD25: =IFERROR((L25/$S25),0) -> -8020.4164 | AE25: =IFERROR((M25/$S25),0) -> 0 | AF25: =IFERROR((#REF!/$S25),0) -> 0 | AG25: =IFERROR((N25/$S25),0) -> 0 | AH25: =IFERROR((O25/$S25),0) -> 0 | AI25: =IFERROR((P25/$S25),0) -> 0 | AJ25: =SUM(T25:AI25) -> -13227.829 | AK25: =+AJ25 -> -13227.829 | AL25: =+R25-AJ25 -> 0 | AN25: 3.1.02.104 | AO25: =EXACT(B25,AN25) -> TRUE
A26: =SUMIF('Balanza ok'!D:D,B26,'Balanza ok'!B:B) -> 708130 | B26: 3.1.02.105 | C26: FLETES - CANAL DIGITAL | D26: 0 | E26: 0 | F26: 0 | G26: 0 | H26: -14363756 | I26: 0 | J26: 0 | K26: 0 | L26: -2866174 | M26: 0 | N26: 0 | O26: 0 | P26: 0 | Q26: =SUM(D26:P26) -> -17229930 | R26: =Q26/S26 -> -19079.708 | S26: =+S25 -> 903.05 | T26: =IFERROR((D26/$S26),0) -> 0 | U26: =IFERROR((#REF!/$S26),0) -> 0 | V26: =IFERROR((#REF!/$S26),0) -> 0 | W26: =IFERROR((E26/$S26),0) -> 0 | X26: =IFERROR((F26/$S26),0) -> 0 | Y26: =IFERROR((G26/$S26),0) -> 0 | Z26: =IFERROR((H26/$S26),0) -> -15905.826 | AA26: =IFERROR((I26/$S26),0) -> 0 | AB26: =IFERROR((J26/$S26),0) -> 0 | AC26: =IFERROR((K26/$S26),0) -> 0 | AD26: =IFERROR((L26/$S26),0) -> -3173.8818 | AE26: =IFERROR((M26/$S26),0) -> 0 | AF26: =IFERROR((#REF!/$S26),0) -> 0 | AG26: =IFERROR((N26/$S26),0) -> 0 | AH26: =IFERROR((O26/$S26),0) -> 0 | AI26: =IFERROR((P26/$S26),0) -> 0 | AJ26: =SUM(T26:AI26) -> -19079.708 | AK26: =+AJ26 -> -19079.708 | AL26: =+R26-AJ26 -> 0 | AN26: 3.1.02.105 | AO26: =EXACT(B26,AN26) -> TRUE
A27: =SUMIF('Balanza ok'!D:D,B27,'Balanza ok'!B:B) -> 709226 | B27: 3.1.02.108 | C27: SERVICIOS - CANAL DIGITAL | D27: 0 | E27: 0 | F27: 0 | G27: 0 | H27: -222925 | I27: 0 | J27: 0 | K27: 0 | L27: -8258503 | M27: 0 | N27: 0 | O27: 0 | P27: 0 | Q27: =SUM(D27:P27) -> -8481428 | R27: =Q27/S27 -> -9391.9805 | S27: =+S26 -> 903.05 | T27: =IFERROR((D27/$S27),0) -> 0 | U27: =IFERROR((#REF!/$S27),0) -> 0 | V27: =IFERROR((#REF!/$S27),0) -> 0 | W27: =IFERROR((E27/$S27),0) -> 0 | X27: =IFERROR((F27/$S27),0) -> 0 | Y27: =IFERROR((G27/$S27),0) -> 0 | Z27: =IFERROR((H27/$S27),0) -> -246.85787 | AA27: =IFERROR((I27/$S27),0) -> 0 | AB27: =IFERROR((J27/$S27),0) -> 0 | AC27: =IFERROR((K27/$S27),0) -> 0 | AD27: =IFERROR((L27/$S27),0) -> -9145.1226 | AE27: =IFERROR((M27/$S27),0) -> 0 | AF27: =IFERROR((#REF!/$S27),0) -> 0 | AG27: =IFERROR((N27/$S27),0) -> 0 | AH27: =IFERROR((O27/$S27),0) -> 0 | AI27: =IFERROR((P27/$S27),0) -> 0 | AJ27: =SUM(T27:AI27) -> -9391.9805 | AK27: =+AJ27 -> -9391.9805 | AL27: =+R27-AJ27 -> 0 | AN27: 3.1.02.108 | AO27: =EXACT(B27,AN27) -> TRUE
A28: =SUMIF('Balanza ok'!D:D,B28,'Balanza ok'!B:B) -> 720716 | B28: 3.1.02.109 | C28: DESCUENTOS GIFTCARD | D28: 0 | E28: 0 | F28: 0 | G28: 0 | H28: 0 | I28: 0 | J28: -60000 | K28: 0 | L28: 0 | M28: -44990 | N28: 0 | O28: 0 | P28: 0 | Q28: =SUM(D28:P28) -> -104990 | R28: =Q28/S28 -> -116.26156 | S28: =+S27 -> 903.05 | AJ28: =SUM(T28:AI28) -> 0 | AK28: =+AJ28 -> 0 | AN28: 3.1.02.109 | AO28: =EXACT(B28,AN28) -> TRUE
A29: =SUMIF('Balanza ok'!D:D,B29,'Balanza ok'!B:B) -> 720716 | B29: 3.1.02.110 | C29: DESCUENTOS CLUB FLEXI | D29: 0 | E29: -10120 | F29: -10776 | G29: -5696 | H29: 0 | I29: 0 | J29: -18330 | K29: -100966 | L29: 0 | M29: -32386 | N29: 0 | O29: 0 | P29: 0 | Q29: =SUM(D29:P29) -> -178274 | R29: =Q29/S29 -> -197.41321 | S29: =+S28 -> 903.05 | AJ29: =SUM(T29:AI29) -> 0 | AK29: =+AJ29 -> 0 | AN29: 3.1.02.110 | AO29: =EXACT(B29,AN29) -> TRUE
A30: =SUMIF('Balanza ok'!D:D,B30,'Balanza ok'!B:B) -> 701011 | B30: 3.1.05.101 | C30: REMUNERACIONES | D30: 0 | E30: -19605284 | F30: -4340553 | G30: -19777384 | H30: -13430862 | I30: -1005381 | J30: -23788136 | K30: -15596068 | L30: -5733292 | M30: -21549622 | N30: -15454865 | O30: -15892636 | P30: -16884316 | Q30: =SUM(D30:P30) -> -173058399 | R30: =Q30/S30 -> -191637.67 | S30: =+S29 -> 903.05 | T30: =IFERROR((D30/$S30),0) -> 0 | U30: =IFERROR((#REF!/$S30),0) -> 0 | V30: =IFERROR((#REF!/$S30),0) -> 0 | W30: =IFERROR((E30/$S30),0) -> -21710.076 | X30: =IFERROR((F30/$S30),0) -> -4806.5478 | Y30: =IFERROR((G30/$S30),0) -> -21900.652 | Z30: =IFERROR((H30/$S30),0) -> -14872.778 | AA30: =IFERROR((I30/$S30),0) -> -1113.3171 | AB30: =IFERROR((J30/$S30),0) -> -26341.992 | AC30: =IFERROR((K30/$S30),0) -> -17270.437 | AD30: =IFERROR((L30/$S30),0) -> -6348.809 | AE30: =IFERROR((M30/$S30),0) -> -23863.155 | AF30: =IFERROR((#REF!/$S30),0) -> 0 | AG30: =IFERROR((N30/$S30),0) -> -17114.075 | AH30: =IFERROR((O30/$S30),0) -> -17598.844 | AI30: =IFERROR((P30/$S30),0) -> -18696.989 | AJ30: =SUM(T30:AI30) -> -191637.67 | AK30: =+AJ30 -> -191637.67 | AL30: =+R30-AJ30 -> 0 | AN30: 3.1.05.101 | AO30: =EXACT(B30,AN30) -> TRUE
A31: =SUMIF('Balanza ok'!D:D,B31,'Balanza ok'!B:B) -> 701025 | B31: 3.1.05.102 | C31: BONOS | D31: 0 | E31: -718846 | F31: -8666 | G31: -387944 | H31: -945271 | I31: -20000 | J31: -635071 | K31: -404590 | L31: 0 | M31: -1518574 | N31: -367293 | O31: 323240 | P31: -953000 | Q31: =SUM(D31:P31) -> -5636015 | R31: =Q31/S31 -> -6241.0885 | S31: =+S30 -> 903.05 | T31: =IFERROR((D31/$S31),0) -> 0 | U31: =IFERROR((#REF!/$S31),0) -> 0 | V31: =IFERROR((#REF!/$S31),0) -> 0 | W31: =IFERROR((E31/$S31),0) -> -796.02015 | X31: =IFERROR((F31/$S31),0) -> -9.5963679 | Y31: =IFERROR((G31/$S31),0) -> -429.59305 | Z31: =IFERROR((H31/$S31),0) -> -1046.7538 | AA31: =IFERROR((I31/$S31),0) -> -22.147168 | AB31: =IFERROR((J31/$S31),0) -> -703.2512 | AC31: =IFERROR((K31/$S31),0) -> -448.02613 | AD31: =IFERROR((L31/$S31),0) -> 0 | AE31: =IFERROR((M31/$S31),0) -> -1681.6057 | AF31: =IFERROR((#REF!/$S31),0) -> 0 | AG31: =IFERROR((N31/$S31),0) -> -406.72499 | AH31: =IFERROR((O31/$S31),0) -> 357.94253 | AI31: =IFERROR((P31/$S31),0) -> -1055.3126 | AJ31: =SUM(T31:AI31) -> -6241.0885 | AK31: =+AJ31 -> -6241.0885 | AL31: =+R31-AJ31 -> 0 | AN31: 3.1.05.102 | AO31: =EXACT(B31,AN31) -> TRUE
A32: =SUMIF('Balanza ok'!D:D,B32,'Balanza ok'!B:B) -> 702059 | B32: 3.1.05.103 | C32: SEGURO DE CESANTIA | D32: 0 | E32: -692642 | F32: -176477 | G32: -718791 | H32: -379112 | I32: -81064 | J32: -866143 | K32: -554933 | L32: -140387 | M32: -804251 | N32: -555974 | O32: -564822 | P32: -613548 | Q32: =SUM(D32:P32) -> -6148144 | R32: =Q32/S32 -> -6808.1989 | S32: =+S31 -> 903.05 | T32: =IFERROR((D32/$S32),0) -> 0 | U32: =IFERROR((#REF!/$S32),0) -> 0 | V32: =IFERROR((#REF!/$S32),0) -> 0 | W32: =IFERROR((E32/$S32),0) -> -767.00293 | X32: =IFERROR((F32/$S32),0) -> -195.42329 | Y32: =IFERROR((G32/$S32),0) -> -795.95925 | Z32: =IFERROR((H32/$S32),0) -> -419.81286 | AA32: =IFERROR((I32/$S32),0) -> -89.766901 | AB32: =IFERROR((J32/$S32),0) -> -959.13072 | AC32: =IFERROR((K32/$S32),0) -> -614.50972 | AD32: =IFERROR((L32/$S32),0) -> -155.45872 | AE32: =IFERROR((M32/$S32),0) -> -890.5941 | AF32: =IFERROR((#REF!/$S32),0) -> 0 | AG32: =IFERROR((N32/$S32),0) -> -615.66248 | AH32: =IFERROR((O32/$S32),0) -> -625.46038 | AI32: =IFERROR((P32/$S32),0) -> -679.41753 | AJ32: =SUM(T32:AI32) -> -6808.1989 | AK32: =+AJ32 -> -6808.1989 | AL32: =+R32-AJ32 -> 0 | AN32: 3.1.05.103 | AO32: =EXACT(B32,AN32) -> TRUE
A33: =SUMIF('Balanza ok'!D:D,B33,'Balanza ok'!B:B) -> 701025 | B33: 3.1.05.104 | C33: GRATIFICACION | D33: 0 | E33: -4698748 | F33: -1339662 | G33: -4820799 | H33: -1839436 | I33: -305874 | J33: -5574494 | K33: -3913639 | L33: -591154 | M33: -5185749 | N33: -3973103 | O33: -3973505 | P33: -4093878 | Q33: =SUM(D33:P33) -> -40310041 | R33: =Q33/S33 -> -44637.662 | S33: =+S32 -> 903.05 | T33: =IFERROR((D33/$S33),0) -> 0 | U33: =IFERROR((#REF!/$S33),0) -> 0 | V33: =IFERROR((#REF!/$S33),0) -> 0 | W33: =IFERROR((E33/$S33),0) -> -5203.1981 | X33: =IFERROR((F33/$S33),0) -> -1483.486 | Y33: =IFERROR((G33/$S33),0) -> -5338.3523 | Z33: =IFERROR((H33/$S33),0) -> -2036.9149 | AA33: =IFERROR((I33/$S33),0) -> -338.71214 | AB33: =IFERROR((J33/$S33),0) -> -6172.9627 | AC33: =IFERROR((K33/$S33),0) -> -4333.801 | AD33: =IFERROR((L33/$S33),0) -> -654.61935 | AE33: =IFERROR((M33/$S33),0) -> -5742.4827 | AF33: =IFERROR((#REF!/$S33),0) -> 0 | AG33: =IFERROR((N33/$S33),0) -> -4399.649 | AH33: =IFERROR((O33/$S33),0) -> -4400.0941 | AI33: =IFERROR((P33/$S33),0) -> -4533.3902 | AJ33: =SUM(T33:AI33) -> -44637.662 | AK33: =+AJ33 -> -44637.662 | AL33: =+R33-AJ33 -> 0 | AN33: 3.1.05.104 | AO33: =EXACT(B33,AN33) -> TRUE
A34: =SUMIF('Balanza ok'!D:D,B34,'Balanza ok'!B:B) -> 701026 | B34: 3.1.05.107 | C34: FINIQUITOS | D34: 0 | E34: -701842 | F34: 0 | G34: -90809 | H34: 0 | I34: -1279325 | J34: 0 | K34: -59888 | L34: 0 | M34: 0 | N34: -86412 | O34: -105208 | P34: -502172 | Q34: =SUM(D34:P34) -> -2825656 | R34: =Q34/S34 -> -3129.0139 | S34: =+S33 -> 903.05 | T34: =IFERROR((D34/$S34),0) -> 0 | U34: =IFERROR((#REF!/$S34),0) -> 0 | V34: =IFERROR((#REF!/$S34),0) -> 0 | W34: =IFERROR((E34/$S34),0) -> -777.19063 | X34: =IFERROR((F34/$S34),0) -> 0 | Y34: =IFERROR((G34/$S34),0) -> -100.55811 | Z34: =IFERROR((H34/$S34),0) -> 0 | AA34: =IFERROR((I34/$S34),0) -> -1416.6713 | AB34: =IFERROR((J34/$S34),0) -> 0 | AC34: =IFERROR((K34/$S34),0) -> -66.31748 | AD34: =IFERROR((L34/$S34),0) -> 0 | AE34: =IFERROR((M34/$S34),0) -> 0 | AF34: =IFERROR((#REF!/$S34),0) -> 0 | AG34: =IFERROR((N34/$S34),0) -> -95.689054 | AH34: =IFERROR((O34/$S34),0) -> -116.50296 | AI34: =IFERROR((P34/$S34),0) -> -556.08438 | AJ34: =SUM(T34:AI34) -> -3129.0139 | AK34: =+AJ34 -> -3129.0139 | AL34: =+R34-AJ34 -> 0 | AN34: 3.1.05.107 | AO34: =EXACT(B34,AN34) -> TRUE
A35: =SUMIF('Balanza ok'!D:D,B35,'Balanza ok'!B:B) -> 702051 | B35: 3.1.05.110 | C35: MUTUAL DE SEGURIDAD | D35: 0 | E35: -260348 | F35: -65861 | G35: -257184 | H35: -141509 | I35: -15661 | J35: -323752 | K35: -200082 | L35: -48283 | M35: -300022 | N35: -204243 | O35: -202216 | P35: -220885 | Q35: =SUM(D35:P35) -> -2240046 | R35: =Q35/S35 -> -2480.5337 | S35: =+S34 -> 903.05 | T35: =IFERROR((D35/$S35),0) -> 0 | U35: =IFERROR((#REF!/$S35),0) -> 0 | V35: =IFERROR((#REF!/$S35),0) -> 0 | W35: =IFERROR((E35/$S35),0) -> -288.29854 | X35: =IFERROR((F35/$S35),0) -> -72.931731 | Y35: =IFERROR((G35/$S35),0) -> -284.79486 | Z35: =IFERROR((H35/$S35),0) -> -156.70118 | AA35: =IFERROR((I35/$S35),0) -> -17.34234 | AB35: =IFERROR((J35/$S35),0) -> -358.5095 | AC35: =IFERROR((K35/$S35),0) -> -221.56248 | AD35: =IFERROR((L35/$S35),0) -> -53.466585 | AE35: =IFERROR((M35/$S35),0) -> -332.23188 | AF35: =IFERROR((#REF!/$S35),0) -> 0 | AG35: =IFERROR((N35/$S35),0) -> -226.1702 | AH35: =IFERROR((O35/$S35),0) -> -223.92559 | AI35: =IFERROR((P35/$S35),0) -> -244.59886 | AJ35: =SUM(T35:AI35) -> -2480.5337 | AK35: =+AJ35 -> -2480.5337 | AL35: =+R35-AJ35 -> 0 | AN35: 3.1.05.110 | AO35: =EXACT(B35,AN35) -> TRUE
A36: =SUMIF('Balanza ok'!D:D,B36,'Balanza ok'!B:B) -> 702052 | B36: 3.1.05.111 | C36: SEGURO INVALIDEZ (AFP) | D36: 0 | E36: -436142 | F36: -114723 | G36: -442491 | H36: -237394 | I36: -52016 | J36: -543253 | K36: -344879 | L36: -81001 | M36: -501846 | N36: -346669 | O36: -339584 | P36: -375381 | Q36: =SUM(D36:P36) -> -3815379 | R36: =Q36/S36 -> -4224.992 | S36: =+S35 -> 903.05 | T36: =IFERROR((D36/$S36),0) -> 0 | U36: =IFERROR((#REF!/$S36),0) -> 0 | V36: =IFERROR((#REF!/$S36),0) -> 0 | W36: =IFERROR((E36/$S36),0) -> -482.96551 | X36: =IFERROR((F36/$S36),0) -> -127.03948 | Y36: =IFERROR((G36/$S36),0) -> -489.99612 | Z36: =IFERROR((H36/$S36),0) -> -262.88024 | AA36: =IFERROR((I36/$S36),0) -> -57.600354 | AB36: =IFERROR((J36/$S36),0) -> -601.57577 | AC36: =IFERROR((K36/$S36),0) -> -381.90466 | AD36: =IFERROR((L36/$S36),0) -> -89.697137 | AE36: =IFERROR((M36/$S36),0) -> -555.72338 | AF36: =IFERROR((#REF!/$S36),0) -> 0 | AG36: =IFERROR((N36/$S36),0) -> -383.88683 | AH36: =IFERROR((O36/$S36),0) -> -376.04119 | AI36: =IFERROR((P36/$S36),0) -> -415.6813 | AJ36: =SUM(T36:AI36) -> -4224.992 | AK36: =+AJ36 -> -4224.992 | AL36: =+R36-AJ36 -> 0 | AN36: 3.1.05.111 | AO36: =EXACT(B36,AN36) -> TRUE
A37: =SUMIF('Balanza ok'!D:D,B37,'Balanza ok'!B:B) -> 702052 | B37: 3.1.05.112 | C37: CAPITALIZACION INDIVIDUAL AFP | D37: 0 | E37: -27997 | F37: -7083 | G37: -27627 | H37: -15218 | I37: -1628 | J37: -34812 | K37: -21494 | L37: -5192 | M37: -32261 | N37: -21952 | O37: -21744 | P37: -23739 | Q37: =SUM(D37:P37) -> -240747 | R37: =Q37/S37 -> -266.59321 | S37: =+S36 -> 903.05 | T37: =IFERROR((D37/$S37),0) -> 0 | U37: =IFERROR((#REF!/$S37),0) -> 0 | V37: =IFERROR((#REF!/$S37),0) -> 0 | W37: =IFERROR((E37/$S37),0) -> -31.002713 | X37: =IFERROR((F37/$S37),0) -> -7.8434195 | Y37: =IFERROR((G37/$S37),0) -> -30.59299 | Z37: =IFERROR((H37/$S37),0) -> -16.85178 | AA37: =IFERROR((I37/$S37),0) -> -1.8027795 | AB37: =IFERROR((J37/$S37),0) -> -38.549361 | AC37: =IFERROR((K37/$S37),0) -> -23.801561 | AD37: =IFERROR((L37/$S37),0) -> -5.7494048 | AE37: =IFERROR((M37/$S37),0) -> -35.724489 | AF37: =IFERROR((#REF!/$S37),0) -> 0 | AG37: =IFERROR((N37/$S37),0) -> -24.308732 | AH37: =IFERROR((O37/$S37),0) -> -24.078401 | AI37: =IFERROR((P37/$S37),0) -> -26.287581 | AJ37: =SUM(T37:AI37) -> -266.59321 | AK37: =+AJ37 -> -266.59321 | AL37: =+R37-AJ37 -> 0 | AN37: 3.1.05.112 | AO37: =EXACT(B37,AN37) -> TRUE
A38: =SUMIF('Balanza ok'!D:D,B38,'Balanza ok'!B:B) -> 702052 | B38: 3.1.05.113 | C38: EXPECTATIVA DE VIDA | D38: 0 | E38: -251947 | F38: -63734 | G38: -255509 | H38: -136944 | I38: -30400 | J38: -313308 | K38: -199693 | L38: -46727 | M38: -290346 | N38: -199937 | O38: -195701 | P38: -216739 | Q38: =SUM(D38:P38) -> -2200985 | R38: =Q38/S38 -> -2437.2792 | S38: =+S37 -> 903.05 | T38: =IFERROR((D38/$S38),0) -> 0 | U38: =IFERROR((#REF!/$S38),0) -> 0 | V38: =IFERROR((#REF!/$S38),0) -> 0 | W38: =IFERROR((E38/$S38),0) -> -278.99563 | X38: =IFERROR((F38/$S38),0) -> -70.57638 | Y38: =IFERROR((G38/$S38),0) -> -282.94004 | Z38: =IFERROR((H38/$S38),0) -> -151.64609 | AA38: =IFERROR((I38/$S38),0) -> -33.663695 | AB38: =IFERROR((J38/$S38),0) -> -346.94424 | AC38: =IFERROR((K38/$S38),0) -> -221.13172 | AD38: =IFERROR((L38/$S38),0) -> -51.743536 | AE38: =IFERROR((M38/$S38),0) -> -321.51708 | AF38: =IFERROR((#REF!/$S38),0) -> 0 | AG38: =IFERROR((N38/$S38),0) -> -221.40192 | AH38: =IFERROR((O38/$S38),0) -> -216.71115 | AI38: =IFERROR((P38/$S38),0) -> -240.00775 | AJ38: =SUM(T38:AI38) -> -2437.2792 | AK38: =+AJ38 -> -2437.2792 | AL38: =+R38-AJ38 -> 0 | AN38: 3.1.05.113 | AO38: =EXACT(B38,AN38) -> TRUE
A39: =SUMIF('Balanza ok'!D:D,B39,'Balanza ok'!B:B) -> 701004 | B39: 3.1.05.114 | C39: HORAS EXTRAS | D39: 0 | E39: 0 | F39: 0 | G39: 0 | H39: 0 | I39: 0 | J39: 0 | K39: 0 | L39: 0 | M39: 0 | N39: 0 | O39: 0 | P39: 0 | Q39: =SUM(D39:P39) -> 0 | R39: =Q39/S39 -> 0 | S39: =+S36 -> 903.05 | T39: =IFERROR((D39/$S39),0) -> 0 | U39: =IFERROR((#REF!/$S39),0) -> 0 | V39: =IFERROR((#REF!/$S39),0) -> 0 | W39: =IFERROR((E39/$S39),0) -> 0 | X39: =IFERROR((F39/$S39),0) -> 0 | Y39: =IFERROR((G39/$S39),0) -> 0 | Z39: =IFERROR((H39/$S39),0) -> 0 | AA39: =IFERROR((I39/$S39),0) -> 0 | AB39: =IFERROR((J39/$S39),0) -> 0 | AC39: =IFERROR((K39/$S39),0) -> 0 | AD39: =IFERROR((L39/$S39),0) -> 0 | AE39: =IFERROR((M39/$S39),0) -> 0 | AF39: =IFERROR((#REF!/$S39),0) -> 0 | AG39: =IFERROR((N39/$S39),0) -> 0 | AH39: =IFERROR((O39/$S39),0) -> 0 | AI39: =IFERROR((P39/$S39),0) -> 0 | AJ39: =SUM(T39:AI39) -> 0 | AK39: =+AJ39 -> 0 | AL39: =+R39-AJ39 -> 0 | AN39: 3.1.05.114 | AO39: =EXACT(B39,AN39) -> TRUE
A40: =SUMIF('Balanza ok'!D:D,B40,'Balanza ok'!B:B) -> 701028 | B40: 3.1.05.117 | C40: DOMINGOS Y FESTIVOS | D40: 0 | E40: -756319 | F40: -470770 | G40: -1034152 | H40: 0 | I40: -7718 | J40: -625126 | K40: -493923 | L40: 0 | M40: 0 | N40: -833493 | O40: -725449 | P40: -455337 | Q40: =SUM(D40:P40) -> -5402287 | R40: =Q40/S40 -> -5982.2679 | S40: =+S39 -> 903.05 | T40: =IFERROR((D40/$S40),0) -> 0 | U40: =IFERROR((#REF!/$S40),0) -> 0 | V40: =IFERROR((#REF!/$S40),0) -> 0 | W40: =IFERROR((E40/$S40),0) -> -837.5162 | X40: =IFERROR((F40/$S40),0) -> -521.31111 | Y40: =IFERROR((G40/$S40),0) -> -1145.1769 | Z40: =IFERROR((H40/$S40),0) -> 0 | AA40: =IFERROR((I40/$S40),0) -> -8.5465921 | AB40: =IFERROR((J40/$S40),0) -> -692.23852 | AC40: =IFERROR((K40/$S40),0) -> -546.94978 | AD40: =IFERROR((L40/$S40),0) -> 0 | AE40: =IFERROR((M40/$S40),0) -> 0 | AF40: =IFERROR((#REF!/$S40),0) -> 0 | AG40: =IFERROR((N40/$S40),0) -> -922.97547 | AH40: =IFERROR((O40/$S40),0) -> -803.33204 | AI40: =IFERROR((P40/$S40),0) -> -504.22125 | AJ40: =SUM(T40:AI40) -> -5982.2679 | AK40: =+AJ40 -> -5982.2679 | AL40: =+R40-AJ40 -> 0 | AN40: 3.1.05.117 | AO40: =EXACT(B40,AN40) -> TRUE
A41: =SUMIF('Balanza ok'!D:D,B41,'Balanza ok'!B:B) -> 701009 | B41: 3.1.05.121 | C41: SEMANA CORRIDA | D41: 0 | E41: -678344 | F41: -237589 | G41: -549134 | H41: 0 | I41: -80923 | J41: -1189945 | K41: -405019 | L41: 0 | M41: -1170652 | N41: -447565 | O41: -337145 | P41: -495606 | Q41: =SUM(D41:P41) -> -5591922 | R41: =Q41/S41 -> -6192.2618 | S41: =+S40 -> 903.05 | T41: =IFERROR((D41/$S41),0) -> 0 | U41: =IFERROR((#REF!/$S41),0) -> 0 | V41: =IFERROR((#REF!/$S41),0) -> 0 | W41: =IFERROR((E41/$S41),0) -> -751.16992 | X41: =IFERROR((F41/$S41),0) -> -263.09617 | Y41: =IFERROR((G41/$S41),0) -> -608.08815 | Z41: =IFERROR((H41/$S41),0) -> 0 | AA41: =IFERROR((I41/$S41),0) -> -89.610764 | AB41: =IFERROR((J41/$S41),0) -> -1317.6956 | AC41: =IFERROR((K41/$S41),0) -> -448.50119 | AD41: =IFERROR((L41/$S41),0) -> 0 | AE41: =IFERROR((M41/$S41),0) -> -1296.3313 | AF41: =IFERROR((#REF!/$S41),0) -> 0 | AG41: =IFERROR((N41/$S41),0) -> -495.61486 | AH41: =IFERROR((O41/$S41),0) -> -373.34035 | AI41: =IFERROR((P41/$S41),0) -> -548.81347 | AJ41: =SUM(T41:AI41) -> -6192.2618 | AK41: =+AJ41 -> -6192.2618 | AL41: =+R41-AJ41 -> 0 | AN41: 3.1.05.121 | AO41: =EXACT(B41,AN41) -> TRUE
A42: =SUMIF('Balanza ok'!D:D,B42,'Balanza ok'!B:B) -> 701013 | B42: 3.1.05.122 | C42: COMISION POR VENTA | D42: 0 | E42: -3028261 | F42: -989208 | G42: -2231239 | H42: 0 | I42: -360252 | J42: -5199117 | K42: -1779090 | L42: 0 | M42: -4443222 | N42: -1696561 | O42: -1452179 | P42: -2110592 | Q42: =SUM(D42:P42) -> -23289721 | R42: =Q42/S42 -> -25790.068 | S42: =+S41 -> 903.05 | T42: =IFERROR((D42/$S42),0) -> 0 | U42: =IFERROR((#REF!/$S42),0) -> 0 | V42: =IFERROR((#REF!/$S42),0) -> 0 | W42: =IFERROR((E42/$S42),0) -> -3353.3702 | X42: =IFERROR((F42/$S42),0) -> -1095.4078 | Y42: =IFERROR((G42/$S42),0) -> -2470.7812 | Z42: =IFERROR((H42/$S42),0) -> 0 | AA42: =IFERROR((I42/$S42),0) -> -398.92808 | AB42: =IFERROR((J42/$S42),0) -> -5757.2859 | AC42: =IFERROR((K42/$S42),0) -> -1970.0902 | AD42: =IFERROR((L42/$S42),0) -> 0 | AE42: =IFERROR((M42/$S42),0) -> -4920.2392 | AF42: =IFERROR((#REF!/$S42),0) -> 0 | AG42: =IFERROR((N42/$S42),0) -> -1878.7011 | AH42: =IFERROR((O42/$S42),0) -> -1608.0826 | AI42: =IFERROR((P42/$S42),0) -> -2337.1818 | AJ42: =SUM(T42:AI42) -> -25790.068 | AK42: =+AJ42 -> -25790.068 | AL42: =+R42-AJ42 -> 0 | AN42: 3.1.05.122 | AO42: =EXACT(B42,AN42) -> TRUE
A43: =SUMIF('Balanza ok'!D:D,B43,'Balanza ok'!B:B) -> 704083 | B43: 3.1.06.108 | C43: ASIGNACION COLACION | D43: 0 | E43: -1184946 | F43: -229140 | G43: -987223 | H43: -428691 | I43: -62000 | J43: -1290879 | K43: -843943 | L43: -278975 | M43: -1206733 | N43: -825957 | O43: -758701 | P43: -888978 | Q43: =SUM(D43:P43) -> -8986166 | R43: =Q43/S43 -> -9950.9064 | S43: =+S42 -> 903.05 | T43: =IFERROR((D43/$S43),0) -> 0 | U43: =IFERROR((#REF!/$S43),0) -> 0 | V43: =IFERROR((#REF!/$S43),0) -> 0 | W43: =IFERROR((E43/$S43),0) -> -1312.1599 | X43: =IFERROR((F43/$S43),0) -> -253.7401 | Y43: =IFERROR((G43/$S43),0) -> -1093.2097 | Z43: =IFERROR((H43/$S43),0) -> -474.71458 | AA43: =IFERROR((I43/$S43),0) -> -68.656221 | AB43: =IFERROR((J43/$S43),0) -> -1429.4657 | AC43: =IFERROR((K43/$S43),0) -> -934.54737 | AD43: =IFERROR((L43/$S43),0) -> -308.92531 | AE43: =IFERROR((M43/$S43),0) -> -1336.2859 | AF43: =IFERROR((#REF!/$S43),0) -> 0 | AG43: =IFERROR((N43/$S43),0) -> -914.63042 | AH43: =IFERROR((O43/$S43),0) -> -840.15392 | AI43: =IFERROR((P43/$S43),0) -> -984.41725 | AJ43: =SUM(T43:AI43) -> -9950.9064 | AK43: =+AJ43 -> -9950.9064 | AL43: =+R43-AJ43 -> 0 | AN43: 3.1.06.108 | AO43: =EXACT(B43,AN43) -> TRUE
...

Sheet errores advicom

Sheet Resultados (2)
E1: HDOMINICOS | F1: HMAIPU | G1: HEGAÑA | H1: HVESPUCIO | I1: TREBOL | J1: HONLINE | L1: HCOSTANERA | M1: HFLORIDA | N1: HDEPARTAME | P1: Valor transaccional | Q1: Tipo de cambio transaccional | S1: HDOMINICOS | T1: HMAIPU | U1: HEGAÑA | V1: HVESPUCIO | W1: TREBOL | X1: HONLINE | Z1: HCOSTANERA | AA1: HFLORIDA | AB1: HDEPARTAME
A2: Cuenta México | B2: N° CUENTA | C2: NOMBRE CUENTA | D2: CEDIS CHILE | E2: DOMINICOS | F2: MAIPU | G2: EGAÑA | H2: VESPUCIO | I2: TREBOL | J2: ONLINE | K2: ADMINISTRACION | L2: COSTANERA CENTER | M2: FLORIDA CENTER | N2: DEPARTAMENTALES | O2: TOTAL | R2: CEDIS CHILE | S2: DOMINICOS | T2: MAIPU | U2: EGAÑA | V2: VESPUCIO | W2: TREBOL | X2: ONLINE | Y2: ADMINISTRACION | Z2: COSTANERA CENTER | AA2: FLORIDA CENTER | AB2: DEPARTAMENTALES | AC2: TOTAL
C4: VENTAS CON BOLETA | D4: 0 | E4: =SUM(E5:E6) -> 90012219 | F4: =SUM(F5:F6) -> 78182140 | G4: =SUM(G5:G6) -> 170857429 | H4: =SUM(H5:H6) -> 163083860 | I4: =SUM(I5:I6) -> 164044512 | J4: =SUM(J5:J6) -> 303243729 | K4: 0 | L4: =SUM(L5:L6) -> 243702388 | M4: =SUM(M5:M6) -> 97315248 | N4: =SUM(N5:N6) -> 312262688 | O4: =SUM(O5:O6) -> 1622704213 | P4: 1965913 | Q4: =+O4/P4 -> 825.42015 | R4: =IFERROR((D4/#REF!),0) -> 0 | S4: =+S5+S6 -> 109050.18 | T4: =+T5+T6 -> 94717.992 | U4: =+U5+U6 -> 206994.5 | V4: =+V5+V6 -> 197576.78 | W4: =+W5+W6 -> 198740.62 | X4: =+X5+X6 -> 367381.06 | Y4: =+Y5+Y6 -> 0 | Z4: =+Z5+Z6 -> 295246.47 | ... AC4: =+AC5+AC6 -> 1965913 | AD4: =+AC4 -> 1965913
A5: =SUMIF(#REF!,B5,#REF!) -> #REF! | B5: ACC | C5: ACCESORIOS | D5: 0 | E5: 3149322 | F5: 2191640 | G5: 4147928 | H5: 5225041 | I5: 3489379 | J5: 246260 | K5: 0 | L5: 8296175 | M5: 2681586 | N5: 0 | O5: =SUM(E5:N5) -> 29427331 | R5: =IFERROR((D5/$Q$4),0) -> 0 | S5: =IFERROR((E5/$Q$4),0) -> 3815.4169 | T5: =IFERROR((F5/$Q$4),0) -> 2655.1811 | U5: =IFERROR((G5/$Q$4),0) -> 5025.2323 | V5: =IFERROR((H5/$Q$4),0) -> 6330.1592 | W5: =IFERROR((I5/$Q$4),0) -> 4227.3974 | X5: =IFERROR((J5/$Q$4),0) -> 298.34503 | Y5: =IFERROR((K5/$Q$4),0) -> 0 | ... AB5: =IFERROR((N5/$Q$4),0) -> 0 | AC5: =SUM(R5:AB5) -> 35651.336
A6: =SUMIF(#REF!,B6,#REF!) -> #REF! | B6: CAL | C6: CALZADO | D6: 0 | E6: 86862897 | F6: 75990500 | G6: 166709501 | H6: 157858819 | I6: 160555133 | J6: 302997469 | K6: 0 | L6: 235406213 | M6: 94633662 | N6: 312262688 | O6: =SUM(E6:N6) -> 1593276882 | R6: =IFERROR((D6/$Q$4),0) -> 0 | S6: =IFERROR((E6/$Q$4),0) -> 105234.77 | T6: =IFERROR((F6/$Q$4),0) -> 92062.811 | U6: =IFERROR((G6/$Q$4),0) -> 201969.26 | V6: =IFERROR((H6/$Q$4),0) -> 191246.63 | W6: =IFERROR((I6/$Q$4),0) -> 194513.22 | X6: =IFERROR((J6/$Q$4),0) -> 367082.71 | Y6: =IFERROR((K6/$Q$4),0) -> 0 | ... AB6: =IFERROR((N6/$Q$4),0) -> 378307.56 | AC6: =SUM(R6:AB6) -> 1930261.7
A7: =SUMIF(#REF!,B7,#REF!) -> #REF! | B7: 3102101 | C7: COSTO DE VENTAS | D7: 0 | E7: -41466377 | F7: -35801636 | G7: -77820870 | H7: -73786688 | I7: -72355485 | J7: -142815023 | K7: 0 | L7: -109503037 | M7: -43988496 | N7: -241355672 | O7: =SUM(D7:N7) -> -838893284 | P7: -1007913 | Q7: =+O7/P7 -> 832.30724 | R7: =IFERROR((D7/$Q$7),0) -> 0 | S7: =IFERROR((E7/$Q$7),0) -> -49820.998 | T7: =IFERROR((F7/$Q$7),0) -> -43014.928 | U7: =IFERROR((G7/$Q$7),0) -> -93500.172 | V7: =IFERROR((H7/$Q$7),0) -> -88653.186 | W7: =IFERROR((I7/$Q$7),0) -> -86933.625 | X7: =IFERROR((J7/$Q$7),0) -> -171589.31 | Y7: =IFERROR((K7/$Q$7),0) -> 0 | ... AB7: =IFERROR((N7/$Q$7),0) -> -289983.87 | AC7: =SUM(R7:AB7) -> -1007913 | AD7: =+AC7 -> -1007913
