Workbook

Sheet OCT
C1: RENDICION CAJA CHICA
C2: COSTANERA CENTER
G3: MES | H3: OCTUBRE
B4: SALDO ANTERIOR | E4: -89315
B5: DEPÓSITO RENDICION ANTERIOR | E5: 75545
B6: MONTO ADICIONAL | E6: 0
B7: MONTO A RENDIR | E7: =SUM(E4:E6) -> -13770
B8: RENDIDO | E8: =+G16 -> 44000 | G8: SALDO AL CIERRE | H8: =E7-E8 -> -57770
A10: N° | B10: Fecha | C10: Tipo Documento (boleta venta-boleta honorarios-factura) | D10: N° documento | E10: RUT Titular del documento | F10: Detalle | G10: Total | H10: Código Imputacion (RSM) 170
A11: 1 | B11: 45573 | C11: Boleta Venta | D11: 18262 | E11: 77.093.957-7 | F11: RECARGA AGUA POTABLE | G11: 7000
A12: 2 | B12: 45586 | C12: Boleta Venta | D12: 18403 | E12: 77.093.957-8 | F12: RECARGA AGUA POTABLE | G12: 7000
A13: 3 | B13: 45589 | C13: Boleta Honorarios | D13: 1068 | E13: 5.666.822-6 | F13: LIMPIEZA DE VIDIRIOS | G13: 30000
A14: 4
A15: 5
B16: TOTALES | G16: =SUM(G11:G15) -> 44000

Sheet NOV
C1: RENDICION CAJA CHICA
C2: COSTANERA CENTER
G3: MES | H3: NOVIEMBRE
B4: SALDO ANTERIOR | E4: =+OCT!$H$8 -> -57770
B5: DEPÓSITO RENDICION ANTERIOR | E5: 44000
B6: MONTO ADICIONAL | E6: 0
B7: MONTO A RENDIR | E7: =SUM(E4:E6) -> -13770
B8: RENDIDO | E8: =+G27 -> 23115 | G8: SALDO AL CIERRE | H8: =E7-E8 -> -36885
A10: N° | B10: Fecha | C10: Tipo Documento (boleta venta-boleta honorarios-factura) | D10: N° documento | E10: RUT Titular del documento | F10: Detalle | G10: Total | H10: Código Imputacion (RSM) 170
A11: 1 | B11: 45604 | C11: Boleta de venta | D11: 18640 | E11: 77093957-7 | F11: RECARGA AGUA 20LTS | G11: 7000
A12: 2 | B12: 45623 | C12: Boleta de venta | D12: 18881 | E12: 77093957-7 | F12: RECARGA AGUA 20LTS | G12: 7000
A13: 3 | B13: 45626 | C13: Boleta de venta | D13: 53151890 | E13: 80478200-1 | F13: ARCHIVADOR | G13: 3790
A14: 4 | B14: 45626 | C14: Boleta de venta | D14: 2930005733 | E14: 81201000-k | F14: BOLSAS PARA BASURA | G14: 1325
A15: 5 | B15: 45628 | C15: Boleta de venta | D15: 242754234 | E15: 76568660-1 | F15: TORNILLOS+TAPA TORNILLOS | G15: 4000
A16: 7
A17: 8
A18: 9
A19: 10
A20: 11
A21: 12
A22: 13
A23: 14
A24: 15
A25: 16
A26: 17
B27: TOTALES | G27: =SUM(G11:G26) -> 23115

Sheet DIC
C1: RENDICION CAJA CHICA
C2: COSTANERA CENTER
G3: MES | H3: DICIEMBRE
B4: SALDO ANTERIOR | E4: =+NOV!H8 -> -36885
B5: DEPÓSITO RENDICION ANTERIOR | E5: 23115
B6: MONTO ADICIONAL | E6: 49980
B7: MONTO A RENDIR | E7: =SUM(E4:E6) -> 36210
B8: RENDIDO | E8: =+G27 -> 45868 | G8: SALDO AL CIERRE | H8: =E7-E8 -> -9658
A10: N° | B10: Fecha | C10: Tipo Documento (boleta venta-boleta honorarios-factura) | D10: N° documento | E10: RUT Titular del documento | F10: Detalle | G10: Total | H10: Código Imputacion (RSM) 170
A11: 1 | B11: 45640 | C11: Boleta de venta | D11: 159790521 | E11: 77.115.570-7 | F11: Desayuno Recepción de Mercaderia | G11: 3980
A12: 2 | B12: 45643 | C12: Boleta de venta | D12: 19152 | E12: 77.093.957-7 | F12: Recarga Agua 20Lts | G12: 7000
A13: 3 | B13: 45645 | C13: Boleta de venta | D13: 39.193.934 | E13: 76.076.630-5 | F13: Desayuno Recepción de Mercaderia | G13: 4790
A14: 4 | B14: 45646 | C14: Boleta de venta | D14: 38.453.583 | E14: 76.076.630-5 | F14: Desayuno Recepción de Mercaderia | G14: 2990
A15: 5 | B15: 45647 | C15: Boleta de venta | D15: 15219130 | E15: 92.642.000-3 | F15: Cintas (ventas para regalo) | G15: 7560
A16: 7 | B16: 45648 | C16: Boleta de venta | D16: 160857037 | E16: 77.115.570-7 | F16: Desayuno Recepción de Mercaderia (4 personas)(llenado) | G16: 5190
A17: 8 | B17: 45648 | C17: Boleta de venta | D17: 2962352814 | E17: 81.201.000-k | G17: 7358
A18: 9 | B18: 45657 | C18: Boleta de venta | D18: 19308 | E18: 77.093.957-7 | F18: RECARGA AGUA 20LTS | G18: 7000
A19: 10
A20: 11
A21: 12
A22: 13
A23: 14
A24: 15
A25: 16
A26: 17
B27: TOTALES | G27: =SUM(G11:G26) -> 45868

Sheet historico
A1: 2022 | E1: 2740 | F1: 2740
A2: 2023
A3: MES | B3: DEBITO/PAGO RAUL | C3: CREDITOS/REND LOCAL | D3: SALDOS MES | E3: ACUMULADO
A5: ENERO | B5: 97260 | C5: 97260 | D5: =+B5-C5 -> 0 | E5: =E1+B5-C5 -> 2740
A6: FEBRERO | B6: 96190 | C6: =96190+86570 -> 182760 | D6: =+B6-C6 -> -86570 | E6: =E5+B6-C6 -> -83830
A7: MARZO | B7: 86570 | C7: 99500 | D7: =+B7-C7 -> -12930 | E7: =E6+B7-C7 -> -96760 | F7: -99500
A8: ABRIL | B8: 94630 | C8: 94630 | D8: =+B8-C8 -> 0 | E8: =E7+B8-C8 -> -96760
A9: MAYO | B9: 0 | C9: 87540 | D9: =+B9-C9 -> -87540 | E9: =E8+B9-C9 -> -184300
A10: JUNIO | B10: =87540+93730 -> 181270 | C10: 93730 | D10: =+B10-C10 -> 87540 | E10: =E9+B10-C10 -> -96760 | F10: -87540
A11: JULIO | B11: 0 | C11: =76510+66715 -> 143225 | D11: =+B11-C11 -> -143225 | E11: =E10+B11-C11 -> -239985 | F11: 181270
A12: AGOSTO | B12: 66715 | C12: 112980 | D12: =+B12-C12 -> -46265 | E12: =E11+B12-C12 -> -286250 | F12: -93730
A13: SEPTIEMBRE | B13: 276527 | C13: 83547 | D13: 192980 | E13: =E12+B13-C13 -> -93270 | F13: -143225
A14: OCTUBRE | B14: 183927 | C14: 91066 | D14: 92861 | E14: =E13+B14-C14 -> -409 | F14: 66715
A15: NOVIEMBRE | B15: 91066 | C15: 97878 | D15: -6812 | E15: =E14+B15-C15 -> -7221 | F15: -112980
A16: DICIEMBRE | B16: 97878 | C16: 65443 | D16: 32435 | E16: =E15+B16-C16 -> 25214 | F16: 276527
A17: 2024 | F17: -83547
A18: MES | B18: DEBITO/PAGO RAUL | C18: CREDITOS/REND LOCAL | D18: SALDOS MES | E18: ACUMULADO | F18: 183927
A20: ENERO | B20: =90657-25214 -> 65443 | C20: 75606 | D20: 15051 | E20: 15051
A21: FEBRERO | B21: 75606 | C21: 0 | D21: 75606 | E21: 90657
A22: MARZO | B22: 38000 | C22: 67057 | D22: -29057 | E22: 61600
A23: ABRIL | B23: 148301 | C23: 81244 | D23: 67057 | E23: 128657 | F23: -65443
A24: MAYO | B24: 105232 | C24: 0 | D24: 105232 | E24: 233889 | F24: 38000
A25: JUNIO | B25: 93908 | C25: 291587 | D25: -197679 | E25: 36210 | F25: 105232
A26: JULIO | B26: 0 | C26: 42070 | D26: -42070 | E26: -5860 | F26: 93908
A27: AGOSTO | B27: 42070 | C27: 50370 | D27: -8300 | E27: -14160 | F27: -291587
A28: SEPTIEMBRE | B28: 50370 | C28: 125525 | D28: -75155 | E28: -89315 | F28: -125525
A29: OCTUBRE | B29: 75545 | C29: 44000 | D29: 31545 | E29: -57770 | F29: 75545
A30: NOVIEMBRE | B30: 44000 | C30: 23115 | D30: 20885 | E30: -36885 | F30: 73095
A31: DICIEMBRE | B31: 73095 | C31: 45868 | D31: 27227 | E31: -9658 | F31: -23115
A32: 2025 | F32: -27240
A33: MES | B33: DEBITO/PAGO RAUL | C33: CREDITOS/REND LOCAL | D33: SALDOS MES | E33: ACUMULADO
A34: ENERO | B34: 45868 | C34: =36898-9658 -> 27240 | D34: =+B34-C34 -> 18628 | E34: =+E31+B34-C34 -> 8970
A35: FEBRERO | F35: =SUM(F1:F32) -> -56473
A36: MARZO
A37: ABRIL
A38: MAYO
A39: JUNIO
A40: JULIO
A41: AGOSTO
A42: SEPTIEMBRE
...

Sheet ENE 25
C1: RENDICION CAJA CHICA
C2: COSTANERA CENTER
G3: MES | H3: ENERO
B4: SALDO ANTERIOR | E4: =+DIC!H8 -> -9658
B5: DEPÓSITO RENDICION ANTERIOR | E5: 45868
B6: MONTO ADICIONAL | E6: 63790
B7: MONTO A RENDIR | E7: =SUM(E4:E6) -> 100000
B8: RENDIDO | E8: =+G27 -> 27240 | G8: SALDO AL CIERRE | H8: =E7-E8 -> 72760
A10: N° | B10: Fecha | C10: Tipo Documento (boleta venta-boleta honorarios-factura) | D10: N° documento | E10: RUT Titular del documento | F10: Detalle | G10: Total | H10: Código Imputacion (RSM) 170
A11: 1 | B11: 45694 | C11: Boleta de venta | D11: 19762 | E11: 77.093.957-7 | F11: Recarga Agua 20Lts | G11: 7000
A12: 2 | B12: 45697 | C12: Boleta de venta | D12: 15351327 | E12: 92.642.000-3 | F12: Cinta para embalaje/Cinta adhesiva | G12: 7680
A13: 3 | B13: 45704 | C13: Boleta de venta | D13: 246937624 | E13: 76.568.660-1 | F13: Terminales para conexión(reparación equipo de sonido) | G13: 1580
A14: 4 | B14: 45675 | C14: Boleta de venta | D14: 15386689 | E14: 92.642.000-3 | F14: Corchetes | G14: 3980
A15: 5 | B15: 45677 | C15: Boleta de venta | D15: 19546 | E15: 77.093.957-7 | F15: Recarga Agua 20Lts | G15: 7000
A16: 7
A17: 8
A18: 9
A19: 10
A20: 11
A21: 12
A22: 13
A23: 14
A24: 15
A25: 16
A26: 17
B27: TOTALES | G27: =SUM(G11:G26) -> 27240
F29: RESPONSABLE FONDO FIJO
F30: Maria Fernanda Pérez

Sheet FEB 25
C1: RENDICION CAJA CHICA
C2: COSTANERA CENTER
G3: MES | H3: FEBRERO
B4: SALDO ANTERIOR | E4: =+'ENE 25'!H8 -> 72760
B5: DEPÓSITO RENDICION ANTERIOR | E5: 27240
B6: MONTO ADICIONAL | E6: 0
B7: MONTO A RENDIR | E7: =SUM(E4:E6) -> 100000
B8: RENDIDO | E8: =+G27 -> 0 | G8: SALDO AL CIERRE | H8: =E7-E8 -> 100000
A10: N° | B10: Fecha | C10: Tipo Documento (boleta venta-boleta honorarios-factura) | D10: N° documento | E10: RUT Titular del documento | F10: Detalle | G10: Total | H10: Código Imputacion (RSM) 170
A11: 1
A12: 2
A13: 3
A14: 4
A15: 5
A16: 7
A17: 8
A18: 9
A19: 10
A20: 11
A21: 12
A22: 13
... A26: 17
B27: TOTALES | G27: =SUM(G11:G26) -> 0
B28: OBSERVACIONES: NO SE GENRERARON GASTOS EN ESTE MES.
F29: RESPONSABLE FONDO FIJO
F30: Maria Fernanda Pérez

Sheet MAR 25
C1: RENDICION CAJA CHICA
C2: COSTANERA CENTER
G3: MES | H3: MARZO
B4: SALDO ANTERIOR | E4: =+'FEB 25'!H8 -> 100000
B5: DEPÓSITO RENDICION ANTERIOR
B6: MONTO ADICIONAL | E6: 0
B7: MONTO A RENDIR | E7: =SUM(E4:E6) -> 100000
B8: RENDIDO | E8: =+G27 -> 47250 | G8: SALDO AL CIERRE | H8: =E7-E8 -> 52750
A10: N° | B10: Fecha | C10: Tipo Documento (boleta venta-boleta honorarios-factura) | D10: N° documento | E10: RUT Titular del documento | F10: Detalle | G10: Total | H10: Código Imputacion (RSM) 170
A11: 1 | B11: 05/032025 | C11: Boleta de venta | D11: 20105 | E11: 77.093.957-7 | F11: RECARGA CON BOTELLÓN | G11: 14000
A12: 2 | B12: 45724 | C12: Boleta de venta | D12: 3016610916 | E12: 81.201.000-K | F12: TORTA AGASAJO DIA DE LA MUJER | G12: 19780
A13: 3 | B13: 45735 | C13: Boleta de venta | D13: 81902563 | E13: 96.811.130-2 | F13: DESAYUNO LLENADO DE CANAL AM | G13: 3480
A14: 4 | B14: 45736 | C14: Boleta de venta | D14: 41365901 | E14: 76076630-5 | F14: DESAYUNO LLENADO DE CANAL AM | G14: 2990
A15: 5 | B15: 45742 | C15: Boleta de venta | D15: 20371 | E15: 77.093.957-7 | F15: RECARGA AGUA POTABLE | G15: 7000
A16: 7
A17: 8
A18: 9
A19: 10
A20: 11
A21: 12
A22: 13
A23: 14
A24: 15
A25: 16
A26: 17
B27: TOTALES | G27: =SUM(G11:G26) -> 47250
B28: OBSERVACIONES: NINGUNA
F29: RESPONSABLE FONDO FIJO
F30: Maria Fernanda Pérez

Sheet ABR 25
C1: RENDICION CAJA CHICA
C2: COSTANERA CENTER
G3: MES | H3: ABRIL
B4: SALDO ANTERIOR | E4: =+'MAR 25'!H8 -> 52750
B5: DEPÓSITO RENDICION ANTERIOR | E5: 47250
B6: MONTO ADICIONAL | E6: 0
B7: MONTO A RENDIR | E7: =SUM(E4:E6) -> 100000
B8: RENDIDO | E8: =+G27 -> 39340 | G8: SALDO AL CIERRE | H8: =E7-E8 -> 60660
A10: N° | B10: Fecha | C10: Tipo Documento (boleta venta-boleta honorarios-factura) | D10: N° documento | E10: RUT Titular del documento | F10: Detalle | G10: Total | H10: Código Imputacion (RSM) 170
A11: 1 | B11: 45750 | C11: BOLETA DE VENTA | D11: 3035595283 | E11: 81.201.000-K | F11: REUNIÓN INICIO DE MES | G11: 5970
A12: 2 | B12: 45756 | C12: BOLETA DE VENTA | D12: 20549 | E12: 77.093.957-7 | F12: RECARGA AGUA POTABLE | G12: 7000
A13: 3 | B13: 45764 | C13: BOLETA DE VENTA | D13: 54461288 | E13: 80.478.200-1 | F13: RESMA HOJAS BLANCAS | G13: 5990
A14: 4 | B14: 45771 | C14: BOLETA DE VENTA | D14: 20739 | E14: 77.093.957-7 | F14: RECARGA AGUA POTABLE | G14: 7000
A15: 5 | B15: 45773 | C15: BOLETA DE VENTA | D15: 167994496 | E15: 77.115.570-7 | F15: DESAYUNO RECEPCIÓN LLENADO | G15: 3390
A16: 6 | B16: 45776 | C16: BOLETA DE VENTA | D16: 253572908 | E16: 76568660-1 | F16: PITILLA(RAFIA OVILLO) | G16: 9990
A17: 7
A18: 8
A19: 9
A20: 10
A21: 11
A22: 12
A23: 13
A24: 14
A25: 15
A26: 16
B27: TOTALES | G27: =SUM(G11:G26) -> 39340
F29: RESPONSABLE FONDO FIJO
F30: Maria Fernanda Pérez

Sheet MAY 25
C1: RENDICION CAJA CHICA
C2: COSTANERA CENTER
G3: MES | H3: MAYO
B4: SALDO ANTERIOR | E4: =+'ABR 25'!H8 -> 60660
B5: DEPÓSITO RENDICION ANTERIOR | E5: 39340
B6: MONTO ADICIONAL | E6: 0
B7: MONTO A RENDIR | E7: =SUM(E4:E6) -> 100000
B8: RENDIDO | E8: =+G27 -> 25790 | G8: SALDO AL CIERRE | H8: =E7-E8 -> 74210
A10: N° | B10: Fecha | C10: Tipo Documento (boleta venta-boleta honorarios-factura) | D10: N° documento | E10: RUT Titular del documento | F10: Detalle | G10: Total | H10: Código Imputacion (RSM) 170
A11: 1 | B11: 45423 | C11: BOLETA DE VENTA | D11: 3074347253 | E11: 81.201.000-K | F11: ARTICULOS DE ASEO | G11: 7020
A12: 2 | B12: 45423 | C12: BOLETA DE VENTA | D12: 54734244 | E12: 80.478.200-1 | F12: PLUMON PIZARRA | G12: 2290
A13: 3 | B13: 45804 | C13: BOLETA DE VENTA | D13: 255127474 | E13: 76.568.660-1 | F13: ADHESIVO LA GOTITA | G13: 5490
A14: 4 | B14: 45789 | C14: BOLETA DE VENTA | D14: 3074124491 | E14: 81.201.000-K | F14: MARCADOR SHARPIE | G14: 3990
A15: 5 | B15: 45791 | C15: BOLETA DE VENTA | D15: 20966 | E15: 77.093.957-7 | F15: RECARGA AGUA | G15: 7000
A16: 7
A17: 8
A18: 9
A19: 10
A20: 11
A21: 12
A22: 13
A23: 14
A24: 15
A25: 16
A26: 17
B27: TOTALES | G27: =SUM(G11:G26) -> 25790
F29: RESPONSABLE FONDO FIJO
F30: Maria Fernanda Pérez

Sheet JUN 25
C1: RENDICION CAJA CHICA
C2: COSTANERA CENTER
G3: MES | H3: JUNIO
B4: SALDO ANTERIOR | E4: =+'MAY 25'!H8 -> 74210
B5: DEPÓSITO RENDICION ANTERIOR | E5: 25790
B6: MONTO ADICIONAL | E6: 0
B7: MONTO A RENDIR | E7: =SUM(E4:E6) -> 100000
B8: RENDIDO | E8: =+G27 -> 14000 | G8: SALDO AL CIERRE | H8: =E7-E8 -> 86000
A10: N° | B10: Fecha | C10: Tipo Documento (boleta venta-boleta honorarios-factura) | D10: N° documento | E10: RUT Titular del documento | F10: Detalle | G10: Total | H10: Código Imputacion (RSM) 170
A11: 1 | B11: 45810 | C11: BOLETA DE VENTA | D11: 21158 | E11: 77.093.957-7 | F11: RECARGA AGUA | G11: 7000
A12: 2 | B12: 45831 | C12: BOLETA DE VENTA | D12: 21392 | E12: 77.093.957-7 | F12: RECARGA AGUA | G12: 7000
A13: 3
A14: 4
A15: 5
A16: 7
A17: 8
A18: 9
A19: 10
A20: 11
A21: 12
A22: 13
A23: 14
A24: 15
... A26: 17
B27: TOTALES | G27: =SUM(G11:G26) -> 14000
F29: RESPONSABLE FONDO FIJO
F30: Maria Fernanda Pérez

Sheet JUL 25
C1: RENDICION CAJA CHICA
C2: COSTANERA CENTER
G3: MES | H3: SEPTIEMBRE
B4: SALDO ANTERIOR | E4: 86000
B5: DEPÓSITO RENDICION ANTERIOR | E5: 14000
B6: MONTO ADICIONAL | E6: 0
B7: MONTO A RENDIR | E7: =SUM(E4:E6) -> 100000
B8: RENDIDO | E8: 12000 | G8: SALDO AL CIERRE | H8: =E7-E8 -> 88000
A10: N° | B10: Fecha | C10: Tipo Documento (boleta venta-boleta honorarios-factura) | D10: N° documento | E10: RUT Titular del documento | F10: Detalle | G10: Total | H10: Código Imputacion (RSM) 170
A11: 1 | B11: 45908 | C11: BOLETA DE VENTA | D11: 22230 | E11: 77.093.957-7 | F11: RECARGA AGUA | G11: 12000
A12: 2
A13: 3
A14: 4
A15: 5
A16: 7
A17: 8
A18: 9
A19: 10
A20: 11
A21: 12
A22: 13
A23: 14
... A26: 17
B27: TOTALES | G27: =SUM(G11:G26) -> 12000
F29: RESPONSABLE FONDO FIJO
F30: Maria Fernanda Pérez

Sheet OCT 25
C1: RENDICION CAJA CHICA
C2: COSTANERA CENTER
G3: MES | H3: OCTUBRE
B4: SALDO ANTERIOR | E4: 88000
B5: DEPÓSITO RENDICION ANTERIOR | E5: 12000
B6: MONTO ADICIONAL | E6: 0
B7: MONTO A RENDIR | E7: =SUM(E4:E6) -> 100000
B8: RENDIDO | E8: =+G27 -> 63990 | G8: SALDO AL CIERRE | H8: =E7-E8 -> 36010
A10: N° | B10: Fecha | C10: Tipo Documento (boleta venta-boleta honorarios-factura) | D10: N° documento | E10: RUT Titular del documento | F10: Detalle | G10: Total | H10: Código Imputacion (RSM) 170
A11: 1 | B11: 45938 | C11: BOLETA DE VENTA | D11: 22545 | E11: 77.093.957-7 | F11: RECARGA AGUA | G11: 7000
A12: 2 | B12: 45940 | C12: BOLETA DE VENTA | D12: 1338 | E12: 5.666.822-5 | F12: LIMPIEZA DE FACHADA Y SLAON DE VENTAS | G12: 40000
A13: 3 | B13: 45957 | C13: BOLETA DE VENTA | D13: 260732131 | E13: 76.568.660-1 | F13: RAFIA OVILLO 800GR | G13: 9990
A14: 4 | B14: 45958 | C14: BOLETA DE VENTA | D14: 22770 | E14: 77.093.957-7 | F14: RECARGA AGUA | G14: 7000
A15: 5
A16: 7
A17: 8
A18: 9
A19: 10
A20: 11
A21: 12
A22: 13
A23: 14
A24: 15
A25: 16
A26: 17
B27: TOTALES | G27: =SUM(G11:G26) -> 63990
F29: RESPONSABLE FONDO FIJO
F30: Maria Fernanda Pérez

Sheet NOV 25
C1: RENDICION CAJA CHICA
C2: COSTANERA CENTER
G3: MES | H3: NOVIEMBRE
B4: SALDO ANTERIOR | E4: 88000
B5: DEPÓSITO RENDICION ANTERIOR | E5: 12000
B6: MONTO ADICIONAL | E6: 0
B7: MONTO A RENDIR | E7: =SUM(E4:E6) -> 100000
B8: RENDIDO | E8: =+G27 -> 87990 | G8: SALDO AL CIERRE | H8: =E7-E8 -> 12010
A10: N° | B10: Fecha | C10: Tipo Documento (boleta venta-boleta honorarios-factura) | D10: N° documento | E10: RUT Titular del documento | F10: Detalle | G10: Total | H10: Código Imputacion (RSM) 170
A11: 1 | B11: 45974 | C11: BOLETA DE VENTA | D11: 1364 | E11: 5.666.822-5 | F11: LIMPIEZA DE FACHADA Y SALÓN DE VENTAS | G11: 40000
A12: 2 | B12: 45978 | C12: BOLETA DE VENTA | D12: 22770 | E12: 77.093.957-7 | F12: RECARGA AGUA | G12: 7000
A13: 3 | B13: 45986 | C13: BOLETA DE VENTA | D13: 56762567 | E13: 80.478.200-1 | F13: PACK TINTAS PARA IMPRESORA BTCMYBK 4 | G13: 40990
A14: 4
A15: 5
A16: 7
A17: 8
A18: 9
A19: 10
A20: 11
A21: 12
A22: 13
A23: 14
A24: 15
A25: 16
A26: 17
B27: TOTALES | G27: =SUM(G11:G26) -> 87990
F29: RESPONSABLE FONDO FIJO
F30: Maria Fernanda Pérez

Sheet DIC 25 
C1: RENDICION CAJA CHICA
C2: COSTANERA CENTER
G3: MES | H3: ENERO
B4: SALDO ANTERIOR | E4: 12010
B5: DEPÓSITO RENDICION ANTERIOR | E5: 87990
B6: MONTO ADICIONAL | E6: 0
B7: MONTO A RENDIR | E7: =SUM(E4:E6) -> 100000
B8: RENDIDO | E8: =+G27 -> 108130 | G8: SALDO AL CIERRE | H8: =E7-E8 -> -8130
A10: N° | B10: Fecha | C10: Tipo Documento (boleta venta-boleta honorarios-factura) | D10: N° documento | E10: RUT Titular del documento | F10: Detalle | G10: Total | H10: Código Imputacion (RSM) 170
B11: 46043 | C11: boleta venta | D11: 1423 | E11: 5.666.822-5 | F11: LIMPIEZA DE FACHADA Y SALÓN DE VENTAS | G11: 40000
B12: 46034 | C12: boleta venta | D12: 23562 | E12: 77.093.957-7 | F12: RECARGA AGUA | G12: 7000
A13: 3 | B13: 46032 | C13: boleta venta | D13: 3275696374 | E13: 81.201.000-k | F13: INSUMOS REUNIÓN INICIO AÑO | G13: 40140
A14: 4 | B14: 46032 | C14: boleta venta | D14: 25004 | E14: 76.847.631-4 | F14: INSUMOS REUNIÓN INICIO AÑO | G14: 20990
A15: 5
A16: 7
A17: 8
A18: 9
A19: 10
A20: 11
A21: 12
A22: 13
A23: 14
A24: 15
A25: 16
A26: 17
B27: TOTALES | G27: =SUM(G11:G26) -> 108130
F29: RESPONSABLE FONDO FIJO
F30: Maria Fernanda Pérez

Sheet ENE 26
C1: RENDICION CAJA CHICA
C2: COSTANERA CENTER
G3: MES | H3: ENERO
B4: SALDO ANTERIOR | E4: 12010
B5: DEPÓSITO RENDICION ANTERIOR | E5: 87990
B6: MONTO ADICIONAL | E6: 0
B7: MONTO A RENDIR | E7: =SUM(E4:E6) -> 100000
B8: RENDIDO | E8: =+G27 -> 108130 | G8: SALDO AL CIERRE | H8: =E7-E8 -> -8130
A10: N° | B10: Fecha | C10: Tipo Documento (boleta venta-boleta honorarios-factura) | D10: N° documento | E10: RUT Titular del documento | F10: Detalle | G10: Total | H10: Código Imputacion (RSM) 170
B11: 46043 | C11: boleta venta | D11: 1423 | E11: 5.666.822-5 | F11: LIMPIEZA DE FACHADA Y SALÓN DE VENTAS | G11: 40000
B12: 46034 | C12: boleta venta | D12: 23562 | E12: 77.093.957-7 | F12: RECARGA AGUA | G12: 7000
A13: 3 | B13: 46032 | C13: boleta venta | D13: 3275696374 | E13: 81.201.000-k | F13: INSUMOS REUNIÓN INICIO AÑO | G13: 40140
A14: 4 | B14: 46032 | C14: boleta venta | D14: 25004 | E14: 76.847.631-4 | F14: INSUMOS REUNIÓN INICIO AÑO | G14: 20990
A15: 5
A16: 7
A17: 8
A18: 9
A19: 10
A20: 11
A21: 12
A22: 13
A23: 14
A24: 15
A25: 16
A26: 17
B27: TOTALES | G27: =SUM(G11:G26) -> 108130
F29: RESPONSABLE FONDO FIJO
F30: Maria Fernanda Pérez

Sheet Hoja2

Sheet Hoja3

Sheet Hoja4

Sheet Hoja5
