Workbook

Sheet historico
A1: 2022 | E1: 2740 | F1: 2740
A2: 2023
A3: MES | B3: DEBITO/PAGO RAUL | C3: CREDITOS/REND LOCAL | D3: SALDOS MES | E3: ACUMULADO
A5: ENERO | B5: 97260 | C5: 97260 | D5: =+B5-C5 -> 0 | E5: =E1+B5-C5 -> 2740
A6: FEBRERO | B6: 96190 | C6: =96190+86570 -> 182760 | D6: =+B6-C6 -> -86570 | E6: =E5+B6-C6 -> -83830
A7: MARZO | B7: 86570 | C7: 99500 | D7: =+B7-C7 -> -12930 | E7: =E6+B7-C7 -> -96760 | F7: -99500
A8: ABRIL | B8: 94630 | C8: 94630 | D8: =+B8-C8 -> 0 | E8: =E7+B8-C8 -> -96760
A9: MAYO | B9: 0 | C9: 87540 | D9: =+B9-C9 -> -87540 | E9: =E8+B9-C9 -> -184300
A10: JUNIO | B10: =87540+93730 -> 181270 | C10: 93730 | D10: =+B10-C10 -> 87540 | E10: =E9+B10-C10 -> -96760 | F10: -87540
A11: JULIO | B11: 0 | C11: =76510+66715 -> 143225 | D11: =+B11-C11 -> -143225 | E11: =E10+B11-C11 -> -239985 | F11: 181270
A12: AGOSTO | B12: 66715 | C12: 112980 | D12: =+B12-C12 -> -46265 | E12: =E11+B12-C12 -> -286250 | F12: -93730
A13: SEPTIEMBRE | B13: 276527 | C13: 83547 | D13: 192980 | E13: =E12+B13-C13 -> -93270 | F13: -143225
A14: OCTUBRE | B14: 183927 | C14: 91066 | D14: 92861 | E14: =E13+B14-C14 -> -409 | F14: 66715
A15: NOVIEMBRE | B15: 91066 | C15: 97878 | D15: -6812 | E15: =E14+B15-C15 -> -7221 | F15: -112980
A16: DICIEMBRE | B16: 97878 | C16: 65443 | D16: 32435 | E16: =E15+B16-C16 -> 25214 | F16: 276527
A17: 2024 | F17: -83547
A18: MES | B18: DEBITO/PAGO RAUL | C18: CREDITOS/REND LOCAL | D18: SALDOS MES | E18: ACUMULADO | F18: 183927
A20: ENERO | B20: =90657-25214 -> 65443 | C20: 75606 | D20: 15051 | E20: 15051
A21: FEBRERO | B21: 75606 | C21: 0 | D21: 75606 | E21: 90657
A22: MARZO | B22: 38000 | C22: 67057 | D22: -29057 | E22: 61600
A23: ABRIL | B23: 148301 | C23: 81244 | D23: 67057 | E23: 128657 | F23: -65443
A24: MAYO | B24: 105232 | C24: 0 | D24: 105232 | E24: 233889 | F24: 38000
A25: JUNIO | B25: 93908 | C25: 291587 | D25: -197679 | E25: 36210 | F25: 105232
A26: JULIO | B26: 0 | C26: 42070 | D26: -42070 | E26: -5860 | F26: 93908
A27: AGOSTO | B27: 42070 | C27: 50370 | D27: -8300 | E27: -14160 | F27: -291587
A28: SEPTIEMBRE | B28: 50370 | C28: 125525 | D28: -75155 | E28: -89315 | F28: -125525
A29: OCTUBRE | B29: 75545 | C29: 44000 | D29: 31545 | E29: -57770 | F29: 75545
A30: NOVIEMBRE | B30: 44000 | C30: 23115 | D30: 20885 | E30: -36885 | F30: 73095
A31: DICIEMBRE | B31: 73095 | C31: 45868 | D31: 27227 | E31: -9658 | F31: -23115
A32: 2025 | F32: -27240
A33: MES | B33: DEBITO/PAGO RAUL | C33: CREDITOS/REND LOCAL | D33: SALDOS MES | E33: ACUMULADO
A34: ENERO | B34: 45868 | C34: =36898-9658 -> 27240 | D34: =+B34-C34 -> 18628 | E34: =+E31+B34-C34 -> 8970
A35: FEBRERO | F35: =SUM(F1:F32) -> -56473
A36: MARZO
A37: ABRIL
A38: MAYO
A39: JUNIO
A40: JULIO
A41: AGOSTO
A42: SEPTIEMBRE
...

Sheet DIC 25 
C1: RENDICION CAJA CHICA
C2: COSTANERA CENTER
G3: MES | H3: DICIEMBRE
B4: SALDO ANTERIOR | E4: 12010
B5: DEPÓSITO RENDICION ANTERIOR | E5: 87990
B6: MONTO ADICIONAL | E6: 0
B7: MONTO A RENDIR | E7: =SUM(E4:E6) -> 100000
B8: RENDIDO | E8: =+G20 -> 47000 | G8: SALDO AL CIERRE | H8: =E7-E8 -> 53000
A10: N° | B10: Fecha | C10: Tipo Documento (boleta venta-boleta honorarios-factura) | D10: N° documento | E10: RUT Titular del documento | F10: Detalle | G10: Total | H10: Código Imputacion (RSM) 170
A11: 1 | B11: 46000 | C11: BOLETA DE VENTA | D11: 1393 | E11: 5.666.822-5 | F11: LIMPIEZA DE FACHADA Y SALÓN DE VENTAS | G11: 40000
A12: 2 | B12: 46003 | C12: BOLETA DE VENTA | D12: 23255 | E12: 77.093.957-7 | F12: RECARGA AGUA | G12: 7000
A13: 3
A14: 4
A15: 5
A16: 7
A17: 8
A18: 9
A19: 10
B20: TOTALES | G20: =SUM(G11:G19) -> 47000
F22: RESPONSABLE FONDO FIJO
F23: Maria Fernanda Pérez

Sheet ENE 2026
C1: RENDICION CAJA CHICA
C2: COSTANERA CENTER
G3: MES | H3: ENERO
B4: SALDO ANTERIOR | E4: =+'DIC 25 '!H8 -> 53000
B5: DEPÓSITO RENDICION ANTERIOR | E5: 47000
B6: MONTO ADICIONAL | E6: 0
B7: MONTO A RENDIR | E7: =SUM(E4:E6) -> 100000
B8: RENDIDO | E8: =+G20 -> 108130 | G8: SALDO AL CIERRE | H8: =E7-E8 -> -8130
A10: N° | B10: Fecha | C10: Tipo Documento (boleta venta-boleta honorarios-factura) | D10: N° documento | E10: RUT Titular del documento | F10: Detalle | G10: Total | H10: Código Imputacion (RSM) 170
A11: 1 | B11: 46043 | C11: boleta venta | D11: 1423 | E11: 5.666.822-5 | F11: LIMPIEZA DE FACHADA Y SALÓN DE VENTAS | G11: 40000
A12: 2 | B12: 46034 | C12: boleta venta | D12: 23562 | E12: 77.093.957-7 | F12: RECARGA AGUA | G12: 7000
A13: 3 | B13: 46032 | C13: boleta venta | D13: 3275696374 | E13: 81.201.000-k | F13: INSUMOS REUNIÓN INICIO AÑO | G13: 40140
A14: 4 | B14: 46032 | C14: boleta venta | D14: 25004 | E14: 76.847.631-4 | F14: INSUMOS REUNIÓN INICIO AÑO | G14: 20990
A15: 5
A16: 7
A17: 8
A18: 9
A19: 10
B20: TOTALES | G20: =SUM(G11:G19) -> 108130
F22: RESPONSABLE FONDO FIJO

Sheet FEB 2026
C1: RENDICION CAJA CHICA
C2: COSTANERA CENTER
G3: MES | H3: FEBRERO
B4: SALDO ANTERIOR | E4: =+'ENE 2026'!H8 -> -8130
B5: DEPÓSITO RENDICION ANTERIOR | E5: 0
B6: MONTO ADICIONAL | E6: 0
B7: MONTO A RENDIR | E7: =SUM(E4:E6) -> -8130
B8: RENDIDO | E8: =+G18 -> 96990 | G8: SALDO AL CIERRE | H8: =E7-E8 -> -105120
A10: N° | B10: Fecha | C10: Tipo Documento (boleta venta-boleta honorarios-factura) | D10: N° documento | E10: RUT Titular del documento | F10: Detalle | G10: Total | H10: Código Imputacion (RSM) 170
A11: 1 | B11: 46059 | C11: BOLETA | D11: 1444 | E11: 5.666.822-5 | F11: LIMPIEZA DE FACHADA Y SALÓN DE VENTAS | G11: 40000
A12: 2 | B12: 46073 | C12: BOLETA | D12: 24001 | E12: 77.093.957-7 | F12: RECARGA AGUA | G12: 7000
A13: 3 | B13: 46078 | C13: BOLETA | D13: 250281629 | E13: 76.568.660-1 | F13: SILLA (CAJA REGISTRADORA) | G13: 49990
A14: 4
A15: 5
A16: 6
A17: 7
B18: TOTALES | G18: =SUM(G11:G17) -> 96990
F20: RESPONSABLE FONDO FIJO

Sheet MAR 2026
C1: RENDICION CAJA CHICA
C2: COSTANERA CENTER
G3: MES | H3: MARZO
B4: SALDO ANTERIOR | E4: =+'FEB 2026'!H8 -> -105120
B5: DEPÓSITO RENDICION ANTERIOR | E5: 205120
B6: MONTO ADICIONAL | E6: 0
B7: MONTO A RENDIR | E7: =SUM(E4:E6) -> 100000
B8: RENDIDO | E8: =+G20 -> 47000 | G8: SALDO AL CIERRE | H8: =E7-E8 -> 53000
A10: N° | B10: Fecha | C10: Tipo Documento (boleta venta-boleta honorarios-factura) | D10: N° documento | E10: RUT Titular del documento | F10: Detalle | G10: Total | H10: Código Imputacion (RSM) 170
A11: 1 | B11: 46104 | C11: BOLETA | D11: 1484 | E11: 5.666.822-5 | F11: LIMPIEZA DE FACHADA Y SALÓN DE VENTAS | G11: 40000
A12: 2 | B12: 46105 | C12: BOLETA | D12: 24308 | E12: 77.093.957-7 | F12: RECARGA AGUA | G12: 7000
A13: 3
A14: 4
A15: 5
A16: 7
A17: 8
A18: 9
A19: 10
B20: TOTALES | G20: =SUM(G11:G19) -> 47000
F22: RESPONSABLE FONDO FIJO

Sheet ABR 2026
C1: RENDICION CAJA CHICA
C2: COSTANERA CENTER
G3: MES | H3: ABRIL
B4: SALDO ANTERIOR | E4: =+'MAR 2026'!H8 -> 53000
B5: DEPÓSITO RENDICION ANTERIOR | E5: 47000
B6: MONTO ADICIONAL | E6: 0
B7: MONTO A RENDIR | E7: =SUM(E4:E6) -> 100000
B8: RENDIDO | E8: =+G20 -> 55030 | G8: SALDO AL CIERRE | H8: =E7-E8 -> 44970
A10: N° | B10: Fecha | C10: Tipo Documento (boleta venta-boleta honorarios-factura) | D10: N° documento | E10: RUT Titular del documento | F10: Detalle | G10: Total | H10: Código Imputacion (RSM) 170
A11: 1 | B11: 46121 | C11: BOLETA | D11: 268666531 | E11: 76.568.660-1 | F11: RAFIA OVILLO 250G | G11: 8030
A12: 2 | B12: 46127 | C12: BOLETA | D12: 1501 | E12: 5.666.822-5 | F12: LIMPIEZA DE FACHADA Y SALÓN DE VENTAS | G12: 40000
A13: 3 | B13: 46140 | C13: BOLETA | D13: 24653 | E13: 77.093.957-8 | F13: RECARGA AGUA | G13: 7000
A14: 4
A15: 5
A16: 7
A17: 8
A18: 9
A19: 10
B20: TOTALES | G20: =SUM(G11:G19) -> 55030
F22: RESPONSABLE FONDO FIJO

Sheet MAY 2026
C1: RENDICION CAJA CHICA
C2: COSTANERA CENTER
G3: MES | H3: MAYO
B4: SALDO ANTERIOR | E4: =+'ABR 2026'!H8 -> 44970
B5: DEPÓSITO RENDICION ANTERIOR
B6: MONTO ADICIONAL | E6: 0
B7: MONTO A RENDIR | E7: =SUM(E4:E6) -> 44970
B8: RENDIDO | E8: =+G20 -> 0 | G8: SALDO AL CIERRE | H8: =E7-E8 -> 44970
A10: N° | B10: Fecha | C10: Tipo Documento (boleta venta-boleta honorarios-factura) | D10: N° documento | E10: RUT Titular del documento | F10: Detalle | G10: Total | H10: Código Imputacion (RSM) 170
A11: 1
A12: 2
A13: 3
A14: 4
A15: 5
A16: 7
A17: 8
A18: 9
A19: 10
B20: TOTALES | G20: =SUM(G11:G19) -> 0
F22: RESPONSABLE FONDO FIJO

Sheet JUN 2026
C1: RENDICION CAJA CHICA
C2: COSTANERA CENTER
G3: MES | H3: JUNIO
B4: SALDO ANTERIOR | E4: =+'MAY 2026'!H8 -> 44970
B5: DEPÓSITO RENDICION ANTERIOR
B6: MONTO ADICIONAL | E6: 0
B7: MONTO A RENDIR | E7: =SUM(E4:E6) -> 44970
B8: RENDIDO | E8: =+G20 -> 0 | G8: SALDO AL CIERRE | H8: =E7-E8 -> 44970
A10: N° | B10: Fecha | C10: Tipo Documento (boleta venta-boleta honorarios-factura) | D10: N° documento | E10: RUT Titular del documento | F10: Detalle | G10: Total | H10: Código Imputacion (RSM) 170
A11: 1
A12: 2
A13: 3
A14: 4
A15: 5
A16: 7
A17: 8
A18: 9
A19: 10
B20: TOTALES | G20: =SUM(G11:G19) -> 0
F22: RESPONSABLE FONDO FIJO
